[2023-12-04 23:32:04 +0100] [69696] [INFO] Starting gunicorn 21.2.0
[2023-12-04 23:32:04 +0100] [69696] [ERROR] Connection in use: ('0.0.0.0', 5000)
[2023-12-04 23:32:04 +0100] [69696] [ERROR] Retrying in 1 second.
[2023-12-04 23:32:05 +0100] [69696] [ERROR] Connection in use: ('0.0.0.0', 5000)
[2023-12-04 23:32:05 +0100] [69696] [ERROR] Retrying in 1 second.
[2023-12-04 23:32:06 +0100] [69696] [ERROR] Connection in use: ('0.0.0.0', 5000)
[2023-12-04 23:32:06 +0100] [69696] [ERROR] Retrying in 1 second.
[2023-12-04 23:32:07 +0100] [69696] [ERROR] Connection in use: ('0.0.0.0', 5000)
[2023-12-04 23:32:07 +0100] [69696] [ERROR] Retrying in 1 second.
[2023-12-04 23:32:08 +0100] [69696] [ERROR] Connection in use: ('0.0.0.0', 5000)
[2023-12-04 23:32:08 +0100] [69696] [ERROR] Retrying in 1 second.
[2023-12-04 23:32:09 +0100] [69696] [ERROR] Can't connect to ('0.0.0.0', 5000)
[2023-12-04 23:32:30 +0100] [69829] [INFO] Starting gunicorn 21.2.0
[2023-12-04 23:32:30 +0100] [69829] [INFO] Listening at: http://0.0.0.0:5000 (69829)
[2023-12-04 23:32:30 +0100] [69829] [INFO] Using worker: sync
[2023-12-04 23:32:30 +0100] [69831] [INFO] Booting worker with pid: 69831
[2023-12-04 23:32:30 +0100] [69831] [ERROR] Exception in worker process
Traceback (most recent call last):
  File "/home/samuel/Documents/freelance/xceedr-api/venv/lib/python3.10/site-packages/gunicorn/arbiter.py", line 609, in spawn_worker
    worker.init_process()
  File "/home/samuel/Documents/freelance/xceedr-api/venv/lib/python3.10/site-packages/gunicorn/workers/base.py", line 134, in init_process
    self.load_wsgi()
  File "/home/samuel/Documents/freelance/xceedr-api/venv/lib/python3.10/site-packages/gunicorn/workers/base.py", line 146, in load_wsgi
    self.wsgi = self.app.wsgi()
  File "/home/samuel/Documents/freelance/xceedr-api/venv/lib/python3.10/site-packages/gunicorn/app/base.py", line 67, in wsgi
    self.callable = self.load()
  File "/home/samuel/Documents/freelance/xceedr-api/venv/lib/python3.10/site-packages/gunicorn/app/wsgiapp.py", line 58, in load
    return self.load_wsgiapp()
  File "/home/samuel/Documents/freelance/xceedr-api/venv/lib/python3.10/site-packages/gunicorn/app/wsgiapp.py", line 48, in load_wsgiapp
    return util.import_app(self.app_uri)
  File "/home/samuel/Documents/freelance/xceedr-api/venv/lib/python3.10/site-packages/gunicorn/util.py", line 371, in import_app
    mod = importlib.import_module(module)
  File "/usr/lib/python3.10/importlib/__init__.py", line 126, in import_module
    return _bootstrap._gcd_import(name[level:], package, level)
  File "<frozen importlib._bootstrap>", line 1050, in _gcd_import
  File "<frozen importlib._bootstrap>", line 1027, in _find_and_load
  File "<frozen importlib._bootstrap>", line 1006, in _find_and_load_unlocked
  File "<frozen importlib._bootstrap>", line 688, in _load_unlocked
  File "<frozen importlib._bootstrap_external>", line 883, in exec_module
  File "<frozen importlib._bootstrap>", line 241, in _call_with_frames_removed
  File "/home/samuel/Documents/freelance/xceedr-api/run.py", line 1, in <module>
    from med_app import create_app, db
ModuleNotFoundError: No module named 'med_app'
[2023-12-04 23:32:30 +0100] [69831] [INFO] Worker exiting (pid: 69831)
[2023-12-04 23:32:30 +0100] [69832] [INFO] Booting worker with pid: 69832
[2023-12-04 23:32:30 +0100] [69832] [ERROR] Exception in worker process
Traceback (most recent call last):
  File "/home/samuel/Documents/freelance/xceedr-api/venv/lib/python3.10/site-packages/gunicorn/arbiter.py", line 609, in spawn_worker
    worker.init_process()
  File "/home/samuel/Documents/freelance/xceedr-api/venv/lib/python3.10/site-packages/gunicorn/workers/base.py", line 134, in init_process
    self.load_wsgi()
  File "/home/samuel/Documents/freelance/xceedr-api/venv/lib/python3.10/site-packages/gunicorn/workers/base.py", line 146, in load_wsgi
    self.wsgi = self.app.wsgi()
  File "/home/samuel/Documents/freelance/xceedr-api/venv/lib/python3.10/site-packages/gunicorn/app/base.py", line 67, in wsgi
    self.callable = self.load()
  File "/home/samuel/Documents/freelance/xceedr-api/venv/lib/python3.10/site-packages/gunicorn/app/wsgiapp.py", line 58, in load
    return self.load_wsgiapp()
  File "/home/samuel/Documents/freelance/xceedr-api/venv/lib/python3.10/site-packages/gunicorn/app/wsgiapp.py", line 48, in load_wsgiapp
    return util.import_app(self.app_uri)
  File "/home/samuel/Documents/freelance/xceedr-api/venv/lib/python3.10/site-packages/gunicorn/util.py", line 371, in import_app
    mod = importlib.import_module(module)
  File "/usr/lib/python3.10/importlib/__init__.py", line 126, in import_module
    return _bootstrap._gcd_import(name[level:], package, level)
  File "<frozen importlib._bootstrap>", line 1050, in _gcd_import
  File "<frozen importlib._bootstrap>", line 1027, in _find_and_load
  File "<frozen importlib._bootstrap>", line 1006, in _find_and_load_unlocked
  File "<frozen importlib._bootstrap>", line 688, in _load_unlocked
  File "<frozen importlib._bootstrap_external>", line 883, in exec_module
  File "<frozen importlib._bootstrap>", line 241, in _call_with_frames_removed
  File "/home/samuel/Documents/freelance/xceedr-api/run.py", line 1, in <module>
    from med_app import create_app, db
ModuleNotFoundError: No module named 'med_app'
[2023-12-04 23:32:30 +0100] [69832] [INFO] Worker exiting (pid: 69832)
[2023-12-04 23:32:30 +0100] [69829] [ERROR] Worker (pid:69831) exited with code 3
[2023-12-04 23:32:30 +0100] [69829] [ERROR] Worker (pid:69832) was sent SIGTERM!
[2023-12-04 23:32:30 +0100] [69829] [ERROR] Shutting down: Master
[2023-12-04 23:32:30 +0100] [69829] [ERROR] Reason: Worker failed to boot.
[2023-12-04 23:34:03 +0100] [70049] [INFO] Starting gunicorn 21.2.0
[2023-12-04 23:34:03 +0100] [70049] [INFO] Listening at: http://0.0.0.0:5000 (70049)
[2023-12-04 23:34:03 +0100] [70049] [INFO] Using worker: sync
[2023-12-04 23:34:03 +0100] [70050] [INFO] Booting worker with pid: 70050
[2023-12-04 23:34:03 +0100] [70051] [INFO] Booting worker with pid: 70051
[2023-12-04 23:34:03 +0100] [70052] [INFO] Booting worker with pid: 70052
[2023-12-04 23:34:03 +0100] [70053] [INFO] Booting worker with pid: 70053
[2023-12-04 23:34:03 +0100] [70051] [ERROR] Exception in worker process
Traceback (most recent call last):
  File "/home/samuel/Documents/freelance/xceedr-api/venv/lib/python3.10/site-packages/gunicorn/arbiter.py", line 609, in spawn_worker
    worker.init_process()
  File "/home/samuel/Documents/freelance/xceedr-api/venv/lib/python3.10/site-packages/gunicorn/workers/base.py", line 134, in init_process
    self.load_wsgi()
  File "/home/samuel/Documents/freelance/xceedr-api/venv/lib/python3.10/site-packages/gunicorn/workers/base.py", line 146, in load_wsgi
    self.wsgi = self.app.wsgi()
  File "/home/samuel/Documents/freelance/xceedr-api/venv/lib/python3.10/site-packages/gunicorn/app/base.py", line 67, in wsgi
    self.callable = self.load()
  File "/home/samuel/Documents/freelance/xceedr-api/venv/lib/python3.10/site-packages/gunicorn/app/wsgiapp.py", line 58, in load
    return self.load_wsgiapp()
  File "/home/samuel/Documents/freelance/xceedr-api/venv/lib/python3.10/site-packages/gunicorn/app/wsgiapp.py", line 48, in load_wsgiapp
    return util.import_app(self.app_uri)
  File "/home/samuel/Documents/freelance/xceedr-api/venv/lib/python3.10/site-packages/gunicorn/util.py", line 371, in import_app
    mod = importlib.import_module(module)
  File "/usr/lib/python3.10/importlib/__init__.py", line 126, in import_module
    return _bootstrap._gcd_import(name[level:], package, level)
  File "<frozen importlib._bootstrap>", line 1050, in _gcd_import
  File "<frozen importlib._bootstrap>", line 1027, in _find_and_load
  File "<frozen importlib._bootstrap>", line 1006, in _find_and_load_unlocked
  File "<frozen importlib._bootstrap>", line 688, in _load_unlocked
  File "<frozen importlib._bootstrap_external>", line 883, in exec_module
  File "<frozen importlib._bootstrap>", line 241, in _call_with_frames_removed
  File "/home/samuel/Documents/freelance/xceedr-api/run.py", line 24, in <module>
    app = create_app(app_config)
  File "/home/samuel/Documents/freelance/xceedr-api/volumx/__init__.py", line 49, in create_app
    with open("swagger_config.yaml", "r") as file:
FileNotFoundError: [Errno 2] No such file or directory: 'swagger_config.yaml'
[2023-12-04 23:34:03 +0100] [70051] [INFO] Worker exiting (pid: 70051)
[2023-12-04 23:34:03 +0100] [70050] [ERROR] Exception in worker process
Traceback (most recent call last):
  File "/home/samuel/Documents/freelance/xceedr-api/venv/lib/python3.10/site-packages/gunicorn/arbiter.py", line 609, in spawn_worker
    worker.init_process()
  File "/home/samuel/Documents/freelance/xceedr-api/venv/lib/python3.10/site-packages/gunicorn/workers/base.py", line 134, in init_process
    self.load_wsgi()
  File "/home/samuel/Documents/freelance/xceedr-api/venv/lib/python3.10/site-packages/gunicorn/workers/base.py", line 146, in load_wsgi
    self.wsgi = self.app.wsgi()
  File "/home/samuel/Documents/freelance/xceedr-api/venv/lib/python3.10/site-packages/gunicorn/app/base.py", line 67, in wsgi
    self.callable = self.load()
  File "/home/samuel/Documents/freelance/xceedr-api/venv/lib/python3.10/site-packages/gunicorn/app/wsgiapp.py", line 58, in load
    return self.load_wsgiapp()
  File "/home/samuel/Documents/freelance/xceedr-api/venv/lib/python3.10/site-packages/gunicorn/app/wsgiapp.py", line 48, in load_wsgiapp
    return util.import_app(self.app_uri)
  File "/home/samuel/Documents/freelance/xceedr-api/venv/lib/python3.10/site-packages/gunicorn/util.py", line 371, in import_app
    mod = importlib.import_module(module)
  File "/usr/lib/python3.10/importlib/__init__.py", line 126, in import_module
    return _bootstrap._gcd_import(name[level:], package, level)
  File "<frozen importlib._bootstrap>", line 1050, in _gcd_import
  File "<frozen importlib._bootstrap>", line 1027, in _find_and_load
  File "<frozen importlib._bootstrap>", line 1006, in _find_and_load_unlocked
  File "<frozen importlib._bootstrap>", line 688, in _load_unlocked
  File "<frozen importlib._bootstrap_external>", line 883, in exec_module
  File "<frozen importlib._bootstrap>", line 241, in _call_with_frames_removed
  File "/home/samuel/Documents/freelance/xceedr-api/run.py", line 24, in <module>
    app = create_app(app_config)
  File "/home/samuel/Documents/freelance/xceedr-api/volumx/__init__.py", line 49, in create_app
    with open("swagger_config.yaml", "r") as file:
FileNotFoundError: [Errno 2] No such file or directory: 'swagger_config.yaml'
[2023-12-04 23:34:03 +0100] [70050] [INFO] Worker exiting (pid: 70050)
[2023-12-04 23:34:04 +0100] [70052] [ERROR] Exception in worker process
Traceback (most recent call last):
  File "/home/samuel/Documents/freelance/xceedr-api/venv/lib/python3.10/site-packages/gunicorn/arbiter.py", line 609, in spawn_worker
    worker.init_process()
  File "/home/samuel/Documents/freelance/xceedr-api/venv/lib/python3.10/site-packages/gunicorn/workers/base.py", line 134, in init_process
    self.load_wsgi()
  File "/home/samuel/Documents/freelance/xceedr-api/venv/lib/python3.10/site-packages/gunicorn/workers/base.py", line 146, in load_wsgi
    self.wsgi = self.app.wsgi()
  File "/home/samuel/Documents/freelance/xceedr-api/venv/lib/python3.10/site-packages/gunicorn/app/base.py", line 67, in wsgi
    self.callable = self.load()
  File "/home/samuel/Documents/freelance/xceedr-api/venv/lib/python3.10/site-packages/gunicorn/app/wsgiapp.py", line 58, in load
    return self.load_wsgiapp()
  File "/home/samuel/Documents/freelance/xceedr-api/venv/lib/python3.10/site-packages/gunicorn/app/wsgiapp.py", line 48, in load_wsgiapp
    return util.import_app(self.app_uri)
  File "/home/samuel/Documents/freelance/xceedr-api/venv/lib/python3.10/site-packages/gunicorn/util.py", line 371, in import_app
    mod = importlib.import_module(module)
  File "/usr/lib/python3.10/importlib/__init__.py", line 126, in import_module
    return _bootstrap._gcd_import(name[level:], package, level)
  File "<frozen importlib._bootstrap>", line 1050, in _gcd_import
  File "<frozen importlib._bootstrap>", line 1027, in _find_and_load
  File "<frozen importlib._bootstrap>", line 1006, in _find_and_load_unlocked
  File "<frozen importlib._bootstrap>", line 688, in _load_unlocked
  File "<frozen importlib._bootstrap_external>", line 883, in exec_module
  File "<frozen importlib._bootstrap>", line 241, in _call_with_frames_removed
  File "/home/samuel/Documents/freelance/xceedr-api/run.py", line 24, in <module>
    app = create_app(app_config)
  File "/home/samuel/Documents/freelance/xceedr-api/volumx/__init__.py", line 49, in create_app
    with open("swagger_config.yaml", "r") as file:
FileNotFoundError: [Errno 2] No such file or directory: 'swagger_config.yaml'
[2023-12-04 23:34:04 +0100] [70052] [INFO] Worker exiting (pid: 70052)
[2023-12-04 23:34:04 +0100] [70049] [ERROR] Worker (pid:70051) exited with code 3
[2023-12-04 23:34:04 +0100] [70049] [ERROR] Worker (pid:70052) was sent SIGTERM!
[2023-12-04 23:34:04 +0100] [70049] [ERROR] Worker (pid:70050) was sent SIGTERM!
[2023-12-04 23:34:04 +0100] [70053] [ERROR] Exception in worker process
Traceback (most recent call last):
  File "/home/samuel/Documents/freelance/xceedr-api/venv/lib/python3.10/site-packages/gunicorn/arbiter.py", line 609, in spawn_worker
    worker.init_process()
  File "/home/samuel/Documents/freelance/xceedr-api/venv/lib/python3.10/site-packages/gunicorn/workers/base.py", line 134, in init_process
    self.load_wsgi()
  File "/home/samuel/Documents/freelance/xceedr-api/venv/lib/python3.10/site-packages/gunicorn/workers/base.py", line 146, in load_wsgi
    self.wsgi = self.app.wsgi()
  File "/home/samuel/Documents/freelance/xceedr-api/venv/lib/python3.10/site-packages/gunicorn/app/base.py", line 67, in wsgi
    self.callable = self.load()
  File "/home/samuel/Documents/freelance/xceedr-api/venv/lib/python3.10/site-packages/gunicorn/app/wsgiapp.py", line 58, in load
    return self.load_wsgiapp()
  File "/home/samuel/Documents/freelance/xceedr-api/venv/lib/python3.10/site-packages/gunicorn/app/wsgiapp.py", line 48, in load_wsgiapp
    return util.import_app(self.app_uri)
  File "/home/samuel/Documents/freelance/xceedr-api/venv/lib/python3.10/site-packages/gunicorn/util.py", line 371, in import_app
    mod = importlib.import_module(module)
  File "/usr/lib/python3.10/importlib/__init__.py", line 126, in import_module
    return _bootstrap._gcd_import(name[level:], package, level)
  File "<frozen importlib._bootstrap>", line 1050, in _gcd_import
  File "<frozen importlib._bootstrap>", line 1027, in _find_and_load
  File "<frozen importlib._bootstrap>", line 1006, in _find_and_load_unlocked
  File "<frozen importlib._bootstrap>", line 688, in _load_unlocked
  File "<frozen importlib._bootstrap_external>", line 883, in exec_module
  File "<frozen importlib._bootstrap>", line 241, in _call_with_frames_removed
  File "/home/samuel/Documents/freelance/xceedr-api/run.py", line 24, in <module>
    app = create_app(app_config)
  File "/home/samuel/Documents/freelance/xceedr-api/volumx/__init__.py", line 49, in create_app
    with open("swagger_config.yaml", "r") as file:
FileNotFoundError: [Errno 2] No such file or directory: 'swagger_config.yaml'
[2023-12-04 23:34:04 +0100] [70053] [INFO] Worker exiting (pid: 70053)
[2023-12-04 23:34:04 +0100] [70049] [ERROR] Worker (pid:70053) exited with code 3
[2023-12-04 23:34:40 +0100] [70179] [INFO] Starting gunicorn 21.2.0
[2023-12-04 23:34:40 +0100] [70179] [INFO] Listening at: http://0.0.0.0:5000 (70179)
[2023-12-04 23:34:40 +0100] [70179] [INFO] Using worker: sync
[2023-12-04 23:34:40 +0100] [70180] [INFO] Booting worker with pid: 70180
[2023-12-04 23:34:40 +0100] [70181] [INFO] Booting worker with pid: 70181
[2023-12-04 23:34:40 +0100] [70182] [INFO] Booting worker with pid: 70182
[2023-12-04 23:34:40 +0100] [70183] [INFO] Booting worker with pid: 70183
[2023-12-04 23:34:41 +0100] [70180] [ERROR] Exception in worker process
Traceback (most recent call last):
  File "/home/samuel/Documents/freelance/xceedr-api/venv/lib/python3.10/site-packages/gunicorn/arbiter.py", line 609, in spawn_worker
    worker.init_process()
  File "/home/samuel/Documents/freelance/xceedr-api/venv/lib/python3.10/site-packages/gunicorn/workers/base.py", line 134, in init_process
    self.load_wsgi()
  File "/home/samuel/Documents/freelance/xceedr-api/venv/lib/python3.10/site-packages/gunicorn/workers/base.py", line 146, in load_wsgi
    self.wsgi = self.app.wsgi()
  File "/home/samuel/Documents/freelance/xceedr-api/venv/lib/python3.10/site-packages/gunicorn/app/base.py", line 67, in wsgi
    self.callable = self.load()
  File "/home/samuel/Documents/freelance/xceedr-api/venv/lib/python3.10/site-packages/gunicorn/app/wsgiapp.py", line 58, in load
    return self.load_wsgiapp()
  File "/home/samuel/Documents/freelance/xceedr-api/venv/lib/python3.10/site-packages/gunicorn/app/wsgiapp.py", line 48, in load_wsgiapp
    return util.import_app(self.app_uri)
  File "/home/samuel/Documents/freelance/xceedr-api/venv/lib/python3.10/site-packages/gunicorn/util.py", line 371, in import_app
    mod = importlib.import_module(module)
  File "/usr/lib/python3.10/importlib/__init__.py", line 126, in import_module
    return _bootstrap._gcd_import(name[level:], package, level)
  File "<frozen importlib._bootstrap>", line 1050, in _gcd_import
  File "<frozen importlib._bootstrap>", line 1027, in _find_and_load
  File "<frozen importlib._bootstrap>", line 1006, in _find_and_load_unlocked
  File "<frozen importlib._bootstrap>", line 688, in _load_unlocked
  File "<frozen importlib._bootstrap_external>", line 883, in exec_module
  File "<frozen importlib._bootstrap>", line 241, in _call_with_frames_removed
  File "/home/samuel/Documents/freelance/xceedr-api/run.py", line 24, in <module>
    app = create_app(app_config)
  File "/home/samuel/Documents/freelance/xceedr-api/volumx/__init__.py", line 96, in create_app
    db.create_all()
  File "/home/samuel/Documents/freelance/xceedr-api/venv/lib/python3.10/site-packages/flask_sqlalchemy/extension.py", line 900, in create_all
    self._call_for_binds(bind_key, "create_all")
  File "/home/samuel/Documents/freelance/xceedr-api/venv/lib/python3.10/site-packages/flask_sqlalchemy/extension.py", line 881, in _call_for_binds
    getattr(metadata, op_name)(bind=engine)
  File "/home/samuel/Documents/freelance/xceedr-api/venv/lib/python3.10/site-packages/sqlalchemy/sql/schema.py", line 5828, in create_all
    bind._run_ddl_visitor(
  File "/home/samuel/Documents/freelance/xceedr-api/venv/lib/python3.10/site-packages/sqlalchemy/engine/base.py", line 3243, in _run_ddl_visitor
    conn._run_ddl_visitor(visitorcallable, element, **kwargs)
  File "/home/samuel/Documents/freelance/xceedr-api/venv/lib/python3.10/site-packages/sqlalchemy/engine/base.py", line 2447, in _run_ddl_visitor
    visitorcallable(self.dialect, self, **kwargs).traverse_single(element)
  File "/home/samuel/Documents/freelance/xceedr-api/venv/lib/python3.10/site-packages/sqlalchemy/sql/visitors.py", line 671, in traverse_single
    return meth(obj, **kw)
  File "/home/samuel/Documents/freelance/xceedr-api/venv/lib/python3.10/site-packages/sqlalchemy/sql/ddl.py", line 897, in visit_metadata
    collection = sort_tables_and_constraints(
  File "/home/samuel/Documents/freelance/xceedr-api/venv/lib/python3.10/site-packages/sqlalchemy/sql/ddl.py", line 1327, in sort_tables_and_constraints
    dependent_on = fkc.referred_table
  File "/home/samuel/Documents/freelance/xceedr-api/venv/lib/python3.10/site-packages/sqlalchemy/sql/schema.py", line 4751, in referred_table
    return self.elements[0].column.table
  File "/home/samuel/Documents/freelance/xceedr-api/venv/lib/python3.10/site-packages/sqlalchemy/util/langhelpers.py", line 1146, in __get__
    obj.__dict__[self.__name__] = result = self.fget(obj)
  File "/home/samuel/Documents/freelance/xceedr-api/venv/lib/python3.10/site-packages/sqlalchemy/sql/schema.py", line 3159, in column
    return self._resolve_column()
  File "/home/samuel/Documents/freelance/xceedr-api/venv/lib/python3.10/site-packages/sqlalchemy/sql/schema.py", line 3182, in _resolve_column
    raise exc.NoReferencedTableError(
sqlalchemy.exc.NoReferencedTableError: Foreign key associated with column 'business_user_rights.userId' could not find table 'user' with which to generate a foreign key to target column 'id'
[2023-12-04 23:34:41 +0100] [70180] [INFO] Worker exiting (pid: 70180)
[2023-12-04 23:34:41 +0100] [70182] [ERROR] Exception in worker process
Traceback (most recent call last):
  File "/home/samuel/Documents/freelance/xceedr-api/venv/lib/python3.10/site-packages/gunicorn/arbiter.py", line 609, in spawn_worker
    worker.init_process()
  File "/home/samuel/Documents/freelance/xceedr-api/venv/lib/python3.10/site-packages/gunicorn/workers/base.py", line 134, in init_process
    self.load_wsgi()
  File "/home/samuel/Documents/freelance/xceedr-api/venv/lib/python3.10/site-packages/gunicorn/workers/base.py", line 146, in load_wsgi
    self.wsgi = self.app.wsgi()
  File "/home/samuel/Documents/freelance/xceedr-api/venv/lib/python3.10/site-packages/gunicorn/app/base.py", line 67, in wsgi
    self.callable = self.load()
  File "/home/samuel/Documents/freelance/xceedr-api/venv/lib/python3.10/site-packages/gunicorn/app/wsgiapp.py", line 58, in load
    return self.load_wsgiapp()
  File "/home/samuel/Documents/freelance/xceedr-api/venv/lib/python3.10/site-packages/gunicorn/app/wsgiapp.py", line 48, in load_wsgiapp
    return util.import_app(self.app_uri)
  File "/home/samuel/Documents/freelance/xceedr-api/venv/lib/python3.10/site-packages/gunicorn/util.py", line 371, in import_app
    mod = importlib.import_module(module)
  File "/usr/lib/python3.10/importlib/__init__.py", line 126, in import_module
    return _bootstrap._gcd_import(name[level:], package, level)
  File "<frozen importlib._bootstrap>", line 1050, in _gcd_import
  File "<frozen importlib._bootstrap>", line 1027, in _find_and_load
  File "<frozen importlib._bootstrap>", line 1006, in _find_and_load_unlocked
  File "<frozen importlib._bootstrap>", line 688, in _load_unlocked
  File "<frozen importlib._bootstrap_external>", line 883, in exec_module
  File "<frozen importlib._bootstrap>", line 241, in _call_with_frames_removed
  File "/home/samuel/Documents/freelance/xceedr-api/run.py", line 24, in <module>
    app = create_app(app_config)
  File "/home/samuel/Documents/freelance/xceedr-api/volumx/__init__.py", line 96, in create_app
    db.create_all()
  File "/home/samuel/Documents/freelance/xceedr-api/venv/lib/python3.10/site-packages/flask_sqlalchemy/extension.py", line 900, in create_all
    self._call_for_binds(bind_key, "create_all")
  File "/home/samuel/Documents/freelance/xceedr-api/venv/lib/python3.10/site-packages/flask_sqlalchemy/extension.py", line 881, in _call_for_binds
    getattr(metadata, op_name)(bind=engine)
  File "/home/samuel/Documents/freelance/xceedr-api/venv/lib/python3.10/site-packages/sqlalchemy/sql/schema.py", line 5828, in create_all
    bind._run_ddl_visitor(
  File "/home/samuel/Documents/freelance/xceedr-api/venv/lib/python3.10/site-packages/sqlalchemy/engine/base.py", line 3243, in _run_ddl_visitor
    conn._run_ddl_visitor(visitorcallable, element, **kwargs)
  File "/home/samuel/Documents/freelance/xceedr-api/venv/lib/python3.10/site-packages/sqlalchemy/engine/base.py", line 2447, in _run_ddl_visitor
    visitorcallable(self.dialect, self, **kwargs).traverse_single(element)
  File "/home/samuel/Documents/freelance/xceedr-api/venv/lib/python3.10/site-packages/sqlalchemy/sql/visitors.py", line 671, in traverse_single
    return meth(obj, **kw)
  File "/home/samuel/Documents/freelance/xceedr-api/venv/lib/python3.10/site-packages/sqlalchemy/sql/ddl.py", line 897, in visit_metadata
    collection = sort_tables_and_constraints(
  File "/home/samuel/Documents/freelance/xceedr-api/venv/lib/python3.10/site-packages/sqlalchemy/sql/ddl.py", line 1327, in sort_tables_and_constraints
    dependent_on = fkc.referred_table
  File "/home/samuel/Documents/freelance/xceedr-api/venv/lib/python3.10/site-packages/sqlalchemy/sql/schema.py", line 4751, in referred_table
    return self.elements[0].column.table
  File "/home/samuel/Documents/freelance/xceedr-api/venv/lib/python3.10/site-packages/sqlalchemy/util/langhelpers.py", line 1146, in __get__
    obj.__dict__[self.__name__] = result = self.fget(obj)
  File "/home/samuel/Documents/freelance/xceedr-api/venv/lib/python3.10/site-packages/sqlalchemy/sql/schema.py", line 3159, in column
    return self._resolve_column()
  File "/home/samuel/Documents/freelance/xceedr-api/venv/lib/python3.10/site-packages/sqlalchemy/sql/schema.py", line 3182, in _resolve_column
    raise exc.NoReferencedTableError(
sqlalchemy.exc.NoReferencedTableError: Foreign key associated with column 'business_user_rights.userId' could not find table 'user' with which to generate a foreign key to target column 'id'
[2023-12-04 23:34:41 +0100] [70182] [INFO] Worker exiting (pid: 70182)
[2023-12-04 23:34:41 +0100] [70179] [ERROR] Worker (pid:70180) exited with code 3
[2023-12-04 23:34:41 +0100] [70179] [ERROR] Worker (pid:70182) was sent SIGTERM!
[2023-12-04 23:34:41 +0100] [70181] [ERROR] Exception in worker process
Traceback (most recent call last):
  File "/home/samuel/Documents/freelance/xceedr-api/venv/lib/python3.10/site-packages/gunicorn/arbiter.py", line 609, in spawn_worker
    worker.init_process()
  File "/home/samuel/Documents/freelance/xceedr-api/venv/lib/python3.10/site-packages/gunicorn/workers/base.py", line 134, in init_process
    self.load_wsgi()
  File "/home/samuel/Documents/freelance/xceedr-api/venv/lib/python3.10/site-packages/gunicorn/workers/base.py", line 146, in load_wsgi
    self.wsgi = self.app.wsgi()
  File "/home/samuel/Documents/freelance/xceedr-api/venv/lib/python3.10/site-packages/gunicorn/app/base.py", line 67, in wsgi
    self.callable = self.load()
  File "/home/samuel/Documents/freelance/xceedr-api/venv/lib/python3.10/site-packages/gunicorn/app/wsgiapp.py", line 58, in load
    return self.load_wsgiapp()
  File "/home/samuel/Documents/freelance/xceedr-api/venv/lib/python3.10/site-packages/gunicorn/app/wsgiapp.py", line 48, in load_wsgiapp
    return util.import_app(self.app_uri)
  File "/home/samuel/Documents/freelance/xceedr-api/venv/lib/python3.10/site-packages/gunicorn/util.py", line 371, in import_app
    mod = importlib.import_module(module)
  File "/usr/lib/python3.10/importlib/__init__.py", line 126, in import_module
    return _bootstrap._gcd_import(name[level:], package, level)
  File "<frozen importlib._bootstrap>", line 1050, in _gcd_import
  File "<frozen importlib._bootstrap>", line 1027, in _find_and_load
  File "<frozen importlib._bootstrap>", line 1006, in _find_and_load_unlocked
  File "<frozen importlib._bootstrap>", line 688, in _load_unlocked
  File "<frozen importlib._bootstrap_external>", line 883, in exec_module
  File "<frozen importlib._bootstrap>", line 241, in _call_with_frames_removed
  File "/home/samuel/Documents/freelance/xceedr-api/run.py", line 24, in <module>
    app = create_app(app_config)
  File "/home/samuel/Documents/freelance/xceedr-api/volumx/__init__.py", line 96, in create_app
    db.create_all()
  File "/home/samuel/Documents/freelance/xceedr-api/venv/lib/python3.10/site-packages/flask_sqlalchemy/extension.py", line 900, in create_all
    self._call_for_binds(bind_key, "create_all")
  File "/home/samuel/Documents/freelance/xceedr-api/venv/lib/python3.10/site-packages/flask_sqlalchemy/extension.py", line 881, in _call_for_binds
    getattr(metadata, op_name)(bind=engine)
  File "/home/samuel/Documents/freelance/xceedr-api/venv/lib/python3.10/site-packages/sqlalchemy/sql/schema.py", line 5828, in create_all
    bind._run_ddl_visitor(
  File "/home/samuel/Documents/freelance/xceedr-api/venv/lib/python3.10/site-packages/sqlalchemy/engine/base.py", line 3243, in _run_ddl_visitor
    conn._run_ddl_visitor(visitorcallable, element, **kwargs)
  File "/home/samuel/Documents/freelance/xceedr-api/venv/lib/python3.10/site-packages/sqlalchemy/engine/base.py", line 2447, in _run_ddl_visitor
    visitorcallable(self.dialect, self, **kwargs).traverse_single(element)
  File "/home/samuel/Documents/freelance/xceedr-api/venv/lib/python3.10/site-packages/sqlalchemy/sql/visitors.py", line 671, in traverse_single
    return meth(obj, **kw)
  File "/home/samuel/Documents/freelance/xceedr-api/venv/lib/python3.10/site-packages/sqlalchemy/sql/ddl.py", line 897, in visit_metadata
    collection = sort_tables_and_constraints(
  File "/home/samuel/Documents/freelance/xceedr-api/venv/lib/python3.10/site-packages/sqlalchemy/sql/ddl.py", line 1327, in sort_tables_and_constraints
    dependent_on = fkc.referred_table
  File "/home/samuel/Documents/freelance/xceedr-api/venv/lib/python3.10/site-packages/sqlalchemy/sql/schema.py", line 4751, in referred_table
    return self.elements[0].column.table
  File "/home/samuel/Documents/freelance/xceedr-api/venv/lib/python3.10/site-packages/sqlalchemy/util/langhelpers.py", line 1146, in __get__
    obj.__dict__[self.__name__] = result = self.fget(obj)
  File "/home/samuel/Documents/freelance/xceedr-api/venv/lib/python3.10/site-packages/sqlalchemy/sql/schema.py", line 3159, in column
    return self._resolve_column()
  File "/home/samuel/Documents/freelance/xceedr-api/venv/lib/python3.10/site-packages/sqlalchemy/sql/schema.py", line 3182, in _resolve_column
    raise exc.NoReferencedTableError(
sqlalchemy.exc.NoReferencedTableError: Foreign key associated with column 'business_user_rights.userId' could not find table 'user' with which to generate a foreign key to target column 'id'
[2023-12-04 23:34:41 +0100] [70181] [INFO] Worker exiting (pid: 70181)
[2023-12-04 23:34:41 +0100] [70183] [ERROR] Exception in worker process
Traceback (most recent call last):
  File "/home/samuel/Documents/freelance/xceedr-api/venv/lib/python3.10/site-packages/gunicorn/arbiter.py", line 609, in spawn_worker
    worker.init_process()
  File "/home/samuel/Documents/freelance/xceedr-api/venv/lib/python3.10/site-packages/gunicorn/workers/base.py", line 134, in init_process
    self.load_wsgi()
  File "/home/samuel/Documents/freelance/xceedr-api/venv/lib/python3.10/site-packages/gunicorn/workers/base.py", line 146, in load_wsgi
    self.wsgi = self.app.wsgi()
  File "/home/samuel/Documents/freelance/xceedr-api/venv/lib/python3.10/site-packages/gunicorn/app/base.py", line 67, in wsgi
    self.callable = self.load()
  File "/home/samuel/Documents/freelance/xceedr-api/venv/lib/python3.10/site-packages/gunicorn/app/wsgiapp.py", line 58, in load
    return self.load_wsgiapp()
  File "/home/samuel/Documents/freelance/xceedr-api/venv/lib/python3.10/site-packages/gunicorn/app/wsgiapp.py", line 48, in load_wsgiapp
    return util.import_app(self.app_uri)
  File "/home/samuel/Documents/freelance/xceedr-api/venv/lib/python3.10/site-packages/gunicorn/util.py", line 371, in import_app
    mod = importlib.import_module(module)
  File "/usr/lib/python3.10/importlib/__init__.py", line 126, in import_module
    return _bootstrap._gcd_import(name[level:], package, level)
  File "<frozen importlib._bootstrap>", line 1050, in _gcd_import
  File "<frozen importlib._bootstrap>", line 1027, in _find_and_load
  File "<frozen importlib._bootstrap>", line 1006, in _find_and_load_unlocked
  File "<frozen importlib._bootstrap>", line 688, in _load_unlocked
  File "<frozen importlib._bootstrap_external>", line 883, in exec_module
  File "<frozen importlib._bootstrap>", line 241, in _call_with_frames_removed
  File "/home/samuel/Documents/freelance/xceedr-api/run.py", line 24, in <module>
    app = create_app(app_config)
  File "/home/samuel/Documents/freelance/xceedr-api/volumx/__init__.py", line 96, in create_app
    db.create_all()
  File "/home/samuel/Documents/freelance/xceedr-api/venv/lib/python3.10/site-packages/flask_sqlalchemy/extension.py", line 900, in create_all
    self._call_for_binds(bind_key, "create_all")
  File "/home/samuel/Documents/freelance/xceedr-api/venv/lib/python3.10/site-packages/flask_sqlalchemy/extension.py", line 881, in _call_for_binds
    getattr(metadata, op_name)(bind=engine)
  File "/home/samuel/Documents/freelance/xceedr-api/venv/lib/python3.10/site-packages/sqlalchemy/sql/schema.py", line 5828, in create_all
    bind._run_ddl_visitor(
  File "/home/samuel/Documents/freelance/xceedr-api/venv/lib/python3.10/site-packages/sqlalchemy/engine/base.py", line 3243, in _run_ddl_visitor
    conn._run_ddl_visitor(visitorcallable, element, **kwargs)
  File "/home/samuel/Documents/freelance/xceedr-api/venv/lib/python3.10/site-packages/sqlalchemy/engine/base.py", line 2447, in _run_ddl_visitor
    visitorcallable(self.dialect, self, **kwargs).traverse_single(element)
  File "/home/samuel/Documents/freelance/xceedr-api/venv/lib/python3.10/site-packages/sqlalchemy/sql/visitors.py", line 671, in traverse_single
    return meth(obj, **kw)
  File "/home/samuel/Documents/freelance/xceedr-api/venv/lib/python3.10/site-packages/sqlalchemy/sql/ddl.py", line 897, in visit_metadata
    collection = sort_tables_and_constraints(
  File "/home/samuel/Documents/freelance/xceedr-api/venv/lib/python3.10/site-packages/sqlalchemy/sql/ddl.py", line 1327, in sort_tables_and_constraints
    dependent_on = fkc.referred_table
  File "/home/samuel/Documents/freelance/xceedr-api/venv/lib/python3.10/site-packages/sqlalchemy/sql/schema.py", line 4751, in referred_table
    return self.elements[0].column.table
  File "/home/samuel/Documents/freelance/xceedr-api/venv/lib/python3.10/site-packages/sqlalchemy/util/langhelpers.py", line 1146, in __get__
    obj.__dict__[self.__name__] = result = self.fget(obj)
  File "/home/samuel/Documents/freelance/xceedr-api/venv/lib/python3.10/site-packages/sqlalchemy/sql/schema.py", line 3159, in column
    return self._resolve_column()
  File "/home/samuel/Documents/freelance/xceedr-api/venv/lib/python3.10/site-packages/sqlalchemy/sql/schema.py", line 3182, in _resolve_column
    raise exc.NoReferencedTableError(
sqlalchemy.exc.NoReferencedTableError: Foreign key associated with column 'business_user_rights.userId' could not find table 'user' with which to generate a foreign key to target column 'id'
[2023-12-04 23:34:41 +0100] [70183] [INFO] Worker exiting (pid: 70183)
[2023-12-04 23:34:42 +0100] [70179] [ERROR] Worker (pid:70181) exited with code 3
[2023-12-04 23:37:01 +0100] [70455] [INFO] Starting gunicorn 21.2.0
[2023-12-04 23:37:01 +0100] [70455] [INFO] Listening at: http://0.0.0.0:5000 (70455)
[2023-12-04 23:37:01 +0100] [70455] [INFO] Using worker: sync
[2023-12-04 23:37:01 +0100] [70457] [INFO] Booting worker with pid: 70457
[2023-12-04 23:37:01 +0100] [70458] [INFO] Booting worker with pid: 70458
[2023-12-04 23:37:01 +0100] [70459] [INFO] Booting worker with pid: 70459
[2023-12-04 23:37:01 +0100] [70460] [INFO] Booting worker with pid: 70460
[2023-12-04 23:37:02 +0100] [70458] [ERROR] Exception in worker process
Traceback (most recent call last):
  File "/home/samuel/Documents/freelance/xceedr-api/venv/lib/python3.10/site-packages/gunicorn/arbiter.py", line 609, in spawn_worker
    worker.init_process()
  File "/home/samuel/Documents/freelance/xceedr-api/venv/lib/python3.10/site-packages/gunicorn/workers/base.py", line 134, in init_process
    self.load_wsgi()
  File "/home/samuel/Documents/freelance/xceedr-api/venv/lib/python3.10/site-packages/gunicorn/workers/base.py", line 146, in load_wsgi
    self.wsgi = self.app.wsgi()
  File "/home/samuel/Documents/freelance/xceedr-api/venv/lib/python3.10/site-packages/gunicorn/app/base.py", line 67, in wsgi
    self.callable = self.load()
  File "/home/samuel/Documents/freelance/xceedr-api/venv/lib/python3.10/site-packages/gunicorn/app/wsgiapp.py", line 58, in load
    return self.load_wsgiapp()
  File "/home/samuel/Documents/freelance/xceedr-api/venv/lib/python3.10/site-packages/gunicorn/app/wsgiapp.py", line 48, in load_wsgiapp
    return util.import_app(self.app_uri)
  File "/home/samuel/Documents/freelance/xceedr-api/venv/lib/python3.10/site-packages/gunicorn/util.py", line 371, in import_app
    mod = importlib.import_module(module)
  File "/usr/lib/python3.10/importlib/__init__.py", line 126, in import_module
    return _bootstrap._gcd_import(name[level:], package, level)
  File "<frozen importlib._bootstrap>", line 1050, in _gcd_import
  File "<frozen importlib._bootstrap>", line 1027, in _find_and_load
  File "<frozen importlib._bootstrap>", line 1006, in _find_and_load_unlocked
  File "<frozen importlib._bootstrap>", line 688, in _load_unlocked
  File "<frozen importlib._bootstrap_external>", line 883, in exec_module
  File "<frozen importlib._bootstrap>", line 241, in _call_with_frames_removed
  File "/home/samuel/Documents/freelance/xceedr-api/run.py", line 24, in <module>
    app = create_app(app_config)
  File "/home/samuel/Documents/freelance/xceedr-api/volumx/__init__.py", line 96, in create_app
    db.create_all()
  File "/home/samuel/Documents/freelance/xceedr-api/venv/lib/python3.10/site-packages/flask_sqlalchemy/extension.py", line 900, in create_all
    self._call_for_binds(bind_key, "create_all")
  File "/home/samuel/Documents/freelance/xceedr-api/venv/lib/python3.10/site-packages/flask_sqlalchemy/extension.py", line 881, in _call_for_binds
    getattr(metadata, op_name)(bind=engine)
  File "/home/samuel/Documents/freelance/xceedr-api/venv/lib/python3.10/site-packages/sqlalchemy/sql/schema.py", line 5828, in create_all
    bind._run_ddl_visitor(
  File "/home/samuel/Documents/freelance/xceedr-api/venv/lib/python3.10/site-packages/sqlalchemy/engine/base.py", line 3243, in _run_ddl_visitor
    conn._run_ddl_visitor(visitorcallable, element, **kwargs)
  File "/home/samuel/Documents/freelance/xceedr-api/venv/lib/python3.10/site-packages/sqlalchemy/engine/base.py", line 2447, in _run_ddl_visitor
    visitorcallable(self.dialect, self, **kwargs).traverse_single(element)
  File "/home/samuel/Documents/freelance/xceedr-api/venv/lib/python3.10/site-packages/sqlalchemy/sql/visitors.py", line 671, in traverse_single
    return meth(obj, **kw)
  File "/home/samuel/Documents/freelance/xceedr-api/venv/lib/python3.10/site-packages/sqlalchemy/sql/ddl.py", line 897, in visit_metadata
    collection = sort_tables_and_constraints(
  File "/home/samuel/Documents/freelance/xceedr-api/venv/lib/python3.10/site-packages/sqlalchemy/sql/ddl.py", line 1327, in sort_tables_and_constraints
    dependent_on = fkc.referred_table
  File "/home/samuel/Documents/freelance/xceedr-api/venv/lib/python3.10/site-packages/sqlalchemy/sql/schema.py", line 4751, in referred_table
    return self.elements[0].column.table
  File "/home/samuel/Documents/freelance/xceedr-api/venv/lib/python3.10/site-packages/sqlalchemy/util/langhelpers.py", line 1146, in __get__
    obj.__dict__[self.__name__] = result = self.fget(obj)
  File "/home/samuel/Documents/freelance/xceedr-api/venv/lib/python3.10/site-packages/sqlalchemy/sql/schema.py", line 3159, in column
    return self._resolve_column()
  File "/home/samuel/Documents/freelance/xceedr-api/venv/lib/python3.10/site-packages/sqlalchemy/sql/schema.py", line 3182, in _resolve_column
    raise exc.NoReferencedTableError(
sqlalchemy.exc.NoReferencedTableError: Foreign key associated with column 'business_user_rights.userId' could not find table 'user' with which to generate a foreign key to target column 'id'
[2023-12-04 23:37:02 +0100] [70458] [INFO] Worker exiting (pid: 70458)
[2023-12-04 23:37:02 +0100] [70457] [ERROR] Exception in worker process
Traceback (most recent call last):
  File "/home/samuel/Documents/freelance/xceedr-api/venv/lib/python3.10/site-packages/gunicorn/arbiter.py", line 609, in spawn_worker
    worker.init_process()
  File "/home/samuel/Documents/freelance/xceedr-api/venv/lib/python3.10/site-packages/gunicorn/workers/base.py", line 134, in init_process
    self.load_wsgi()
  File "/home/samuel/Documents/freelance/xceedr-api/venv/lib/python3.10/site-packages/gunicorn/workers/base.py", line 146, in load_wsgi
    self.wsgi = self.app.wsgi()
  File "/home/samuel/Documents/freelance/xceedr-api/venv/lib/python3.10/site-packages/gunicorn/app/base.py", line 67, in wsgi
    self.callable = self.load()
  File "/home/samuel/Documents/freelance/xceedr-api/venv/lib/python3.10/site-packages/gunicorn/app/wsgiapp.py", line 58, in load
    return self.load_wsgiapp()
  File "/home/samuel/Documents/freelance/xceedr-api/venv/lib/python3.10/site-packages/gunicorn/app/wsgiapp.py", line 48, in load_wsgiapp
    return util.import_app(self.app_uri)
  File "/home/samuel/Documents/freelance/xceedr-api/venv/lib/python3.10/site-packages/gunicorn/util.py", line 371, in import_app
    mod = importlib.import_module(module)
  File "/usr/lib/python3.10/importlib/__init__.py", line 126, in import_module
    return _bootstrap._gcd_import(name[level:], package, level)
  File "<frozen importlib._bootstrap>", line 1050, in _gcd_import
  File "<frozen importlib._bootstrap>", line 1027, in _find_and_load
  File "<frozen importlib._bootstrap>", line 1006, in _find_and_load_unlocked
  File "<frozen importlib._bootstrap>", line 688, in _load_unlocked
  File "<frozen importlib._bootstrap_external>", line 883, in exec_module
  File "<frozen importlib._bootstrap>", line 241, in _call_with_frames_removed
  File "/home/samuel/Documents/freelance/xceedr-api/run.py", line 24, in <module>
    app = create_app(app_config)
  File "/home/samuel/Documents/freelance/xceedr-api/volumx/__init__.py", line 96, in create_app
    db.create_all()
  File "/home/samuel/Documents/freelance/xceedr-api/venv/lib/python3.10/site-packages/flask_sqlalchemy/extension.py", line 900, in create_all
    self._call_for_binds(bind_key, "create_all")
  File "/home/samuel/Documents/freelance/xceedr-api/venv/lib/python3.10/site-packages/flask_sqlalchemy/extension.py", line 881, in _call_for_binds
    getattr(metadata, op_name)(bind=engine)
  File "/home/samuel/Documents/freelance/xceedr-api/venv/lib/python3.10/site-packages/sqlalchemy/sql/schema.py", line 5828, in create_all
    bind._run_ddl_visitor(
  File "/home/samuel/Documents/freelance/xceedr-api/venv/lib/python3.10/site-packages/sqlalchemy/engine/base.py", line 3243, in _run_ddl_visitor
    conn._run_ddl_visitor(visitorcallable, element, **kwargs)
  File "/home/samuel/Documents/freelance/xceedr-api/venv/lib/python3.10/site-packages/sqlalchemy/engine/base.py", line 2447, in _run_ddl_visitor
    visitorcallable(self.dialect, self, **kwargs).traverse_single(element)
  File "/home/samuel/Documents/freelance/xceedr-api/venv/lib/python3.10/site-packages/sqlalchemy/sql/visitors.py", line 671, in traverse_single
    return meth(obj, **kw)
  File "/home/samuel/Documents/freelance/xceedr-api/venv/lib/python3.10/site-packages/sqlalchemy/sql/ddl.py", line 897, in visit_metadata
    collection = sort_tables_and_constraints(
  File "/home/samuel/Documents/freelance/xceedr-api/venv/lib/python3.10/site-packages/sqlalchemy/sql/ddl.py", line 1327, in sort_tables_and_constraints
    dependent_on = fkc.referred_table
  File "/home/samuel/Documents/freelance/xceedr-api/venv/lib/python3.10/site-packages/sqlalchemy/sql/schema.py", line 4751, in referred_table
    return self.elements[0].column.table
  File "/home/samuel/Documents/freelance/xceedr-api/venv/lib/python3.10/site-packages/sqlalchemy/util/langhelpers.py", line 1146, in __get__
    obj.__dict__[self.__name__] = result = self.fget(obj)
  File "/home/samuel/Documents/freelance/xceedr-api/venv/lib/python3.10/site-packages/sqlalchemy/sql/schema.py", line 3159, in column
    return self._resolve_column()
  File "/home/samuel/Documents/freelance/xceedr-api/venv/lib/python3.10/site-packages/sqlalchemy/sql/schema.py", line 3182, in _resolve_column
    raise exc.NoReferencedTableError(
sqlalchemy.exc.NoReferencedTableError: Foreign key associated with column 'business_user_rights.userId' could not find table 'user' with which to generate a foreign key to target column 'id'
[2023-12-04 23:37:02 +0100] [70457] [INFO] Worker exiting (pid: 70457)
[2023-12-04 23:37:02 +0100] [70455] [ERROR] Worker (pid:70458) exited with code 3
[2023-12-04 23:37:02 +0100] [70455] [ERROR] Worker (pid:70457) exited with code 3
[2023-12-04 23:37:02 +0100] [70459] [ERROR] Exception in worker process
Traceback (most recent call last):
  File "/home/samuel/Documents/freelance/xceedr-api/venv/lib/python3.10/site-packages/gunicorn/arbiter.py", line 609, in spawn_worker
    worker.init_process()
  File "/home/samuel/Documents/freelance/xceedr-api/venv/lib/python3.10/site-packages/gunicorn/workers/base.py", line 134, in init_process
    self.load_wsgi()
  File "/home/samuel/Documents/freelance/xceedr-api/venv/lib/python3.10/site-packages/gunicorn/workers/base.py", line 146, in load_wsgi
    self.wsgi = self.app.wsgi()
  File "/home/samuel/Documents/freelance/xceedr-api/venv/lib/python3.10/site-packages/gunicorn/app/base.py", line 67, in wsgi
    self.callable = self.load()
  File "/home/samuel/Documents/freelance/xceedr-api/venv/lib/python3.10/site-packages/gunicorn/app/wsgiapp.py", line 58, in load
    return self.load_wsgiapp()
  File "/home/samuel/Documents/freelance/xceedr-api/venv/lib/python3.10/site-packages/gunicorn/app/wsgiapp.py", line 48, in load_wsgiapp
    return util.import_app(self.app_uri)
  File "/home/samuel/Documents/freelance/xceedr-api/venv/lib/python3.10/site-packages/gunicorn/util.py", line 371, in import_app
    mod = importlib.import_module(module)
  File "/usr/lib/python3.10/importlib/__init__.py", line 126, in import_module
    return _bootstrap._gcd_import(name[level:], package, level)
  File "<frozen importlib._bootstrap>", line 1050, in _gcd_import
  File "<frozen importlib._bootstrap>", line 1027, in _find_and_load
  File "<frozen importlib._bootstrap>", line 1006, in _find_and_load_unlocked
  File "<frozen importlib._bootstrap>", line 688, in _load_unlocked
  File "<frozen importlib._bootstrap_external>", line 883, in exec_module
  File "<frozen importlib._bootstrap>", line 241, in _call_with_frames_removed
  File "/home/samuel/Documents/freelance/xceedr-api/run.py", line 24, in <module>
    app = create_app(app_config)
  File "/home/samuel/Documents/freelance/xceedr-api/volumx/__init__.py", line 96, in create_app
    db.create_all()
  File "/home/samuel/Documents/freelance/xceedr-api/venv/lib/python3.10/site-packages/flask_sqlalchemy/extension.py", line 900, in create_all
    self._call_for_binds(bind_key, "create_all")
  File "/home/samuel/Documents/freelance/xceedr-api/venv/lib/python3.10/site-packages/flask_sqlalchemy/extension.py", line 881, in _call_for_binds
    getattr(metadata, op_name)(bind=engine)
  File "/home/samuel/Documents/freelance/xceedr-api/venv/lib/python3.10/site-packages/sqlalchemy/sql/schema.py", line 5828, in create_all
    bind._run_ddl_visitor(
  File "/home/samuel/Documents/freelance/xceedr-api/venv/lib/python3.10/site-packages/sqlalchemy/engine/base.py", line 3243, in _run_ddl_visitor
    conn._run_ddl_visitor(visitorcallable, element, **kwargs)
  File "/home/samuel/Documents/freelance/xceedr-api/venv/lib/python3.10/site-packages/sqlalchemy/engine/base.py", line 2447, in _run_ddl_visitor
    visitorcallable(self.dialect, self, **kwargs).traverse_single(element)
  File "/home/samuel/Documents/freelance/xceedr-api/venv/lib/python3.10/site-packages/sqlalchemy/sql/visitors.py", line 671, in traverse_single
    return meth(obj, **kw)
  File "/home/samuel/Documents/freelance/xceedr-api/venv/lib/python3.10/site-packages/sqlalchemy/sql/ddl.py", line 897, in visit_metadata
    collection = sort_tables_and_constraints(
  File "/home/samuel/Documents/freelance/xceedr-api/venv/lib/python3.10/site-packages/sqlalchemy/sql/ddl.py", line 1327, in sort_tables_and_constraints
    dependent_on = fkc.referred_table
  File "/home/samuel/Documents/freelance/xceedr-api/venv/lib/python3.10/site-packages/sqlalchemy/sql/schema.py", line 4751, in referred_table
    return self.elements[0].column.table
  File "/home/samuel/Documents/freelance/xceedr-api/venv/lib/python3.10/site-packages/sqlalchemy/util/langhelpers.py", line 1146, in __get__
    obj.__dict__[self.__name__] = result = self.fget(obj)
  File "/home/samuel/Documents/freelance/xceedr-api/venv/lib/python3.10/site-packages/sqlalchemy/sql/schema.py", line 3159, in column
    return self._resolve_column()
  File "/home/samuel/Documents/freelance/xceedr-api/venv/lib/python3.10/site-packages/sqlalchemy/sql/schema.py", line 3182, in _resolve_column
    raise exc.NoReferencedTableError(
sqlalchemy.exc.NoReferencedTableError: Foreign key associated with column 'business_user_rights.userId' could not find table 'user' with which to generate a foreign key to target column 'id'
[2023-12-04 23:37:02 +0100] [70459] [INFO] Worker exiting (pid: 70459)
[2023-12-04 23:37:02 +0100] [70460] [ERROR] Exception in worker process
Traceback (most recent call last):
  File "/home/samuel/Documents/freelance/xceedr-api/venv/lib/python3.10/site-packages/gunicorn/arbiter.py", line 609, in spawn_worker
    worker.init_process()
  File "/home/samuel/Documents/freelance/xceedr-api/venv/lib/python3.10/site-packages/gunicorn/workers/base.py", line 134, in init_process
    self.load_wsgi()
  File "/home/samuel/Documents/freelance/xceedr-api/venv/lib/python3.10/site-packages/gunicorn/workers/base.py", line 146, in load_wsgi
    self.wsgi = self.app.wsgi()
  File "/home/samuel/Documents/freelance/xceedr-api/venv/lib/python3.10/site-packages/gunicorn/app/base.py", line 67, in wsgi
    self.callable = self.load()
  File "/home/samuel/Documents/freelance/xceedr-api/venv/lib/python3.10/site-packages/gunicorn/app/wsgiapp.py", line 58, in load
    return self.load_wsgiapp()
  File "/home/samuel/Documents/freelance/xceedr-api/venv/lib/python3.10/site-packages/gunicorn/app/wsgiapp.py", line 48, in load_wsgiapp
    return util.import_app(self.app_uri)
  File "/home/samuel/Documents/freelance/xceedr-api/venv/lib/python3.10/site-packages/gunicorn/util.py", line 371, in import_app
    mod = importlib.import_module(module)
  File "/usr/lib/python3.10/importlib/__init__.py", line 126, in import_module
    return _bootstrap._gcd_import(name[level:], package, level)
  File "<frozen importlib._bootstrap>", line 1050, in _gcd_import
  File "<frozen importlib._bootstrap>", line 1027, in _find_and_load
  File "<frozen importlib._bootstrap>", line 1006, in _find_and_load_unlocked
  File "<frozen importlib._bootstrap>", line 688, in _load_unlocked
  File "<frozen importlib._bootstrap_external>", line 883, in exec_module
  File "<frozen importlib._bootstrap>", line 241, in _call_with_frames_removed
  File "/home/samuel/Documents/freelance/xceedr-api/run.py", line 24, in <module>
    app = create_app(app_config)
  File "/home/samuel/Documents/freelance/xceedr-api/volumx/__init__.py", line 96, in create_app
    db.create_all()
  File "/home/samuel/Documents/freelance/xceedr-api/venv/lib/python3.10/site-packages/flask_sqlalchemy/extension.py", line 900, in create_all
    self._call_for_binds(bind_key, "create_all")
  File "/home/samuel/Documents/freelance/xceedr-api/venv/lib/python3.10/site-packages/flask_sqlalchemy/extension.py", line 881, in _call_for_binds
    getattr(metadata, op_name)(bind=engine)
  File "/home/samuel/Documents/freelance/xceedr-api/venv/lib/python3.10/site-packages/sqlalchemy/sql/schema.py", line 5828, in create_all
    bind._run_ddl_visitor(
  File "/home/samuel/Documents/freelance/xceedr-api/venv/lib/python3.10/site-packages/sqlalchemy/engine/base.py", line 3243, in _run_ddl_visitor
    conn._run_ddl_visitor(visitorcallable, element, **kwargs)
  File "/home/samuel/Documents/freelance/xceedr-api/venv/lib/python3.10/site-packages/sqlalchemy/engine/base.py", line 2447, in _run_ddl_visitor
    visitorcallable(self.dialect, self, **kwargs).traverse_single(element)
  File "/home/samuel/Documents/freelance/xceedr-api/venv/lib/python3.10/site-packages/sqlalchemy/sql/visitors.py", line 671, in traverse_single
    return meth(obj, **kw)
  File "/home/samuel/Documents/freelance/xceedr-api/venv/lib/python3.10/site-packages/sqlalchemy/sql/ddl.py", line 897, in visit_metadata
    collection = sort_tables_and_constraints(
  File "/home/samuel/Documents/freelance/xceedr-api/venv/lib/python3.10/site-packages/sqlalchemy/sql/ddl.py", line 1327, in sort_tables_and_constraints
    dependent_on = fkc.referred_table
  File "/home/samuel/Documents/freelance/xceedr-api/venv/lib/python3.10/site-packages/sqlalchemy/sql/schema.py", line 4751, in referred_table
    return self.elements[0].column.table
  File "/home/samuel/Documents/freelance/xceedr-api/venv/lib/python3.10/site-packages/sqlalchemy/util/langhelpers.py", line 1146, in __get__
    obj.__dict__[self.__name__] = result = self.fget(obj)
  File "/home/samuel/Documents/freelance/xceedr-api/venv/lib/python3.10/site-packages/sqlalchemy/sql/schema.py", line 3159, in column
    return self._resolve_column()
  File "/home/samuel/Documents/freelance/xceedr-api/venv/lib/python3.10/site-packages/sqlalchemy/sql/schema.py", line 3182, in _resolve_column
    raise exc.NoReferencedTableError(
sqlalchemy.exc.NoReferencedTableError: Foreign key associated with column 'business_user_rights.userId' could not find table 'user' with which to generate a foreign key to target column 'id'
[2023-12-04 23:37:02 +0100] [70460] [INFO] Worker exiting (pid: 70460)
[2023-12-04 23:43:43 +0100] [71104] [INFO] Starting gunicorn 21.2.0
[2023-12-04 23:43:43 +0100] [71104] [INFO] Listening at: http://0.0.0.0:5000 (71104)
[2023-12-04 23:43:43 +0100] [71104] [INFO] Using worker: sync
[2023-12-04 23:43:43 +0100] [71106] [INFO] Booting worker with pid: 71106
[2023-12-04 23:43:43 +0100] [71107] [INFO] Booting worker with pid: 71107
[2023-12-04 23:43:43 +0100] [71108] [INFO] Booting worker with pid: 71108
[2023-12-04 23:43:43 +0100] [71109] [INFO] Booting worker with pid: 71109
[2023-12-04 23:43:44 +0100] [71106] [ERROR] Exception in worker process
Traceback (most recent call last):
  File "/home/samuel/Documents/freelance/xceedr-api/venv/lib/python3.10/site-packages/gunicorn/arbiter.py", line 609, in spawn_worker
    worker.init_process()
  File "/home/samuel/Documents/freelance/xceedr-api/venv/lib/python3.10/site-packages/gunicorn/workers/base.py", line 134, in init_process
    self.load_wsgi()
  File "/home/samuel/Documents/freelance/xceedr-api/venv/lib/python3.10/site-packages/gunicorn/workers/base.py", line 146, in load_wsgi
    self.wsgi = self.app.wsgi()
  File "/home/samuel/Documents/freelance/xceedr-api/venv/lib/python3.10/site-packages/gunicorn/app/base.py", line 67, in wsgi
    self.callable = self.load()
  File "/home/samuel/Documents/freelance/xceedr-api/venv/lib/python3.10/site-packages/gunicorn/app/wsgiapp.py", line 58, in load
    return self.load_wsgiapp()
  File "/home/samuel/Documents/freelance/xceedr-api/venv/lib/python3.10/site-packages/gunicorn/app/wsgiapp.py", line 48, in load_wsgiapp
    return util.import_app(self.app_uri)
  File "/home/samuel/Documents/freelance/xceedr-api/venv/lib/python3.10/site-packages/gunicorn/util.py", line 371, in import_app
    mod = importlib.import_module(module)
  File "/usr/lib/python3.10/importlib/__init__.py", line 126, in import_module
    return _bootstrap._gcd_import(name[level:], package, level)
  File "<frozen importlib._bootstrap>", line 1050, in _gcd_import
  File "<frozen importlib._bootstrap>", line 1027, in _find_and_load
  File "<frozen importlib._bootstrap>", line 1006, in _find_and_load_unlocked
  File "<frozen importlib._bootstrap>", line 688, in _load_unlocked
  File "<frozen importlib._bootstrap_external>", line 883, in exec_module
  File "<frozen importlib._bootstrap>", line 241, in _call_with_frames_removed
  File "/home/samuel/Documents/freelance/xceedr-api/run.py", line 24, in <module>
    app = create_app(app_config)
  File "/home/samuel/Documents/freelance/xceedr-api/volumx/__init__.py", line 96, in create_app
    db.create_all()
  File "/home/samuel/Documents/freelance/xceedr-api/venv/lib/python3.10/site-packages/flask_sqlalchemy/extension.py", line 900, in create_all
    self._call_for_binds(bind_key, "create_all")
  File "/home/samuel/Documents/freelance/xceedr-api/venv/lib/python3.10/site-packages/flask_sqlalchemy/extension.py", line 881, in _call_for_binds
    getattr(metadata, op_name)(bind=engine)
  File "/home/samuel/Documents/freelance/xceedr-api/venv/lib/python3.10/site-packages/sqlalchemy/sql/schema.py", line 5828, in create_all
    bind._run_ddl_visitor(
  File "/home/samuel/Documents/freelance/xceedr-api/venv/lib/python3.10/site-packages/sqlalchemy/engine/base.py", line 3243, in _run_ddl_visitor
    conn._run_ddl_visitor(visitorcallable, element, **kwargs)
  File "/home/samuel/Documents/freelance/xceedr-api/venv/lib/python3.10/site-packages/sqlalchemy/engine/base.py", line 2447, in _run_ddl_visitor
    visitorcallable(self.dialect, self, **kwargs).traverse_single(element)
  File "/home/samuel/Documents/freelance/xceedr-api/venv/lib/python3.10/site-packages/sqlalchemy/sql/visitors.py", line 671, in traverse_single
    return meth(obj, **kw)
  File "/home/samuel/Documents/freelance/xceedr-api/venv/lib/python3.10/site-packages/sqlalchemy/sql/ddl.py", line 897, in visit_metadata
    collection = sort_tables_and_constraints(
  File "/home/samuel/Documents/freelance/xceedr-api/venv/lib/python3.10/site-packages/sqlalchemy/sql/ddl.py", line 1327, in sort_tables_and_constraints
    dependent_on = fkc.referred_table
  File "/home/samuel/Documents/freelance/xceedr-api/venv/lib/python3.10/site-packages/sqlalchemy/sql/schema.py", line 4751, in referred_table
    return self.elements[0].column.table
  File "/home/samuel/Documents/freelance/xceedr-api/venv/lib/python3.10/site-packages/sqlalchemy/util/langhelpers.py", line 1146, in __get__
    obj.__dict__[self.__name__] = result = self.fget(obj)
  File "/home/samuel/Documents/freelance/xceedr-api/venv/lib/python3.10/site-packages/sqlalchemy/sql/schema.py", line 3159, in column
    return self._resolve_column()
  File "/home/samuel/Documents/freelance/xceedr-api/venv/lib/python3.10/site-packages/sqlalchemy/sql/schema.py", line 3182, in _resolve_column
    raise exc.NoReferencedTableError(
sqlalchemy.exc.NoReferencedTableError: Foreign key associated with column 'business_user_rights.userId' could not find table 'user' with which to generate a foreign key to target column 'id'
[2023-12-04 23:43:44 +0100] [71106] [INFO] Worker exiting (pid: 71106)
[2023-12-04 23:43:44 +0100] [71107] [ERROR] Exception in worker process
Traceback (most recent call last):
  File "/home/samuel/Documents/freelance/xceedr-api/venv/lib/python3.10/site-packages/gunicorn/arbiter.py", line 609, in spawn_worker
    worker.init_process()
  File "/home/samuel/Documents/freelance/xceedr-api/venv/lib/python3.10/site-packages/gunicorn/workers/base.py", line 134, in init_process
    self.load_wsgi()
  File "/home/samuel/Documents/freelance/xceedr-api/venv/lib/python3.10/site-packages/gunicorn/workers/base.py", line 146, in load_wsgi
    self.wsgi = self.app.wsgi()
  File "/home/samuel/Documents/freelance/xceedr-api/venv/lib/python3.10/site-packages/gunicorn/app/base.py", line 67, in wsgi
    self.callable = self.load()
  File "/home/samuel/Documents/freelance/xceedr-api/venv/lib/python3.10/site-packages/gunicorn/app/wsgiapp.py", line 58, in load
    return self.load_wsgiapp()
  File "/home/samuel/Documents/freelance/xceedr-api/venv/lib/python3.10/site-packages/gunicorn/app/wsgiapp.py", line 48, in load_wsgiapp
    return util.import_app(self.app_uri)
  File "/home/samuel/Documents/freelance/xceedr-api/venv/lib/python3.10/site-packages/gunicorn/util.py", line 371, in import_app
    mod = importlib.import_module(module)
  File "/usr/lib/python3.10/importlib/__init__.py", line 126, in import_module
    return _bootstrap._gcd_import(name[level:], package, level)
  File "<frozen importlib._bootstrap>", line 1050, in _gcd_import
  File "<frozen importlib._bootstrap>", line 1027, in _find_and_load
  File "<frozen importlib._bootstrap>", line 1006, in _find_and_load_unlocked
  File "<frozen importlib._bootstrap>", line 688, in _load_unlocked
  File "<frozen importlib._bootstrap_external>", line 883, in exec_module
  File "<frozen importlib._bootstrap>", line 241, in _call_with_frames_removed
  File "/home/samuel/Documents/freelance/xceedr-api/run.py", line 24, in <module>
    app = create_app(app_config)
  File "/home/samuel/Documents/freelance/xceedr-api/volumx/__init__.py", line 96, in create_app
    db.create_all()
  File "/home/samuel/Documents/freelance/xceedr-api/venv/lib/python3.10/site-packages/flask_sqlalchemy/extension.py", line 900, in create_all
    self._call_for_binds(bind_key, "create_all")
  File "/home/samuel/Documents/freelance/xceedr-api/venv/lib/python3.10/site-packages/flask_sqlalchemy/extension.py", line 881, in _call_for_binds
    getattr(metadata, op_name)(bind=engine)
  File "/home/samuel/Documents/freelance/xceedr-api/venv/lib/python3.10/site-packages/sqlalchemy/sql/schema.py", line 5828, in create_all
    bind._run_ddl_visitor(
  File "/home/samuel/Documents/freelance/xceedr-api/venv/lib/python3.10/site-packages/sqlalchemy/engine/base.py", line 3243, in _run_ddl_visitor
    conn._run_ddl_visitor(visitorcallable, element, **kwargs)
  File "/home/samuel/Documents/freelance/xceedr-api/venv/lib/python3.10/site-packages/sqlalchemy/engine/base.py", line 2447, in _run_ddl_visitor
    visitorcallable(self.dialect, self, **kwargs).traverse_single(element)
  File "/home/samuel/Documents/freelance/xceedr-api/venv/lib/python3.10/site-packages/sqlalchemy/sql/visitors.py", line 671, in traverse_single
    return meth(obj, **kw)
  File "/home/samuel/Documents/freelance/xceedr-api/venv/lib/python3.10/site-packages/sqlalchemy/sql/ddl.py", line 897, in visit_metadata
    collection = sort_tables_and_constraints(
  File "/home/samuel/Documents/freelance/xceedr-api/venv/lib/python3.10/site-packages/sqlalchemy/sql/ddl.py", line 1327, in sort_tables_and_constraints
    dependent_on = fkc.referred_table
  File "/home/samuel/Documents/freelance/xceedr-api/venv/lib/python3.10/site-packages/sqlalchemy/sql/schema.py", line 4751, in referred_table
    return self.elements[0].column.table
  File "/home/samuel/Documents/freelance/xceedr-api/venv/lib/python3.10/site-packages/sqlalchemy/util/langhelpers.py", line 1146, in __get__
    obj.__dict__[self.__name__] = result = self.fget(obj)
  File "/home/samuel/Documents/freelance/xceedr-api/venv/lib/python3.10/site-packages/sqlalchemy/sql/schema.py", line 3159, in column
    return self._resolve_column()
  File "/home/samuel/Documents/freelance/xceedr-api/venv/lib/python3.10/site-packages/sqlalchemy/sql/schema.py", line 3182, in _resolve_column
    raise exc.NoReferencedTableError(
sqlalchemy.exc.NoReferencedTableError: Foreign key associated with column 'business_user_rights.userId' could not find table 'user' with which to generate a foreign key to target column 'id'
[2023-12-04 23:43:44 +0100] [71107] [INFO] Worker exiting (pid: 71107)
[2023-12-04 23:43:45 +0100] [71104] [ERROR] Worker (pid:71106) exited with code 3
[2023-12-04 23:43:45 +0100] [71104] [ERROR] Worker (pid:71107) was sent SIGTERM!
[2023-12-04 23:43:45 +0100] [71108] [ERROR] Exception in worker process
Traceback (most recent call last):
  File "/home/samuel/Documents/freelance/xceedr-api/venv/lib/python3.10/site-packages/gunicorn/arbiter.py", line 609, in spawn_worker
    worker.init_process()
  File "/home/samuel/Documents/freelance/xceedr-api/venv/lib/python3.10/site-packages/gunicorn/workers/base.py", line 134, in init_process
    self.load_wsgi()
  File "/home/samuel/Documents/freelance/xceedr-api/venv/lib/python3.10/site-packages/gunicorn/workers/base.py", line 146, in load_wsgi
    self.wsgi = self.app.wsgi()
  File "/home/samuel/Documents/freelance/xceedr-api/venv/lib/python3.10/site-packages/gunicorn/app/base.py", line 67, in wsgi
    self.callable = self.load()
  File "/home/samuel/Documents/freelance/xceedr-api/venv/lib/python3.10/site-packages/gunicorn/app/wsgiapp.py", line 58, in load
    return self.load_wsgiapp()
  File "/home/samuel/Documents/freelance/xceedr-api/venv/lib/python3.10/site-packages/gunicorn/app/wsgiapp.py", line 48, in load_wsgiapp
    return util.import_app(self.app_uri)
  File "/home/samuel/Documents/freelance/xceedr-api/venv/lib/python3.10/site-packages/gunicorn/util.py", line 371, in import_app
    mod = importlib.import_module(module)
  File "/usr/lib/python3.10/importlib/__init__.py", line 126, in import_module
    return _bootstrap._gcd_import(name[level:], package, level)
  File "<frozen importlib._bootstrap>", line 1050, in _gcd_import
  File "<frozen importlib._bootstrap>", line 1027, in _find_and_load
  File "<frozen importlib._bootstrap>", line 1006, in _find_and_load_unlocked
  File "<frozen importlib._bootstrap>", line 688, in _load_unlocked
  File "<frozen importlib._bootstrap_external>", line 883, in exec_module
  File "<frozen importlib._bootstrap>", line 241, in _call_with_frames_removed
  File "/home/samuel/Documents/freelance/xceedr-api/run.py", line 24, in <module>
    app = create_app(app_config)
  File "/home/samuel/Documents/freelance/xceedr-api/volumx/__init__.py", line 96, in create_app
    db.create_all()
  File "/home/samuel/Documents/freelance/xceedr-api/venv/lib/python3.10/site-packages/flask_sqlalchemy/extension.py", line 900, in create_all
    self._call_for_binds(bind_key, "create_all")
  File "/home/samuel/Documents/freelance/xceedr-api/venv/lib/python3.10/site-packages/flask_sqlalchemy/extension.py", line 881, in _call_for_binds
    getattr(metadata, op_name)(bind=engine)
  File "/home/samuel/Documents/freelance/xceedr-api/venv/lib/python3.10/site-packages/sqlalchemy/sql/schema.py", line 5828, in create_all
    bind._run_ddl_visitor(
  File "/home/samuel/Documents/freelance/xceedr-api/venv/lib/python3.10/site-packages/sqlalchemy/engine/base.py", line 3243, in _run_ddl_visitor
    conn._run_ddl_visitor(visitorcallable, element, **kwargs)
  File "/home/samuel/Documents/freelance/xceedr-api/venv/lib/python3.10/site-packages/sqlalchemy/engine/base.py", line 2447, in _run_ddl_visitor
    visitorcallable(self.dialect, self, **kwargs).traverse_single(element)
  File "/home/samuel/Documents/freelance/xceedr-api/venv/lib/python3.10/site-packages/sqlalchemy/sql/visitors.py", line 671, in traverse_single
    return meth(obj, **kw)
  File "/home/samuel/Documents/freelance/xceedr-api/venv/lib/python3.10/site-packages/sqlalchemy/sql/ddl.py", line 897, in visit_metadata
    collection = sort_tables_and_constraints(
  File "/home/samuel/Documents/freelance/xceedr-api/venv/lib/python3.10/site-packages/sqlalchemy/sql/ddl.py", line 1327, in sort_tables_and_constraints
    dependent_on = fkc.referred_table
  File "/home/samuel/Documents/freelance/xceedr-api/venv/lib/python3.10/site-packages/sqlalchemy/sql/schema.py", line 4751, in referred_table
    return self.elements[0].column.table
  File "/home/samuel/Documents/freelance/xceedr-api/venv/lib/python3.10/site-packages/sqlalchemy/util/langhelpers.py", line 1146, in __get__
    obj.__dict__[self.__name__] = result = self.fget(obj)
  File "/home/samuel/Documents/freelance/xceedr-api/venv/lib/python3.10/site-packages/sqlalchemy/sql/schema.py", line 3159, in column
    return self._resolve_column()
  File "/home/samuel/Documents/freelance/xceedr-api/venv/lib/python3.10/site-packages/sqlalchemy/sql/schema.py", line 3182, in _resolve_column
    raise exc.NoReferencedTableError(
sqlalchemy.exc.NoReferencedTableError: Foreign key associated with column 'business_user_rights.userId' could not find table 'user' with which to generate a foreign key to target column 'id'
[2023-12-04 23:43:45 +0100] [71108] [INFO] Worker exiting (pid: 71108)
[2023-12-04 23:43:45 +0100] [71109] [ERROR] Exception in worker process
Traceback (most recent call last):
  File "/home/samuel/Documents/freelance/xceedr-api/venv/lib/python3.10/site-packages/gunicorn/arbiter.py", line 609, in spawn_worker
    worker.init_process()
  File "/home/samuel/Documents/freelance/xceedr-api/venv/lib/python3.10/site-packages/gunicorn/workers/base.py", line 134, in init_process
    self.load_wsgi()
  File "/home/samuel/Documents/freelance/xceedr-api/venv/lib/python3.10/site-packages/gunicorn/workers/base.py", line 146, in load_wsgi
    self.wsgi = self.app.wsgi()
  File "/home/samuel/Documents/freelance/xceedr-api/venv/lib/python3.10/site-packages/gunicorn/app/base.py", line 67, in wsgi
    self.callable = self.load()
  File "/home/samuel/Documents/freelance/xceedr-api/venv/lib/python3.10/site-packages/gunicorn/app/wsgiapp.py", line 58, in load
    return self.load_wsgiapp()
  File "/home/samuel/Documents/freelance/xceedr-api/venv/lib/python3.10/site-packages/gunicorn/app/wsgiapp.py", line 48, in load_wsgiapp
    return util.import_app(self.app_uri)
  File "/home/samuel/Documents/freelance/xceedr-api/venv/lib/python3.10/site-packages/gunicorn/util.py", line 371, in import_app
    mod = importlib.import_module(module)
  File "/usr/lib/python3.10/importlib/__init__.py", line 126, in import_module
    return _bootstrap._gcd_import(name[level:], package, level)
  File "<frozen importlib._bootstrap>", line 1050, in _gcd_import
  File "<frozen importlib._bootstrap>", line 1027, in _find_and_load
  File "<frozen importlib._bootstrap>", line 1006, in _find_and_load_unlocked
  File "<frozen importlib._bootstrap>", line 688, in _load_unlocked
  File "<frozen importlib._bootstrap_external>", line 883, in exec_module
  File "<frozen importlib._bootstrap>", line 241, in _call_with_frames_removed
  File "/home/samuel/Documents/freelance/xceedr-api/run.py", line 24, in <module>
    app = create_app(app_config)
  File "/home/samuel/Documents/freelance/xceedr-api/volumx/__init__.py", line 96, in create_app
    db.create_all()
  File "/home/samuel/Documents/freelance/xceedr-api/venv/lib/python3.10/site-packages/flask_sqlalchemy/extension.py", line 900, in create_all
    self._call_for_binds(bind_key, "create_all")
  File "/home/samuel/Documents/freelance/xceedr-api/venv/lib/python3.10/site-packages/flask_sqlalchemy/extension.py", line 881, in _call_for_binds
    getattr(metadata, op_name)(bind=engine)
  File "/home/samuel/Documents/freelance/xceedr-api/venv/lib/python3.10/site-packages/sqlalchemy/sql/schema.py", line 5828, in create_all
    bind._run_ddl_visitor(
  File "/home/samuel/Documents/freelance/xceedr-api/venv/lib/python3.10/site-packages/sqlalchemy/engine/base.py", line 3243, in _run_ddl_visitor
    conn._run_ddl_visitor(visitorcallable, element, **kwargs)
  File "/home/samuel/Documents/freelance/xceedr-api/venv/lib/python3.10/site-packages/sqlalchemy/engine/base.py", line 2447, in _run_ddl_visitor
    visitorcallable(self.dialect, self, **kwargs).traverse_single(element)
  File "/home/samuel/Documents/freelance/xceedr-api/venv/lib/python3.10/site-packages/sqlalchemy/sql/visitors.py", line 671, in traverse_single
    return meth(obj, **kw)
  File "/home/samuel/Documents/freelance/xceedr-api/venv/lib/python3.10/site-packages/sqlalchemy/sql/ddl.py", line 897, in visit_metadata
    collection = sort_tables_and_constraints(
  File "/home/samuel/Documents/freelance/xceedr-api/venv/lib/python3.10/site-packages/sqlalchemy/sql/ddl.py", line 1327, in sort_tables_and_constraints
    dependent_on = fkc.referred_table
  File "/home/samuel/Documents/freelance/xceedr-api/venv/lib/python3.10/site-packages/sqlalchemy/sql/schema.py", line 4751, in referred_table
    return self.elements[0].column.table
  File "/home/samuel/Documents/freelance/xceedr-api/venv/lib/python3.10/site-packages/sqlalchemy/util/langhelpers.py", line 1146, in __get__
    obj.__dict__[self.__name__] = result = self.fget(obj)
  File "/home/samuel/Documents/freelance/xceedr-api/venv/lib/python3.10/site-packages/sqlalchemy/sql/schema.py", line 3159, in column
    return self._resolve_column()
  File "/home/samuel/Documents/freelance/xceedr-api/venv/lib/python3.10/site-packages/sqlalchemy/sql/schema.py", line 3182, in _resolve_column
    raise exc.NoReferencedTableError(
sqlalchemy.exc.NoReferencedTableError: Foreign key associated with column 'business_user_rights.userId' could not find table 'user' with which to generate a foreign key to target column 'id'
[2023-12-04 23:43:45 +0100] [71109] [INFO] Worker exiting (pid: 71109)
[2023-12-04 23:43:45 +0100] [71104] [ERROR] Worker (pid:71109) exited with code 3
