[2023-12-04 23:32:04 +0100] [69696] [INFO] Starting gunicorn 21.2.0
[2023-12-04 23:32:04 +0100] [69696] [ERROR] Connection in use: ('0.0.0.0', 5000)
[2023-12-04 23:32:04 +0100] [69696] [ERROR] Retrying in 1 second.
[2023-12-04 23:32:05 +0100] [69696] [ERROR] Connection in use: ('0.0.0.0', 5000)
[2023-12-04 23:32:05 +0100] [69696] [ERROR] Retrying in 1 second.
[2023-12-04 23:32:06 +0100] [69696] [ERROR] Connection in use: ('0.0.0.0', 5000)
[2023-12-04 23:32:06 +0100] [69696] [ERROR] Retrying in 1 second.
[2023-12-04 23:32:07 +0100] [69696] [ERROR] Connection in use: ('0.0.0.0', 5000)
[2023-12-04 23:32:07 +0100] [69696] [ERROR] Retrying in 1 second.
[2023-12-04 23:32:08 +0100] [69696] [ERROR] Connection in use: ('0.0.0.0', 5000)
[2023-12-04 23:32:08 +0100] [69696] [ERROR] Retrying in 1 second.
[2023-12-04 23:32:09 +0100] [69696] [ERROR] Can't connect to ('0.0.0.0', 5000)
[2023-12-04 23:32:30 +0100] [69829] [INFO] Starting gunicorn 21.2.0
[2023-12-04 23:32:30 +0100] [69829] [INFO] Listening at: http://0.0.0.0:5000 (69829)
[2023-12-04 23:32:30 +0100] [69829] [INFO] Using worker: sync
[2023-12-04 23:32:30 +0100] [69831] [INFO] Booting worker with pid: 69831
[2023-12-04 23:32:30 +0100] [69831] [ERROR] Exception in worker process
Traceback (most recent call last):
  File "/home/samuel/Documents/freelance/xceedr-api/venv/lib/python3.10/site-packages/gunicorn/arbiter.py", line 609, in spawn_worker
    worker.init_process()
  File "/home/samuel/Documents/freelance/xceedr-api/venv/lib/python3.10/site-packages/gunicorn/workers/base.py", line 134, in init_process
    self.load_wsgi()
  File "/home/samuel/Documents/freelance/xceedr-api/venv/lib/python3.10/site-packages/gunicorn/workers/base.py", line 146, in load_wsgi
    self.wsgi = self.app.wsgi()
  File "/home/samuel/Documents/freelance/xceedr-api/venv/lib/python3.10/site-packages/gunicorn/app/base.py", line 67, in wsgi
    self.callable = self.load()
  File "/home/samuel/Documents/freelance/xceedr-api/venv/lib/python3.10/site-packages/gunicorn/app/wsgiapp.py", line 58, in load
    return self.load_wsgiapp()
  File "/home/samuel/Documents/freelance/xceedr-api/venv/lib/python3.10/site-packages/gunicorn/app/wsgiapp.py", line 48, in load_wsgiapp
    return util.import_app(self.app_uri)
  File "/home/samuel/Documents/freelance/xceedr-api/venv/lib/python3.10/site-packages/gunicorn/util.py", line 371, in import_app
    mod = importlib.import_module(module)
  File "/usr/lib/python3.10/importlib/__init__.py", line 126, in import_module
    return _bootstrap._gcd_import(name[level:], package, level)
  File "<frozen importlib._bootstrap>", line 1050, in _gcd_import
  File "<frozen importlib._bootstrap>", line 1027, in _find_and_load
  File "<frozen importlib._bootstrap>", line 1006, in _find_and_load_unlocked
  File "<frozen importlib._bootstrap>", line 688, in _load_unlocked
  File "<frozen importlib._bootstrap_external>", line 883, in exec_module
  File "<frozen importlib._bootstrap>", line 241, in _call_with_frames_removed
  File "/home/samuel/Documents/freelance/xceedr-api/run.py", line 1, in <module>
    from med_app import create_app, db
ModuleNotFoundError: No module named 'med_app'
[2023-12-04 23:32:30 +0100] [69831] [INFO] Worker exiting (pid: 69831)
[2023-12-04 23:32:30 +0100] [69832] [INFO] Booting worker with pid: 69832
[2023-12-04 23:32:30 +0100] [69832] [ERROR] Exception in worker process
Traceback (most recent call last):
  File "/home/samuel/Documents/freelance/xceedr-api/venv/lib/python3.10/site-packages/gunicorn/arbiter.py", line 609, in spawn_worker
    worker.init_process()
  File "/home/samuel/Documents/freelance/xceedr-api/venv/lib/python3.10/site-packages/gunicorn/workers/base.py", line 134, in init_process
    self.load_wsgi()
  File "/home/samuel/Documents/freelance/xceedr-api/venv/lib/python3.10/site-packages/gunicorn/workers/base.py", line 146, in load_wsgi
    self.wsgi = self.app.wsgi()
  File "/home/samuel/Documents/freelance/xceedr-api/venv/lib/python3.10/site-packages/gunicorn/app/base.py", line 67, in wsgi
    self.callable = self.load()
  File "/home/samuel/Documents/freelance/xceedr-api/venv/lib/python3.10/site-packages/gunicorn/app/wsgiapp.py", line 58, in load
    return self.load_wsgiapp()
  File "/home/samuel/Documents/freelance/xceedr-api/venv/lib/python3.10/site-packages/gunicorn/app/wsgiapp.py", line 48, in load_wsgiapp
    return util.import_app(self.app_uri)
  File "/home/samuel/Documents/freelance/xceedr-api/venv/lib/python3.10/site-packages/gunicorn/util.py", line 371, in import_app
    mod = importlib.import_module(module)
  File "/usr/lib/python3.10/importlib/__init__.py", line 126, in import_module
    return _bootstrap._gcd_import(name[level:], package, level)
  File "<frozen importlib._bootstrap>", line 1050, in _gcd_import
  File "<frozen importlib._bootstrap>", line 1027, in _find_and_load
  File "<frozen importlib._bootstrap>", line 1006, in _find_and_load_unlocked
  File "<frozen importlib._bootstrap>", line 688, in _load_unlocked
  File "<frozen importlib._bootstrap_external>", line 883, in exec_module
  File "<frozen importlib._bootstrap>", line 241, in _call_with_frames_removed
  File "/home/samuel/Documents/freelance/xceedr-api/run.py", line 1, in <module>
    from med_app import create_app, db
ModuleNotFoundError: No module named 'med_app'
[2023-12-04 23:32:30 +0100] [69832] [INFO] Worker exiting (pid: 69832)
[2023-12-04 23:32:30 +0100] [69829] [ERROR] Worker (pid:69831) exited with code 3
[2023-12-04 23:32:30 +0100] [69829] [ERROR] Worker (pid:69832) was sent SIGTERM!
[2023-12-04 23:32:30 +0100] [69829] [ERROR] Shutting down: Master
[2023-12-04 23:32:30 +0100] [69829] [ERROR] Reason: Worker failed to boot.
[2023-12-04 23:34:03 +0100] [70049] [INFO] Starting gunicorn 21.2.0
[2023-12-04 23:34:03 +0100] [70049] [INFO] Listening at: http://0.0.0.0:5000 (70049)
[2023-12-04 23:34:03 +0100] [70049] [INFO] Using worker: sync
[2023-12-04 23:34:03 +0100] [70050] [INFO] Booting worker with pid: 70050
[2023-12-04 23:34:03 +0100] [70051] [INFO] Booting worker with pid: 70051
[2023-12-04 23:34:03 +0100] [70052] [INFO] Booting worker with pid: 70052
[2023-12-04 23:34:03 +0100] [70053] [INFO] Booting worker with pid: 70053
[2023-12-04 23:34:03 +0100] [70051] [ERROR] Exception in worker process
Traceback (most recent call last):
  File "/home/samuel/Documents/freelance/xceedr-api/venv/lib/python3.10/site-packages/gunicorn/arbiter.py", line 609, in spawn_worker
    worker.init_process()
  File "/home/samuel/Documents/freelance/xceedr-api/venv/lib/python3.10/site-packages/gunicorn/workers/base.py", line 134, in init_process
    self.load_wsgi()
  File "/home/samuel/Documents/freelance/xceedr-api/venv/lib/python3.10/site-packages/gunicorn/workers/base.py", line 146, in load_wsgi
    self.wsgi = self.app.wsgi()
  File "/home/samuel/Documents/freelance/xceedr-api/venv/lib/python3.10/site-packages/gunicorn/app/base.py", line 67, in wsgi
    self.callable = self.load()
  File "/home/samuel/Documents/freelance/xceedr-api/venv/lib/python3.10/site-packages/gunicorn/app/wsgiapp.py", line 58, in load
    return self.load_wsgiapp()
  File "/home/samuel/Documents/freelance/xceedr-api/venv/lib/python3.10/site-packages/gunicorn/app/wsgiapp.py", line 48, in load_wsgiapp
    return util.import_app(self.app_uri)
  File "/home/samuel/Documents/freelance/xceedr-api/venv/lib/python3.10/site-packages/gunicorn/util.py", line 371, in import_app
    mod = importlib.import_module(module)
  File "/usr/lib/python3.10/importlib/__init__.py", line 126, in import_module
    return _bootstrap._gcd_import(name[level:], package, level)
  File "<frozen importlib._bootstrap>", line 1050, in _gcd_import
  File "<frozen importlib._bootstrap>", line 1027, in _find_and_load
  File "<frozen importlib._bootstrap>", line 1006, in _find_and_load_unlocked
  File "<frozen importlib._bootstrap>", line 688, in _load_unlocked
  File "<frozen importlib._bootstrap_external>", line 883, in exec_module
  File "<frozen importlib._bootstrap>", line 241, in _call_with_frames_removed
  File "/home/samuel/Documents/freelance/xceedr-api/run.py", line 24, in <module>
    app = create_app(app_config)
  File "/home/samuel/Documents/freelance/xceedr-api/volumx/__init__.py", line 49, in create_app
    with open("swagger_config.yaml", "r") as file:
FileNotFoundError: [Errno 2] No such file or directory: 'swagger_config.yaml'
[2023-12-04 23:34:03 +0100] [70051] [INFO] Worker exiting (pid: 70051)
[2023-12-04 23:34:03 +0100] [70050] [ERROR] Exception in worker process
Traceback (most recent call last):
  File "/home/samuel/Documents/freelance/xceedr-api/venv/lib/python3.10/site-packages/gunicorn/arbiter.py", line 609, in spawn_worker
    worker.init_process()
  File "/home/samuel/Documents/freelance/xceedr-api/venv/lib/python3.10/site-packages/gunicorn/workers/base.py", line 134, in init_process
    self.load_wsgi()
  File "/home/samuel/Documents/freelance/xceedr-api/venv/lib/python3.10/site-packages/gunicorn/workers/base.py", line 146, in load_wsgi
    self.wsgi = self.app.wsgi()
  File "/home/samuel/Documents/freelance/xceedr-api/venv/lib/python3.10/site-packages/gunicorn/app/base.py", line 67, in wsgi
    self.callable = self.load()
  File "/home/samuel/Documents/freelance/xceedr-api/venv/lib/python3.10/site-packages/gunicorn/app/wsgiapp.py", line 58, in load
    return self.load_wsgiapp()
  File "/home/samuel/Documents/freelance/xceedr-api/venv/lib/python3.10/site-packages/gunicorn/app/wsgiapp.py", line 48, in load_wsgiapp
    return util.import_app(self.app_uri)
  File "/home/samuel/Documents/freelance/xceedr-api/venv/lib/python3.10/site-packages/gunicorn/util.py", line 371, in import_app
    mod = importlib.import_module(module)
  File "/usr/lib/python3.10/importlib/__init__.py", line 126, in import_module
    return _bootstrap._gcd_import(name[level:], package, level)
  File "<frozen importlib._bootstrap>", line 1050, in _gcd_import
  File "<frozen importlib._bootstrap>", line 1027, in _find_and_load
  File "<frozen importlib._bootstrap>", line 1006, in _find_and_load_unlocked
  File "<frozen importlib._bootstrap>", line 688, in _load_unlocked
  File "<frozen importlib._bootstrap_external>", line 883, in exec_module
  File "<frozen importlib._bootstrap>", line 241, in _call_with_frames_removed
  File "/home/samuel/Documents/freelance/xceedr-api/run.py", line 24, in <module>
    app = create_app(app_config)
  File "/home/samuel/Documents/freelance/xceedr-api/volumx/__init__.py", line 49, in create_app
    with open("swagger_config.yaml", "r") as file:
FileNotFoundError: [Errno 2] No such file or directory: 'swagger_config.yaml'
[2023-12-04 23:34:03 +0100] [70050] [INFO] Worker exiting (pid: 70050)
[2023-12-04 23:34:04 +0100] [70052] [ERROR] Exception in worker process
Traceback (most recent call last):
  File "/home/samuel/Documents/freelance/xceedr-api/venv/lib/python3.10/site-packages/gunicorn/arbiter.py", line 609, in spawn_worker
    worker.init_process()
  File "/home/samuel/Documents/freelance/xceedr-api/venv/lib/python3.10/site-packages/gunicorn/workers/base.py", line 134, in init_process
    self.load_wsgi()
  File "/home/samuel/Documents/freelance/xceedr-api/venv/lib/python3.10/site-packages/gunicorn/workers/base.py", line 146, in load_wsgi
    self.wsgi = self.app.wsgi()
  File "/home/samuel/Documents/freelance/xceedr-api/venv/lib/python3.10/site-packages/gunicorn/app/base.py", line 67, in wsgi
    self.callable = self.load()
  File "/home/samuel/Documents/freelance/xceedr-api/venv/lib/python3.10/site-packages/gunicorn/app/wsgiapp.py", line 58, in load
    return self.load_wsgiapp()
  File "/home/samuel/Documents/freelance/xceedr-api/venv/lib/python3.10/site-packages/gunicorn/app/wsgiapp.py", line 48, in load_wsgiapp
    return util.import_app(self.app_uri)
  File "/home/samuel/Documents/freelance/xceedr-api/venv/lib/python3.10/site-packages/gunicorn/util.py", line 371, in import_app
    mod = importlib.import_module(module)
  File "/usr/lib/python3.10/importlib/__init__.py", line 126, in import_module
    return _bootstrap._gcd_import(name[level:], package, level)
  File "<frozen importlib._bootstrap>", line 1050, in _gcd_import
  File "<frozen importlib._bootstrap>", line 1027, in _find_and_load
  File "<frozen importlib._bootstrap>", line 1006, in _find_and_load_unlocked
  File "<frozen importlib._bootstrap>", line 688, in _load_unlocked
  File "<frozen importlib._bootstrap_external>", line 883, in exec_module
  File "<frozen importlib._bootstrap>", line 241, in _call_with_frames_removed
  File "/home/samuel/Documents/freelance/xceedr-api/run.py", line 24, in <module>
    app = create_app(app_config)
  File "/home/samuel/Documents/freelance/xceedr-api/volumx/__init__.py", line 49, in create_app
    with open("swagger_config.yaml", "r") as file:
FileNotFoundError: [Errno 2] No such file or directory: 'swagger_config.yaml'
[2023-12-04 23:34:04 +0100] [70052] [INFO] Worker exiting (pid: 70052)
[2023-12-04 23:34:04 +0100] [70049] [ERROR] Worker (pid:70051) exited with code 3
[2023-12-04 23:34:04 +0100] [70049] [ERROR] Worker (pid:70052) was sent SIGTERM!
[2023-12-04 23:34:04 +0100] [70049] [ERROR] Worker (pid:70050) was sent SIGTERM!
[2023-12-04 23:34:04 +0100] [70053] [ERROR] Exception in worker process
Traceback (most recent call last):
  File "/home/samuel/Documents/freelance/xceedr-api/venv/lib/python3.10/site-packages/gunicorn/arbiter.py", line 609, in spawn_worker
    worker.init_process()
  File "/home/samuel/Documents/freelance/xceedr-api/venv/lib/python3.10/site-packages/gunicorn/workers/base.py", line 134, in init_process
    self.load_wsgi()
  File "/home/samuel/Documents/freelance/xceedr-api/venv/lib/python3.10/site-packages/gunicorn/workers/base.py", line 146, in load_wsgi
    self.wsgi = self.app.wsgi()
  File "/home/samuel/Documents/freelance/xceedr-api/venv/lib/python3.10/site-packages/gunicorn/app/base.py", line 67, in wsgi
    self.callable = self.load()
  File "/home/samuel/Documents/freelance/xceedr-api/venv/lib/python3.10/site-packages/gunicorn/app/wsgiapp.py", line 58, in load
    return self.load_wsgiapp()
  File "/home/samuel/Documents/freelance/xceedr-api/venv/lib/python3.10/site-packages/gunicorn/app/wsgiapp.py", line 48, in load_wsgiapp
    return util.import_app(self.app_uri)
  File "/home/samuel/Documents/freelance/xceedr-api/venv/lib/python3.10/site-packages/gunicorn/util.py", line 371, in import_app
    mod = importlib.import_module(module)
  File "/usr/lib/python3.10/importlib/__init__.py", line 126, in import_module
    return _bootstrap._gcd_import(name[level:], package, level)
  File "<frozen importlib._bootstrap>", line 1050, in _gcd_import
  File "<frozen importlib._bootstrap>", line 1027, in _find_and_load
  File "<frozen importlib._bootstrap>", line 1006, in _find_and_load_unlocked
  File "<frozen importlib._bootstrap>", line 688, in _load_unlocked
  File "<frozen importlib._bootstrap_external>", line 883, in exec_module
  File "<frozen importlib._bootstrap>", line 241, in _call_with_frames_removed
  File "/home/samuel/Documents/freelance/xceedr-api/run.py", line 24, in <module>
    app = create_app(app_config)
  File "/home/samuel/Documents/freelance/xceedr-api/volumx/__init__.py", line 49, in create_app
    with open("swagger_config.yaml", "r") as file:
FileNotFoundError: [Errno 2] No such file or directory: 'swagger_config.yaml'
[2023-12-04 23:34:04 +0100] [70053] [INFO] Worker exiting (pid: 70053)
[2023-12-04 23:34:04 +0100] [70049] [ERROR] Worker (pid:70053) exited with code 3
[2023-12-04 23:34:40 +0100] [70179] [INFO] Starting gunicorn 21.2.0
[2023-12-04 23:34:40 +0100] [70179] [INFO] Listening at: http://0.0.0.0:5000 (70179)
[2023-12-04 23:34:40 +0100] [70179] [INFO] Using worker: sync
[2023-12-04 23:34:40 +0100] [70180] [INFO] Booting worker with pid: 70180
[2023-12-04 23:34:40 +0100] [70181] [INFO] Booting worker with pid: 70181
[2023-12-04 23:34:40 +0100] [70182] [INFO] Booting worker with pid: 70182
[2023-12-04 23:34:40 +0100] [70183] [INFO] Booting worker with pid: 70183
[2023-12-04 23:34:41 +0100] [70180] [ERROR] Exception in worker process
Traceback (most recent call last):
  File "/home/samuel/Documents/freelance/xceedr-api/venv/lib/python3.10/site-packages/gunicorn/arbiter.py", line 609, in spawn_worker
    worker.init_process()
  File "/home/samuel/Documents/freelance/xceedr-api/venv/lib/python3.10/site-packages/gunicorn/workers/base.py", line 134, in init_process
    self.load_wsgi()
  File "/home/samuel/Documents/freelance/xceedr-api/venv/lib/python3.10/site-packages/gunicorn/workers/base.py", line 146, in load_wsgi
    self.wsgi = self.app.wsgi()
  File "/home/samuel/Documents/freelance/xceedr-api/venv/lib/python3.10/site-packages/gunicorn/app/base.py", line 67, in wsgi
    self.callable = self.load()
  File "/home/samuel/Documents/freelance/xceedr-api/venv/lib/python3.10/site-packages/gunicorn/app/wsgiapp.py", line 58, in load
    return self.load_wsgiapp()
  File "/home/samuel/Documents/freelance/xceedr-api/venv/lib/python3.10/site-packages/gunicorn/app/wsgiapp.py", line 48, in load_wsgiapp
    return util.import_app(self.app_uri)
  File "/home/samuel/Documents/freelance/xceedr-api/venv/lib/python3.10/site-packages/gunicorn/util.py", line 371, in import_app
    mod = importlib.import_module(module)
  File "/usr/lib/python3.10/importlib/__init__.py", line 126, in import_module
    return _bootstrap._gcd_import(name[level:], package, level)
  File "<frozen importlib._bootstrap>", line 1050, in _gcd_import
  File "<frozen importlib._bootstrap>", line 1027, in _find_and_load
  File "<frozen importlib._bootstrap>", line 1006, in _find_and_load_unlocked
  File "<frozen importlib._bootstrap>", line 688, in _load_unlocked
  File "<frozen importlib._bootstrap_external>", line 883, in exec_module
  File "<frozen importlib._bootstrap>", line 241, in _call_with_frames_removed
  File "/home/samuel/Documents/freelance/xceedr-api/run.py", line 24, in <module>
    app = create_app(app_config)
  File "/home/samuel/Documents/freelance/xceedr-api/volumx/__init__.py", line 96, in create_app
    db.create_all()
  File "/home/samuel/Documents/freelance/xceedr-api/venv/lib/python3.10/site-packages/flask_sqlalchemy/extension.py", line 900, in create_all
    self._call_for_binds(bind_key, "create_all")
  File "/home/samuel/Documents/freelance/xceedr-api/venv/lib/python3.10/site-packages/flask_sqlalchemy/extension.py", line 881, in _call_for_binds
    getattr(metadata, op_name)(bind=engine)
  File "/home/samuel/Documents/freelance/xceedr-api/venv/lib/python3.10/site-packages/sqlalchemy/sql/schema.py", line 5828, in create_all
    bind._run_ddl_visitor(
  File "/home/samuel/Documents/freelance/xceedr-api/venv/lib/python3.10/site-packages/sqlalchemy/engine/base.py", line 3243, in _run_ddl_visitor
    conn._run_ddl_visitor(visitorcallable, element, **kwargs)
  File "/home/samuel/Documents/freelance/xceedr-api/venv/lib/python3.10/site-packages/sqlalchemy/engine/base.py", line 2447, in _run_ddl_visitor
    visitorcallable(self.dialect, self, **kwargs).traverse_single(element)
  File "/home/samuel/Documents/freelance/xceedr-api/venv/lib/python3.10/site-packages/sqlalchemy/sql/visitors.py", line 671, in traverse_single
    return meth(obj, **kw)
  File "/home/samuel/Documents/freelance/xceedr-api/venv/lib/python3.10/site-packages/sqlalchemy/sql/ddl.py", line 897, in visit_metadata
    collection = sort_tables_and_constraints(
  File "/home/samuel/Documents/freelance/xceedr-api/venv/lib/python3.10/site-packages/sqlalchemy/sql/ddl.py", line 1327, in sort_tables_and_constraints
    dependent_on = fkc.referred_table
  File "/home/samuel/Documents/freelance/xceedr-api/venv/lib/python3.10/site-packages/sqlalchemy/sql/schema.py", line 4751, in referred_table
    return self.elements[0].column.table
  File "/home/samuel/Documents/freelance/xceedr-api/venv/lib/python3.10/site-packages/sqlalchemy/util/langhelpers.py", line 1146, in __get__
    obj.__dict__[self.__name__] = result = self.fget(obj)
  File "/home/samuel/Documents/freelance/xceedr-api/venv/lib/python3.10/site-packages/sqlalchemy/sql/schema.py", line 3159, in column
    return self._resolve_column()
  File "/home/samuel/Documents/freelance/xceedr-api/venv/lib/python3.10/site-packages/sqlalchemy/sql/schema.py", line 3182, in _resolve_column
    raise exc.NoReferencedTableError(
sqlalchemy.exc.NoReferencedTableError: Foreign key associated with column 'business_user_rights.userId' could not find table 'user' with which to generate a foreign key to target column 'id'
[2023-12-04 23:34:41 +0100] [70180] [INFO] Worker exiting (pid: 70180)
[2023-12-04 23:34:41 +0100] [70182] [ERROR] Exception in worker process
Traceback (most recent call last):
  File "/home/samuel/Documents/freelance/xceedr-api/venv/lib/python3.10/site-packages/gunicorn/arbiter.py", line 609, in spawn_worker
    worker.init_process()
  File "/home/samuel/Documents/freelance/xceedr-api/venv/lib/python3.10/site-packages/gunicorn/workers/base.py", line 134, in init_process
    self.load_wsgi()
  File "/home/samuel/Documents/freelance/xceedr-api/venv/lib/python3.10/site-packages/gunicorn/workers/base.py", line 146, in load_wsgi
    self.wsgi = self.app.wsgi()
  File "/home/samuel/Documents/freelance/xceedr-api/venv/lib/python3.10/site-packages/gunicorn/app/base.py", line 67, in wsgi
    self.callable = self.load()
  File "/home/samuel/Documents/freelance/xceedr-api/venv/lib/python3.10/site-packages/gunicorn/app/wsgiapp.py", line 58, in load
    return self.load_wsgiapp()
  File "/home/samuel/Documents/freelance/xceedr-api/venv/lib/python3.10/site-packages/gunicorn/app/wsgiapp.py", line 48, in load_wsgiapp
    return util.import_app(self.app_uri)
  File "/home/samuel/Documents/freelance/xceedr-api/venv/lib/python3.10/site-packages/gunicorn/util.py", line 371, in import_app
    mod = importlib.import_module(module)
  File "/usr/lib/python3.10/importlib/__init__.py", line 126, in import_module
    return _bootstrap._gcd_import(name[level:], package, level)
  File "<frozen importlib._bootstrap>", line 1050, in _gcd_import
  File "<frozen importlib._bootstrap>", line 1027, in _find_and_load
  File "<frozen importlib._bootstrap>", line 1006, in _find_and_load_unlocked
  File "<frozen importlib._bootstrap>", line 688, in _load_unlocked
  File "<frozen importlib._bootstrap_external>", line 883, in exec_module
  File "<frozen importlib._bootstrap>", line 241, in _call_with_frames_removed
  File "/home/samuel/Documents/freelance/xceedr-api/run.py", line 24, in <module>
    app = create_app(app_config)
  File "/home/samuel/Documents/freelance/xceedr-api/volumx/__init__.py", line 96, in create_app
    db.create_all()
  File "/home/samuel/Documents/freelance/xceedr-api/venv/lib/python3.10/site-packages/flask_sqlalchemy/extension.py", line 900, in create_all
    self._call_for_binds(bind_key, "create_all")
  File "/home/samuel/Documents/freelance/xceedr-api/venv/lib/python3.10/site-packages/flask_sqlalchemy/extension.py", line 881, in _call_for_binds
    getattr(metadata, op_name)(bind=engine)
  File "/home/samuel/Documents/freelance/xceedr-api/venv/lib/python3.10/site-packages/sqlalchemy/sql/schema.py", line 5828, in create_all
    bind._run_ddl_visitor(
  File "/home/samuel/Documents/freelance/xceedr-api/venv/lib/python3.10/site-packages/sqlalchemy/engine/base.py", line 3243, in _run_ddl_visitor
    conn._run_ddl_visitor(visitorcallable, element, **kwargs)
  File "/home/samuel/Documents/freelance/xceedr-api/venv/lib/python3.10/site-packages/sqlalchemy/engine/base.py", line 2447, in _run_ddl_visitor
    visitorcallable(self.dialect, self, **kwargs).traverse_single(element)
  File "/home/samuel/Documents/freelance/xceedr-api/venv/lib/python3.10/site-packages/sqlalchemy/sql/visitors.py", line 671, in traverse_single
    return meth(obj, **kw)
  File "/home/samuel/Documents/freelance/xceedr-api/venv/lib/python3.10/site-packages/sqlalchemy/sql/ddl.py", line 897, in visit_metadata
    collection = sort_tables_and_constraints(
  File "/home/samuel/Documents/freelance/xceedr-api/venv/lib/python3.10/site-packages/sqlalchemy/sql/ddl.py", line 1327, in sort_tables_and_constraints
    dependent_on = fkc.referred_table
  File "/home/samuel/Documents/freelance/xceedr-api/venv/lib/python3.10/site-packages/sqlalchemy/sql/schema.py", line 4751, in referred_table
    return self.elements[0].column.table
  File "/home/samuel/Documents/freelance/xceedr-api/venv/lib/python3.10/site-packages/sqlalchemy/util/langhelpers.py", line 1146, in __get__
    obj.__dict__[self.__name__] = result = self.fget(obj)
  File "/home/samuel/Documents/freelance/xceedr-api/venv/lib/python3.10/site-packages/sqlalchemy/sql/schema.py", line 3159, in column
    return self._resolve_column()
  File "/home/samuel/Documents/freelance/xceedr-api/venv/lib/python3.10/site-packages/sqlalchemy/sql/schema.py", line 3182, in _resolve_column
    raise exc.NoReferencedTableError(
sqlalchemy.exc.NoReferencedTableError: Foreign key associated with column 'business_user_rights.userId' could not find table 'user' with which to generate a foreign key to target column 'id'
[2023-12-04 23:34:41 +0100] [70182] [INFO] Worker exiting (pid: 70182)
[2023-12-04 23:34:41 +0100] [70179] [ERROR] Worker (pid:70180) exited with code 3
[2023-12-04 23:34:41 +0100] [70179] [ERROR] Worker (pid:70182) was sent SIGTERM!
[2023-12-04 23:34:41 +0100] [70181] [ERROR] Exception in worker process
Traceback (most recent call last):
  File "/home/samuel/Documents/freelance/xceedr-api/venv/lib/python3.10/site-packages/gunicorn/arbiter.py", line 609, in spawn_worker
    worker.init_process()
  File "/home/samuel/Documents/freelance/xceedr-api/venv/lib/python3.10/site-packages/gunicorn/workers/base.py", line 134, in init_process
    self.load_wsgi()
  File "/home/samuel/Documents/freelance/xceedr-api/venv/lib/python3.10/site-packages/gunicorn/workers/base.py", line 146, in load_wsgi
    self.wsgi = self.app.wsgi()
  File "/home/samuel/Documents/freelance/xceedr-api/venv/lib/python3.10/site-packages/gunicorn/app/base.py", line 67, in wsgi
    self.callable = self.load()
  File "/home/samuel/Documents/freelance/xceedr-api/venv/lib/python3.10/site-packages/gunicorn/app/wsgiapp.py", line 58, in load
    return self.load_wsgiapp()
  File "/home/samuel/Documents/freelance/xceedr-api/venv/lib/python3.10/site-packages/gunicorn/app/wsgiapp.py", line 48, in load_wsgiapp
    return util.import_app(self.app_uri)
  File "/home/samuel/Documents/freelance/xceedr-api/venv/lib/python3.10/site-packages/gunicorn/util.py", line 371, in import_app
    mod = importlib.import_module(module)
  File "/usr/lib/python3.10/importlib/__init__.py", line 126, in import_module
    return _bootstrap._gcd_import(name[level:], package, level)
  File "<frozen importlib._bootstrap>", line 1050, in _gcd_import
  File "<frozen importlib._bootstrap>", line 1027, in _find_and_load
  File "<frozen importlib._bootstrap>", line 1006, in _find_and_load_unlocked
  File "<frozen importlib._bootstrap>", line 688, in _load_unlocked
  File "<frozen importlib._bootstrap_external>", line 883, in exec_module
  File "<frozen importlib._bootstrap>", line 241, in _call_with_frames_removed
  File "/home/samuel/Documents/freelance/xceedr-api/run.py", line 24, in <module>
    app = create_app(app_config)
  File "/home/samuel/Documents/freelance/xceedr-api/volumx/__init__.py", line 96, in create_app
    db.create_all()
  File "/home/samuel/Documents/freelance/xceedr-api/venv/lib/python3.10/site-packages/flask_sqlalchemy/extension.py", line 900, in create_all
    self._call_for_binds(bind_key, "create_all")
  File "/home/samuel/Documents/freelance/xceedr-api/venv/lib/python3.10/site-packages/flask_sqlalchemy/extension.py", line 881, in _call_for_binds
    getattr(metadata, op_name)(bind=engine)
  File "/home/samuel/Documents/freelance/xceedr-api/venv/lib/python3.10/site-packages/sqlalchemy/sql/schema.py", line 5828, in create_all
    bind._run_ddl_visitor(
  File "/home/samuel/Documents/freelance/xceedr-api/venv/lib/python3.10/site-packages/sqlalchemy/engine/base.py", line 3243, in _run_ddl_visitor
    conn._run_ddl_visitor(visitorcallable, element, **kwargs)
  File "/home/samuel/Documents/freelance/xceedr-api/venv/lib/python3.10/site-packages/sqlalchemy/engine/base.py", line 2447, in _run_ddl_visitor
    visitorcallable(self.dialect, self, **kwargs).traverse_single(element)
  File "/home/samuel/Documents/freelance/xceedr-api/venv/lib/python3.10/site-packages/sqlalchemy/sql/visitors.py", line 671, in traverse_single
    return meth(obj, **kw)
  File "/home/samuel/Documents/freelance/xceedr-api/venv/lib/python3.10/site-packages/sqlalchemy/sql/ddl.py", line 897, in visit_metadata
    collection = sort_tables_and_constraints(
  File "/home/samuel/Documents/freelance/xceedr-api/venv/lib/python3.10/site-packages/sqlalchemy/sql/ddl.py", line 1327, in sort_tables_and_constraints
    dependent_on = fkc.referred_table
  File "/home/samuel/Documents/freelance/xceedr-api/venv/lib/python3.10/site-packages/sqlalchemy/sql/schema.py", line 4751, in referred_table
    return self.elements[0].column.table
  File "/home/samuel/Documents/freelance/xceedr-api/venv/lib/python3.10/site-packages/sqlalchemy/util/langhelpers.py", line 1146, in __get__
    obj.__dict__[self.__name__] = result = self.fget(obj)
  File "/home/samuel/Documents/freelance/xceedr-api/venv/lib/python3.10/site-packages/sqlalchemy/sql/schema.py", line 3159, in column
    return self._resolve_column()
  File "/home/samuel/Documents/freelance/xceedr-api/venv/lib/python3.10/site-packages/sqlalchemy/sql/schema.py", line 3182, in _resolve_column
    raise exc.NoReferencedTableError(
sqlalchemy.exc.NoReferencedTableError: Foreign key associated with column 'business_user_rights.userId' could not find table 'user' with which to generate a foreign key to target column 'id'
[2023-12-04 23:34:41 +0100] [70181] [INFO] Worker exiting (pid: 70181)
[2023-12-04 23:34:41 +0100] [70183] [ERROR] Exception in worker process
Traceback (most recent call last):
  File "/home/samuel/Documents/freelance/xceedr-api/venv/lib/python3.10/site-packages/gunicorn/arbiter.py", line 609, in spawn_worker
    worker.init_process()
  File "/home/samuel/Documents/freelance/xceedr-api/venv/lib/python3.10/site-packages/gunicorn/workers/base.py", line 134, in init_process
    self.load_wsgi()
  File "/home/samuel/Documents/freelance/xceedr-api/venv/lib/python3.10/site-packages/gunicorn/workers/base.py", line 146, in load_wsgi
    self.wsgi = self.app.wsgi()
  File "/home/samuel/Documents/freelance/xceedr-api/venv/lib/python3.10/site-packages/gunicorn/app/base.py", line 67, in wsgi
    self.callable = self.load()
  File "/home/samuel/Documents/freelance/xceedr-api/venv/lib/python3.10/site-packages/gunicorn/app/wsgiapp.py", line 58, in load
    return self.load_wsgiapp()
  File "/home/samuel/Documents/freelance/xceedr-api/venv/lib/python3.10/site-packages/gunicorn/app/wsgiapp.py", line 48, in load_wsgiapp
    return util.import_app(self.app_uri)
  File "/home/samuel/Documents/freelance/xceedr-api/venv/lib/python3.10/site-packages/gunicorn/util.py", line 371, in import_app
    mod = importlib.import_module(module)
  File "/usr/lib/python3.10/importlib/__init__.py", line 126, in import_module
    return _bootstrap._gcd_import(name[level:], package, level)
  File "<frozen importlib._bootstrap>", line 1050, in _gcd_import
  File "<frozen importlib._bootstrap>", line 1027, in _find_and_load
  File "<frozen importlib._bootstrap>", line 1006, in _find_and_load_unlocked
  File "<frozen importlib._bootstrap>", line 688, in _load_unlocked
  File "<frozen importlib._bootstrap_external>", line 883, in exec_module
  File "<frozen importlib._bootstrap>", line 241, in _call_with_frames_removed
  File "/home/samuel/Documents/freelance/xceedr-api/run.py", line 24, in <module>
    app = create_app(app_config)
  File "/home/samuel/Documents/freelance/xceedr-api/volumx/__init__.py", line 96, in create_app
    db.create_all()
  File "/home/samuel/Documents/freelance/xceedr-api/venv/lib/python3.10/site-packages/flask_sqlalchemy/extension.py", line 900, in create_all
    self._call_for_binds(bind_key, "create_all")
  File "/home/samuel/Documents/freelance/xceedr-api/venv/lib/python3.10/site-packages/flask_sqlalchemy/extension.py", line 881, in _call_for_binds
    getattr(metadata, op_name)(bind=engine)
  File "/home/samuel/Documents/freelance/xceedr-api/venv/lib/python3.10/site-packages/sqlalchemy/sql/schema.py", line 5828, in create_all
    bind._run_ddl_visitor(
  File "/home/samuel/Documents/freelance/xceedr-api/venv/lib/python3.10/site-packages/sqlalchemy/engine/base.py", line 3243, in _run_ddl_visitor
    conn._run_ddl_visitor(visitorcallable, element, **kwargs)
  File "/home/samuel/Documents/freelance/xceedr-api/venv/lib/python3.10/site-packages/sqlalchemy/engine/base.py", line 2447, in _run_ddl_visitor
    visitorcallable(self.dialect, self, **kwargs).traverse_single(element)
  File "/home/samuel/Documents/freelance/xceedr-api/venv/lib/python3.10/site-packages/sqlalchemy/sql/visitors.py", line 671, in traverse_single
    return meth(obj, **kw)
  File "/home/samuel/Documents/freelance/xceedr-api/venv/lib/python3.10/site-packages/sqlalchemy/sql/ddl.py", line 897, in visit_metadata
    collection = sort_tables_and_constraints(
  File "/home/samuel/Documents/freelance/xceedr-api/venv/lib/python3.10/site-packages/sqlalchemy/sql/ddl.py", line 1327, in sort_tables_and_constraints
    dependent_on = fkc.referred_table
  File "/home/samuel/Documents/freelance/xceedr-api/venv/lib/python3.10/site-packages/sqlalchemy/sql/schema.py", line 4751, in referred_table
    return self.elements[0].column.table
  File "/home/samuel/Documents/freelance/xceedr-api/venv/lib/python3.10/site-packages/sqlalchemy/util/langhelpers.py", line 1146, in __get__
    obj.__dict__[self.__name__] = result = self.fget(obj)
  File "/home/samuel/Documents/freelance/xceedr-api/venv/lib/python3.10/site-packages/sqlalchemy/sql/schema.py", line 3159, in column
    return self._resolve_column()
  File "/home/samuel/Documents/freelance/xceedr-api/venv/lib/python3.10/site-packages/sqlalchemy/sql/schema.py", line 3182, in _resolve_column
    raise exc.NoReferencedTableError(
sqlalchemy.exc.NoReferencedTableError: Foreign key associated with column 'business_user_rights.userId' could not find table 'user' with which to generate a foreign key to target column 'id'
[2023-12-04 23:34:41 +0100] [70183] [INFO] Worker exiting (pid: 70183)
[2023-12-04 23:34:42 +0100] [70179] [ERROR] Worker (pid:70181) exited with code 3
[2023-12-04 23:37:01 +0100] [70455] [INFO] Starting gunicorn 21.2.0
[2023-12-04 23:37:01 +0100] [70455] [INFO] Listening at: http://0.0.0.0:5000 (70455)
[2023-12-04 23:37:01 +0100] [70455] [INFO] Using worker: sync
[2023-12-04 23:37:01 +0100] [70457] [INFO] Booting worker with pid: 70457
[2023-12-04 23:37:01 +0100] [70458] [INFO] Booting worker with pid: 70458
[2023-12-04 23:37:01 +0100] [70459] [INFO] Booting worker with pid: 70459
[2023-12-04 23:37:01 +0100] [70460] [INFO] Booting worker with pid: 70460
[2023-12-04 23:37:02 +0100] [70458] [ERROR] Exception in worker process
Traceback (most recent call last):
  File "/home/samuel/Documents/freelance/xceedr-api/venv/lib/python3.10/site-packages/gunicorn/arbiter.py", line 609, in spawn_worker
    worker.init_process()
  File "/home/samuel/Documents/freelance/xceedr-api/venv/lib/python3.10/site-packages/gunicorn/workers/base.py", line 134, in init_process
    self.load_wsgi()
  File "/home/samuel/Documents/freelance/xceedr-api/venv/lib/python3.10/site-packages/gunicorn/workers/base.py", line 146, in load_wsgi
    self.wsgi = self.app.wsgi()
  File "/home/samuel/Documents/freelance/xceedr-api/venv/lib/python3.10/site-packages/gunicorn/app/base.py", line 67, in wsgi
    self.callable = self.load()
  File "/home/samuel/Documents/freelance/xceedr-api/venv/lib/python3.10/site-packages/gunicorn/app/wsgiapp.py", line 58, in load
    return self.load_wsgiapp()
  File "/home/samuel/Documents/freelance/xceedr-api/venv/lib/python3.10/site-packages/gunicorn/app/wsgiapp.py", line 48, in load_wsgiapp
    return util.import_app(self.app_uri)
  File "/home/samuel/Documents/freelance/xceedr-api/venv/lib/python3.10/site-packages/gunicorn/util.py", line 371, in import_app
    mod = importlib.import_module(module)
  File "/usr/lib/python3.10/importlib/__init__.py", line 126, in import_module
    return _bootstrap._gcd_import(name[level:], package, level)
  File "<frozen importlib._bootstrap>", line 1050, in _gcd_import
  File "<frozen importlib._bootstrap>", line 1027, in _find_and_load
  File "<frozen importlib._bootstrap>", line 1006, in _find_and_load_unlocked
  File "<frozen importlib._bootstrap>", line 688, in _load_unlocked
  File "<frozen importlib._bootstrap_external>", line 883, in exec_module
  File "<frozen importlib._bootstrap>", line 241, in _call_with_frames_removed
  File "/home/samuel/Documents/freelance/xceedr-api/run.py", line 24, in <module>
    app = create_app(app_config)
  File "/home/samuel/Documents/freelance/xceedr-api/volumx/__init__.py", line 96, in create_app
    db.create_all()
  File "/home/samuel/Documents/freelance/xceedr-api/venv/lib/python3.10/site-packages/flask_sqlalchemy/extension.py", line 900, in create_all
    self._call_for_binds(bind_key, "create_all")
  File "/home/samuel/Documents/freelance/xceedr-api/venv/lib/python3.10/site-packages/flask_sqlalchemy/extension.py", line 881, in _call_for_binds
    getattr(metadata, op_name)(bind=engine)
  File "/home/samuel/Documents/freelance/xceedr-api/venv/lib/python3.10/site-packages/sqlalchemy/sql/schema.py", line 5828, in create_all
    bind._run_ddl_visitor(
  File "/home/samuel/Documents/freelance/xceedr-api/venv/lib/python3.10/site-packages/sqlalchemy/engine/base.py", line 3243, in _run_ddl_visitor
    conn._run_ddl_visitor(visitorcallable, element, **kwargs)
  File "/home/samuel/Documents/freelance/xceedr-api/venv/lib/python3.10/site-packages/sqlalchemy/engine/base.py", line 2447, in _run_ddl_visitor
    visitorcallable(self.dialect, self, **kwargs).traverse_single(element)
  File "/home/samuel/Documents/freelance/xceedr-api/venv/lib/python3.10/site-packages/sqlalchemy/sql/visitors.py", line 671, in traverse_single
    return meth(obj, **kw)
  File "/home/samuel/Documents/freelance/xceedr-api/venv/lib/python3.10/site-packages/sqlalchemy/sql/ddl.py", line 897, in visit_metadata
    collection = sort_tables_and_constraints(
  File "/home/samuel/Documents/freelance/xceedr-api/venv/lib/python3.10/site-packages/sqlalchemy/sql/ddl.py", line 1327, in sort_tables_and_constraints
    dependent_on = fkc.referred_table
  File "/home/samuel/Documents/freelance/xceedr-api/venv/lib/python3.10/site-packages/sqlalchemy/sql/schema.py", line 4751, in referred_table
    return self.elements[0].column.table
  File "/home/samuel/Documents/freelance/xceedr-api/venv/lib/python3.10/site-packages/sqlalchemy/util/langhelpers.py", line 1146, in __get__
    obj.__dict__[self.__name__] = result = self.fget(obj)
  File "/home/samuel/Documents/freelance/xceedr-api/venv/lib/python3.10/site-packages/sqlalchemy/sql/schema.py", line 3159, in column
    return self._resolve_column()
  File "/home/samuel/Documents/freelance/xceedr-api/venv/lib/python3.10/site-packages/sqlalchemy/sql/schema.py", line 3182, in _resolve_column
    raise exc.NoReferencedTableError(
sqlalchemy.exc.NoReferencedTableError: Foreign key associated with column 'business_user_rights.userId' could not find table 'user' with which to generate a foreign key to target column 'id'
[2023-12-04 23:37:02 +0100] [70458] [INFO] Worker exiting (pid: 70458)
[2023-12-04 23:37:02 +0100] [70457] [ERROR] Exception in worker process
Traceback (most recent call last):
  File "/home/samuel/Documents/freelance/xceedr-api/venv/lib/python3.10/site-packages/gunicorn/arbiter.py", line 609, in spawn_worker
    worker.init_process()
  File "/home/samuel/Documents/freelance/xceedr-api/venv/lib/python3.10/site-packages/gunicorn/workers/base.py", line 134, in init_process
    self.load_wsgi()
  File "/home/samuel/Documents/freelance/xceedr-api/venv/lib/python3.10/site-packages/gunicorn/workers/base.py", line 146, in load_wsgi
    self.wsgi = self.app.wsgi()
  File "/home/samuel/Documents/freelance/xceedr-api/venv/lib/python3.10/site-packages/gunicorn/app/base.py", line 67, in wsgi
    self.callable = self.load()
  File "/home/samuel/Documents/freelance/xceedr-api/venv/lib/python3.10/site-packages/gunicorn/app/wsgiapp.py", line 58, in load
    return self.load_wsgiapp()
  File "/home/samuel/Documents/freelance/xceedr-api/venv/lib/python3.10/site-packages/gunicorn/app/wsgiapp.py", line 48, in load_wsgiapp
    return util.import_app(self.app_uri)
  File "/home/samuel/Documents/freelance/xceedr-api/venv/lib/python3.10/site-packages/gunicorn/util.py", line 371, in import_app
    mod = importlib.import_module(module)
  File "/usr/lib/python3.10/importlib/__init__.py", line 126, in import_module
    return _bootstrap._gcd_import(name[level:], package, level)
  File "<frozen importlib._bootstrap>", line 1050, in _gcd_import
  File "<frozen importlib._bootstrap>", line 1027, in _find_and_load
  File "<frozen importlib._bootstrap>", line 1006, in _find_and_load_unlocked
  File "<frozen importlib._bootstrap>", line 688, in _load_unlocked
  File "<frozen importlib._bootstrap_external>", line 883, in exec_module
  File "<frozen importlib._bootstrap>", line 241, in _call_with_frames_removed
  File "/home/samuel/Documents/freelance/xceedr-api/run.py", line 24, in <module>
    app = create_app(app_config)
  File "/home/samuel/Documents/freelance/xceedr-api/volumx/__init__.py", line 96, in create_app
    db.create_all()
  File "/home/samuel/Documents/freelance/xceedr-api/venv/lib/python3.10/site-packages/flask_sqlalchemy/extension.py", line 900, in create_all
    self._call_for_binds(bind_key, "create_all")
  File "/home/samuel/Documents/freelance/xceedr-api/venv/lib/python3.10/site-packages/flask_sqlalchemy/extension.py", line 881, in _call_for_binds
    getattr(metadata, op_name)(bind=engine)
  File "/home/samuel/Documents/freelance/xceedr-api/venv/lib/python3.10/site-packages/sqlalchemy/sql/schema.py", line 5828, in create_all
    bind._run_ddl_visitor(
  File "/home/samuel/Documents/freelance/xceedr-api/venv/lib/python3.10/site-packages/sqlalchemy/engine/base.py", line 3243, in _run_ddl_visitor
    conn._run_ddl_visitor(visitorcallable, element, **kwargs)
  File "/home/samuel/Documents/freelance/xceedr-api/venv/lib/python3.10/site-packages/sqlalchemy/engine/base.py", line 2447, in _run_ddl_visitor
    visitorcallable(self.dialect, self, **kwargs).traverse_single(element)
  File "/home/samuel/Documents/freelance/xceedr-api/venv/lib/python3.10/site-packages/sqlalchemy/sql/visitors.py", line 671, in traverse_single
    return meth(obj, **kw)
  File "/home/samuel/Documents/freelance/xceedr-api/venv/lib/python3.10/site-packages/sqlalchemy/sql/ddl.py", line 897, in visit_metadata
    collection = sort_tables_and_constraints(
  File "/home/samuel/Documents/freelance/xceedr-api/venv/lib/python3.10/site-packages/sqlalchemy/sql/ddl.py", line 1327, in sort_tables_and_constraints
    dependent_on = fkc.referred_table
  File "/home/samuel/Documents/freelance/xceedr-api/venv/lib/python3.10/site-packages/sqlalchemy/sql/schema.py", line 4751, in referred_table
    return self.elements[0].column.table
  File "/home/samuel/Documents/freelance/xceedr-api/venv/lib/python3.10/site-packages/sqlalchemy/util/langhelpers.py", line 1146, in __get__
    obj.__dict__[self.__name__] = result = self.fget(obj)
  File "/home/samuel/Documents/freelance/xceedr-api/venv/lib/python3.10/site-packages/sqlalchemy/sql/schema.py", line 3159, in column
    return self._resolve_column()
  File "/home/samuel/Documents/freelance/xceedr-api/venv/lib/python3.10/site-packages/sqlalchemy/sql/schema.py", line 3182, in _resolve_column
    raise exc.NoReferencedTableError(
sqlalchemy.exc.NoReferencedTableError: Foreign key associated with column 'business_user_rights.userId' could not find table 'user' with which to generate a foreign key to target column 'id'
[2023-12-04 23:37:02 +0100] [70457] [INFO] Worker exiting (pid: 70457)
[2023-12-04 23:37:02 +0100] [70455] [ERROR] Worker (pid:70458) exited with code 3
[2023-12-04 23:37:02 +0100] [70455] [ERROR] Worker (pid:70457) exited with code 3
[2023-12-04 23:37:02 +0100] [70459] [ERROR] Exception in worker process
Traceback (most recent call last):
  File "/home/samuel/Documents/freelance/xceedr-api/venv/lib/python3.10/site-packages/gunicorn/arbiter.py", line 609, in spawn_worker
    worker.init_process()
  File "/home/samuel/Documents/freelance/xceedr-api/venv/lib/python3.10/site-packages/gunicorn/workers/base.py", line 134, in init_process
    self.load_wsgi()
  File "/home/samuel/Documents/freelance/xceedr-api/venv/lib/python3.10/site-packages/gunicorn/workers/base.py", line 146, in load_wsgi
    self.wsgi = self.app.wsgi()
  File "/home/samuel/Documents/freelance/xceedr-api/venv/lib/python3.10/site-packages/gunicorn/app/base.py", line 67, in wsgi
    self.callable = self.load()
  File "/home/samuel/Documents/freelance/xceedr-api/venv/lib/python3.10/site-packages/gunicorn/app/wsgiapp.py", line 58, in load
    return self.load_wsgiapp()
  File "/home/samuel/Documents/freelance/xceedr-api/venv/lib/python3.10/site-packages/gunicorn/app/wsgiapp.py", line 48, in load_wsgiapp
    return util.import_app(self.app_uri)
  File "/home/samuel/Documents/freelance/xceedr-api/venv/lib/python3.10/site-packages/gunicorn/util.py", line 371, in import_app
    mod = importlib.import_module(module)
  File "/usr/lib/python3.10/importlib/__init__.py", line 126, in import_module
    return _bootstrap._gcd_import(name[level:], package, level)
  File "<frozen importlib._bootstrap>", line 1050, in _gcd_import
  File "<frozen importlib._bootstrap>", line 1027, in _find_and_load
  File "<frozen importlib._bootstrap>", line 1006, in _find_and_load_unlocked
  File "<frozen importlib._bootstrap>", line 688, in _load_unlocked
  File "<frozen importlib._bootstrap_external>", line 883, in exec_module
  File "<frozen importlib._bootstrap>", line 241, in _call_with_frames_removed
  File "/home/samuel/Documents/freelance/xceedr-api/run.py", line 24, in <module>
    app = create_app(app_config)
  File "/home/samuel/Documents/freelance/xceedr-api/volumx/__init__.py", line 96, in create_app
    db.create_all()
  File "/home/samuel/Documents/freelance/xceedr-api/venv/lib/python3.10/site-packages/flask_sqlalchemy/extension.py", line 900, in create_all
    self._call_for_binds(bind_key, "create_all")
  File "/home/samuel/Documents/freelance/xceedr-api/venv/lib/python3.10/site-packages/flask_sqlalchemy/extension.py", line 881, in _call_for_binds
    getattr(metadata, op_name)(bind=engine)
  File "/home/samuel/Documents/freelance/xceedr-api/venv/lib/python3.10/site-packages/sqlalchemy/sql/schema.py", line 5828, in create_all
    bind._run_ddl_visitor(
  File "/home/samuel/Documents/freelance/xceedr-api/venv/lib/python3.10/site-packages/sqlalchemy/engine/base.py", line 3243, in _run_ddl_visitor
    conn._run_ddl_visitor(visitorcallable, element, **kwargs)
  File "/home/samuel/Documents/freelance/xceedr-api/venv/lib/python3.10/site-packages/sqlalchemy/engine/base.py", line 2447, in _run_ddl_visitor
    visitorcallable(self.dialect, self, **kwargs).traverse_single(element)
  File "/home/samuel/Documents/freelance/xceedr-api/venv/lib/python3.10/site-packages/sqlalchemy/sql/visitors.py", line 671, in traverse_single
    return meth(obj, **kw)
  File "/home/samuel/Documents/freelance/xceedr-api/venv/lib/python3.10/site-packages/sqlalchemy/sql/ddl.py", line 897, in visit_metadata
    collection = sort_tables_and_constraints(
  File "/home/samuel/Documents/freelance/xceedr-api/venv/lib/python3.10/site-packages/sqlalchemy/sql/ddl.py", line 1327, in sort_tables_and_constraints
    dependent_on = fkc.referred_table
  File "/home/samuel/Documents/freelance/xceedr-api/venv/lib/python3.10/site-packages/sqlalchemy/sql/schema.py", line 4751, in referred_table
    return self.elements[0].column.table
  File "/home/samuel/Documents/freelance/xceedr-api/venv/lib/python3.10/site-packages/sqlalchemy/util/langhelpers.py", line 1146, in __get__
    obj.__dict__[self.__name__] = result = self.fget(obj)
  File "/home/samuel/Documents/freelance/xceedr-api/venv/lib/python3.10/site-packages/sqlalchemy/sql/schema.py", line 3159, in column
    return self._resolve_column()
  File "/home/samuel/Documents/freelance/xceedr-api/venv/lib/python3.10/site-packages/sqlalchemy/sql/schema.py", line 3182, in _resolve_column
    raise exc.NoReferencedTableError(
sqlalchemy.exc.NoReferencedTableError: Foreign key associated with column 'business_user_rights.userId' could not find table 'user' with which to generate a foreign key to target column 'id'
[2023-12-04 23:37:02 +0100] [70459] [INFO] Worker exiting (pid: 70459)
[2023-12-04 23:37:02 +0100] [70460] [ERROR] Exception in worker process
Traceback (most recent call last):
  File "/home/samuel/Documents/freelance/xceedr-api/venv/lib/python3.10/site-packages/gunicorn/arbiter.py", line 609, in spawn_worker
    worker.init_process()
  File "/home/samuel/Documents/freelance/xceedr-api/venv/lib/python3.10/site-packages/gunicorn/workers/base.py", line 134, in init_process
    self.load_wsgi()
  File "/home/samuel/Documents/freelance/xceedr-api/venv/lib/python3.10/site-packages/gunicorn/workers/base.py", line 146, in load_wsgi
    self.wsgi = self.app.wsgi()
  File "/home/samuel/Documents/freelance/xceedr-api/venv/lib/python3.10/site-packages/gunicorn/app/base.py", line 67, in wsgi
    self.callable = self.load()
  File "/home/samuel/Documents/freelance/xceedr-api/venv/lib/python3.10/site-packages/gunicorn/app/wsgiapp.py", line 58, in load
    return self.load_wsgiapp()
  File "/home/samuel/Documents/freelance/xceedr-api/venv/lib/python3.10/site-packages/gunicorn/app/wsgiapp.py", line 48, in load_wsgiapp
    return util.import_app(self.app_uri)
  File "/home/samuel/Documents/freelance/xceedr-api/venv/lib/python3.10/site-packages/gunicorn/util.py", line 371, in import_app
    mod = importlib.import_module(module)
  File "/usr/lib/python3.10/importlib/__init__.py", line 126, in import_module
    return _bootstrap._gcd_import(name[level:], package, level)
  File "<frozen importlib._bootstrap>", line 1050, in _gcd_import
  File "<frozen importlib._bootstrap>", line 1027, in _find_and_load
  File "<frozen importlib._bootstrap>", line 1006, in _find_and_load_unlocked
  File "<frozen importlib._bootstrap>", line 688, in _load_unlocked
  File "<frozen importlib._bootstrap_external>", line 883, in exec_module
  File "<frozen importlib._bootstrap>", line 241, in _call_with_frames_removed
  File "/home/samuel/Documents/freelance/xceedr-api/run.py", line 24, in <module>
    app = create_app(app_config)
  File "/home/samuel/Documents/freelance/xceedr-api/volumx/__init__.py", line 96, in create_app
    db.create_all()
  File "/home/samuel/Documents/freelance/xceedr-api/venv/lib/python3.10/site-packages/flask_sqlalchemy/extension.py", line 900, in create_all
    self._call_for_binds(bind_key, "create_all")
  File "/home/samuel/Documents/freelance/xceedr-api/venv/lib/python3.10/site-packages/flask_sqlalchemy/extension.py", line 881, in _call_for_binds
    getattr(metadata, op_name)(bind=engine)
  File "/home/samuel/Documents/freelance/xceedr-api/venv/lib/python3.10/site-packages/sqlalchemy/sql/schema.py", line 5828, in create_all
    bind._run_ddl_visitor(
  File "/home/samuel/Documents/freelance/xceedr-api/venv/lib/python3.10/site-packages/sqlalchemy/engine/base.py", line 3243, in _run_ddl_visitor
    conn._run_ddl_visitor(visitorcallable, element, **kwargs)
  File "/home/samuel/Documents/freelance/xceedr-api/venv/lib/python3.10/site-packages/sqlalchemy/engine/base.py", line 2447, in _run_ddl_visitor
    visitorcallable(self.dialect, self, **kwargs).traverse_single(element)
  File "/home/samuel/Documents/freelance/xceedr-api/venv/lib/python3.10/site-packages/sqlalchemy/sql/visitors.py", line 671, in traverse_single
    return meth(obj, **kw)
  File "/home/samuel/Documents/freelance/xceedr-api/venv/lib/python3.10/site-packages/sqlalchemy/sql/ddl.py", line 897, in visit_metadata
    collection = sort_tables_and_constraints(
  File "/home/samuel/Documents/freelance/xceedr-api/venv/lib/python3.10/site-packages/sqlalchemy/sql/ddl.py", line 1327, in sort_tables_and_constraints
    dependent_on = fkc.referred_table
  File "/home/samuel/Documents/freelance/xceedr-api/venv/lib/python3.10/site-packages/sqlalchemy/sql/schema.py", line 4751, in referred_table
    return self.elements[0].column.table
  File "/home/samuel/Documents/freelance/xceedr-api/venv/lib/python3.10/site-packages/sqlalchemy/util/langhelpers.py", line 1146, in __get__
    obj.__dict__[self.__name__] = result = self.fget(obj)
  File "/home/samuel/Documents/freelance/xceedr-api/venv/lib/python3.10/site-packages/sqlalchemy/sql/schema.py", line 3159, in column
    return self._resolve_column()
  File "/home/samuel/Documents/freelance/xceedr-api/venv/lib/python3.10/site-packages/sqlalchemy/sql/schema.py", line 3182, in _resolve_column
    raise exc.NoReferencedTableError(
sqlalchemy.exc.NoReferencedTableError: Foreign key associated with column 'business_user_rights.userId' could not find table 'user' with which to generate a foreign key to target column 'id'
[2023-12-04 23:37:02 +0100] [70460] [INFO] Worker exiting (pid: 70460)
[2023-12-04 23:43:43 +0100] [71104] [INFO] Starting gunicorn 21.2.0
[2023-12-04 23:43:43 +0100] [71104] [INFO] Listening at: http://0.0.0.0:5000 (71104)
[2023-12-04 23:43:43 +0100] [71104] [INFO] Using worker: sync
[2023-12-04 23:43:43 +0100] [71106] [INFO] Booting worker with pid: 71106
[2023-12-04 23:43:43 +0100] [71107] [INFO] Booting worker with pid: 71107
[2023-12-04 23:43:43 +0100] [71108] [INFO] Booting worker with pid: 71108
[2023-12-04 23:43:43 +0100] [71109] [INFO] Booting worker with pid: 71109
[2023-12-04 23:43:44 +0100] [71106] [ERROR] Exception in worker process
Traceback (most recent call last):
  File "/home/samuel/Documents/freelance/xceedr-api/venv/lib/python3.10/site-packages/gunicorn/arbiter.py", line 609, in spawn_worker
    worker.init_process()
  File "/home/samuel/Documents/freelance/xceedr-api/venv/lib/python3.10/site-packages/gunicorn/workers/base.py", line 134, in init_process
    self.load_wsgi()
  File "/home/samuel/Documents/freelance/xceedr-api/venv/lib/python3.10/site-packages/gunicorn/workers/base.py", line 146, in load_wsgi
    self.wsgi = self.app.wsgi()
  File "/home/samuel/Documents/freelance/xceedr-api/venv/lib/python3.10/site-packages/gunicorn/app/base.py", line 67, in wsgi
    self.callable = self.load()
  File "/home/samuel/Documents/freelance/xceedr-api/venv/lib/python3.10/site-packages/gunicorn/app/wsgiapp.py", line 58, in load
    return self.load_wsgiapp()
  File "/home/samuel/Documents/freelance/xceedr-api/venv/lib/python3.10/site-packages/gunicorn/app/wsgiapp.py", line 48, in load_wsgiapp
    return util.import_app(self.app_uri)
  File "/home/samuel/Documents/freelance/xceedr-api/venv/lib/python3.10/site-packages/gunicorn/util.py", line 371, in import_app
    mod = importlib.import_module(module)
  File "/usr/lib/python3.10/importlib/__init__.py", line 126, in import_module
    return _bootstrap._gcd_import(name[level:], package, level)
  File "<frozen importlib._bootstrap>", line 1050, in _gcd_import
  File "<frozen importlib._bootstrap>", line 1027, in _find_and_load
  File "<frozen importlib._bootstrap>", line 1006, in _find_and_load_unlocked
  File "<frozen importlib._bootstrap>", line 688, in _load_unlocked
  File "<frozen importlib._bootstrap_external>", line 883, in exec_module
  File "<frozen importlib._bootstrap>", line 241, in _call_with_frames_removed
  File "/home/samuel/Documents/freelance/xceedr-api/run.py", line 24, in <module>
    app = create_app(app_config)
  File "/home/samuel/Documents/freelance/xceedr-api/volumx/__init__.py", line 96, in create_app
    db.create_all()
  File "/home/samuel/Documents/freelance/xceedr-api/venv/lib/python3.10/site-packages/flask_sqlalchemy/extension.py", line 900, in create_all
    self._call_for_binds(bind_key, "create_all")
  File "/home/samuel/Documents/freelance/xceedr-api/venv/lib/python3.10/site-packages/flask_sqlalchemy/extension.py", line 881, in _call_for_binds
    getattr(metadata, op_name)(bind=engine)
  File "/home/samuel/Documents/freelance/xceedr-api/venv/lib/python3.10/site-packages/sqlalchemy/sql/schema.py", line 5828, in create_all
    bind._run_ddl_visitor(
  File "/home/samuel/Documents/freelance/xceedr-api/venv/lib/python3.10/site-packages/sqlalchemy/engine/base.py", line 3243, in _run_ddl_visitor
    conn._run_ddl_visitor(visitorcallable, element, **kwargs)
  File "/home/samuel/Documents/freelance/xceedr-api/venv/lib/python3.10/site-packages/sqlalchemy/engine/base.py", line 2447, in _run_ddl_visitor
    visitorcallable(self.dialect, self, **kwargs).traverse_single(element)
  File "/home/samuel/Documents/freelance/xceedr-api/venv/lib/python3.10/site-packages/sqlalchemy/sql/visitors.py", line 671, in traverse_single
    return meth(obj, **kw)
  File "/home/samuel/Documents/freelance/xceedr-api/venv/lib/python3.10/site-packages/sqlalchemy/sql/ddl.py", line 897, in visit_metadata
    collection = sort_tables_and_constraints(
  File "/home/samuel/Documents/freelance/xceedr-api/venv/lib/python3.10/site-packages/sqlalchemy/sql/ddl.py", line 1327, in sort_tables_and_constraints
    dependent_on = fkc.referred_table
  File "/home/samuel/Documents/freelance/xceedr-api/venv/lib/python3.10/site-packages/sqlalchemy/sql/schema.py", line 4751, in referred_table
    return self.elements[0].column.table
  File "/home/samuel/Documents/freelance/xceedr-api/venv/lib/python3.10/site-packages/sqlalchemy/util/langhelpers.py", line 1146, in __get__
    obj.__dict__[self.__name__] = result = self.fget(obj)
  File "/home/samuel/Documents/freelance/xceedr-api/venv/lib/python3.10/site-packages/sqlalchemy/sql/schema.py", line 3159, in column
    return self._resolve_column()
  File "/home/samuel/Documents/freelance/xceedr-api/venv/lib/python3.10/site-packages/sqlalchemy/sql/schema.py", line 3182, in _resolve_column
    raise exc.NoReferencedTableError(
sqlalchemy.exc.NoReferencedTableError: Foreign key associated with column 'business_user_rights.userId' could not find table 'user' with which to generate a foreign key to target column 'id'
[2023-12-04 23:43:44 +0100] [71106] [INFO] Worker exiting (pid: 71106)
[2023-12-04 23:43:44 +0100] [71107] [ERROR] Exception in worker process
Traceback (most recent call last):
  File "/home/samuel/Documents/freelance/xceedr-api/venv/lib/python3.10/site-packages/gunicorn/arbiter.py", line 609, in spawn_worker
    worker.init_process()
  File "/home/samuel/Documents/freelance/xceedr-api/venv/lib/python3.10/site-packages/gunicorn/workers/base.py", line 134, in init_process
    self.load_wsgi()
  File "/home/samuel/Documents/freelance/xceedr-api/venv/lib/python3.10/site-packages/gunicorn/workers/base.py", line 146, in load_wsgi
    self.wsgi = self.app.wsgi()
  File "/home/samuel/Documents/freelance/xceedr-api/venv/lib/python3.10/site-packages/gunicorn/app/base.py", line 67, in wsgi
    self.callable = self.load()
  File "/home/samuel/Documents/freelance/xceedr-api/venv/lib/python3.10/site-packages/gunicorn/app/wsgiapp.py", line 58, in load
    return self.load_wsgiapp()
  File "/home/samuel/Documents/freelance/xceedr-api/venv/lib/python3.10/site-packages/gunicorn/app/wsgiapp.py", line 48, in load_wsgiapp
    return util.import_app(self.app_uri)
  File "/home/samuel/Documents/freelance/xceedr-api/venv/lib/python3.10/site-packages/gunicorn/util.py", line 371, in import_app
    mod = importlib.import_module(module)
  File "/usr/lib/python3.10/importlib/__init__.py", line 126, in import_module
    return _bootstrap._gcd_import(name[level:], package, level)
  File "<frozen importlib._bootstrap>", line 1050, in _gcd_import
  File "<frozen importlib._bootstrap>", line 1027, in _find_and_load
  File "<frozen importlib._bootstrap>", line 1006, in _find_and_load_unlocked
  File "<frozen importlib._bootstrap>", line 688, in _load_unlocked
  File "<frozen importlib._bootstrap_external>", line 883, in exec_module
  File "<frozen importlib._bootstrap>", line 241, in _call_with_frames_removed
  File "/home/samuel/Documents/freelance/xceedr-api/run.py", line 24, in <module>
    app = create_app(app_config)
  File "/home/samuel/Documents/freelance/xceedr-api/volumx/__init__.py", line 96, in create_app
    db.create_all()
  File "/home/samuel/Documents/freelance/xceedr-api/venv/lib/python3.10/site-packages/flask_sqlalchemy/extension.py", line 900, in create_all
    self._call_for_binds(bind_key, "create_all")
  File "/home/samuel/Documents/freelance/xceedr-api/venv/lib/python3.10/site-packages/flask_sqlalchemy/extension.py", line 881, in _call_for_binds
    getattr(metadata, op_name)(bind=engine)
  File "/home/samuel/Documents/freelance/xceedr-api/venv/lib/python3.10/site-packages/sqlalchemy/sql/schema.py", line 5828, in create_all
    bind._run_ddl_visitor(
  File "/home/samuel/Documents/freelance/xceedr-api/venv/lib/python3.10/site-packages/sqlalchemy/engine/base.py", line 3243, in _run_ddl_visitor
    conn._run_ddl_visitor(visitorcallable, element, **kwargs)
  File "/home/samuel/Documents/freelance/xceedr-api/venv/lib/python3.10/site-packages/sqlalchemy/engine/base.py", line 2447, in _run_ddl_visitor
    visitorcallable(self.dialect, self, **kwargs).traverse_single(element)
  File "/home/samuel/Documents/freelance/xceedr-api/venv/lib/python3.10/site-packages/sqlalchemy/sql/visitors.py", line 671, in traverse_single
    return meth(obj, **kw)
  File "/home/samuel/Documents/freelance/xceedr-api/venv/lib/python3.10/site-packages/sqlalchemy/sql/ddl.py", line 897, in visit_metadata
    collection = sort_tables_and_constraints(
  File "/home/samuel/Documents/freelance/xceedr-api/venv/lib/python3.10/site-packages/sqlalchemy/sql/ddl.py", line 1327, in sort_tables_and_constraints
    dependent_on = fkc.referred_table
  File "/home/samuel/Documents/freelance/xceedr-api/venv/lib/python3.10/site-packages/sqlalchemy/sql/schema.py", line 4751, in referred_table
    return self.elements[0].column.table
  File "/home/samuel/Documents/freelance/xceedr-api/venv/lib/python3.10/site-packages/sqlalchemy/util/langhelpers.py", line 1146, in __get__
    obj.__dict__[self.__name__] = result = self.fget(obj)
  File "/home/samuel/Documents/freelance/xceedr-api/venv/lib/python3.10/site-packages/sqlalchemy/sql/schema.py", line 3159, in column
    return self._resolve_column()
  File "/home/samuel/Documents/freelance/xceedr-api/venv/lib/python3.10/site-packages/sqlalchemy/sql/schema.py", line 3182, in _resolve_column
    raise exc.NoReferencedTableError(
sqlalchemy.exc.NoReferencedTableError: Foreign key associated with column 'business_user_rights.userId' could not find table 'user' with which to generate a foreign key to target column 'id'
[2023-12-04 23:43:44 +0100] [71107] [INFO] Worker exiting (pid: 71107)
[2023-12-04 23:43:45 +0100] [71104] [ERROR] Worker (pid:71106) exited with code 3
[2023-12-04 23:43:45 +0100] [71104] [ERROR] Worker (pid:71107) was sent SIGTERM!
[2023-12-04 23:43:45 +0100] [71108] [ERROR] Exception in worker process
Traceback (most recent call last):
  File "/home/samuel/Documents/freelance/xceedr-api/venv/lib/python3.10/site-packages/gunicorn/arbiter.py", line 609, in spawn_worker
    worker.init_process()
  File "/home/samuel/Documents/freelance/xceedr-api/venv/lib/python3.10/site-packages/gunicorn/workers/base.py", line 134, in init_process
    self.load_wsgi()
  File "/home/samuel/Documents/freelance/xceedr-api/venv/lib/python3.10/site-packages/gunicorn/workers/base.py", line 146, in load_wsgi
    self.wsgi = self.app.wsgi()
  File "/home/samuel/Documents/freelance/xceedr-api/venv/lib/python3.10/site-packages/gunicorn/app/base.py", line 67, in wsgi
    self.callable = self.load()
  File "/home/samuel/Documents/freelance/xceedr-api/venv/lib/python3.10/site-packages/gunicorn/app/wsgiapp.py", line 58, in load
    return self.load_wsgiapp()
  File "/home/samuel/Documents/freelance/xceedr-api/venv/lib/python3.10/site-packages/gunicorn/app/wsgiapp.py", line 48, in load_wsgiapp
    return util.import_app(self.app_uri)
  File "/home/samuel/Documents/freelance/xceedr-api/venv/lib/python3.10/site-packages/gunicorn/util.py", line 371, in import_app
    mod = importlib.import_module(module)
  File "/usr/lib/python3.10/importlib/__init__.py", line 126, in import_module
    return _bootstrap._gcd_import(name[level:], package, level)
  File "<frozen importlib._bootstrap>", line 1050, in _gcd_import
  File "<frozen importlib._bootstrap>", line 1027, in _find_and_load
  File "<frozen importlib._bootstrap>", line 1006, in _find_and_load_unlocked
  File "<frozen importlib._bootstrap>", line 688, in _load_unlocked
  File "<frozen importlib._bootstrap_external>", line 883, in exec_module
  File "<frozen importlib._bootstrap>", line 241, in _call_with_frames_removed
  File "/home/samuel/Documents/freelance/xceedr-api/run.py", line 24, in <module>
    app = create_app(app_config)
  File "/home/samuel/Documents/freelance/xceedr-api/volumx/__init__.py", line 96, in create_app
    db.create_all()
  File "/home/samuel/Documents/freelance/xceedr-api/venv/lib/python3.10/site-packages/flask_sqlalchemy/extension.py", line 900, in create_all
    self._call_for_binds(bind_key, "create_all")
  File "/home/samuel/Documents/freelance/xceedr-api/venv/lib/python3.10/site-packages/flask_sqlalchemy/extension.py", line 881, in _call_for_binds
    getattr(metadata, op_name)(bind=engine)
  File "/home/samuel/Documents/freelance/xceedr-api/venv/lib/python3.10/site-packages/sqlalchemy/sql/schema.py", line 5828, in create_all
    bind._run_ddl_visitor(
  File "/home/samuel/Documents/freelance/xceedr-api/venv/lib/python3.10/site-packages/sqlalchemy/engine/base.py", line 3243, in _run_ddl_visitor
    conn._run_ddl_visitor(visitorcallable, element, **kwargs)
  File "/home/samuel/Documents/freelance/xceedr-api/venv/lib/python3.10/site-packages/sqlalchemy/engine/base.py", line 2447, in _run_ddl_visitor
    visitorcallable(self.dialect, self, **kwargs).traverse_single(element)
  File "/home/samuel/Documents/freelance/xceedr-api/venv/lib/python3.10/site-packages/sqlalchemy/sql/visitors.py", line 671, in traverse_single
    return meth(obj, **kw)
  File "/home/samuel/Documents/freelance/xceedr-api/venv/lib/python3.10/site-packages/sqlalchemy/sql/ddl.py", line 897, in visit_metadata
    collection = sort_tables_and_constraints(
  File "/home/samuel/Documents/freelance/xceedr-api/venv/lib/python3.10/site-packages/sqlalchemy/sql/ddl.py", line 1327, in sort_tables_and_constraints
    dependent_on = fkc.referred_table
  File "/home/samuel/Documents/freelance/xceedr-api/venv/lib/python3.10/site-packages/sqlalchemy/sql/schema.py", line 4751, in referred_table
    return self.elements[0].column.table
  File "/home/samuel/Documents/freelance/xceedr-api/venv/lib/python3.10/site-packages/sqlalchemy/util/langhelpers.py", line 1146, in __get__
    obj.__dict__[self.__name__] = result = self.fget(obj)
  File "/home/samuel/Documents/freelance/xceedr-api/venv/lib/python3.10/site-packages/sqlalchemy/sql/schema.py", line 3159, in column
    return self._resolve_column()
  File "/home/samuel/Documents/freelance/xceedr-api/venv/lib/python3.10/site-packages/sqlalchemy/sql/schema.py", line 3182, in _resolve_column
    raise exc.NoReferencedTableError(
sqlalchemy.exc.NoReferencedTableError: Foreign key associated with column 'business_user_rights.userId' could not find table 'user' with which to generate a foreign key to target column 'id'
[2023-12-04 23:43:45 +0100] [71108] [INFO] Worker exiting (pid: 71108)
[2023-12-04 23:43:45 +0100] [71109] [ERROR] Exception in worker process
Traceback (most recent call last):
  File "/home/samuel/Documents/freelance/xceedr-api/venv/lib/python3.10/site-packages/gunicorn/arbiter.py", line 609, in spawn_worker
    worker.init_process()
  File "/home/samuel/Documents/freelance/xceedr-api/venv/lib/python3.10/site-packages/gunicorn/workers/base.py", line 134, in init_process
    self.load_wsgi()
  File "/home/samuel/Documents/freelance/xceedr-api/venv/lib/python3.10/site-packages/gunicorn/workers/base.py", line 146, in load_wsgi
    self.wsgi = self.app.wsgi()
  File "/home/samuel/Documents/freelance/xceedr-api/venv/lib/python3.10/site-packages/gunicorn/app/base.py", line 67, in wsgi
    self.callable = self.load()
  File "/home/samuel/Documents/freelance/xceedr-api/venv/lib/python3.10/site-packages/gunicorn/app/wsgiapp.py", line 58, in load
    return self.load_wsgiapp()
  File "/home/samuel/Documents/freelance/xceedr-api/venv/lib/python3.10/site-packages/gunicorn/app/wsgiapp.py", line 48, in load_wsgiapp
    return util.import_app(self.app_uri)
  File "/home/samuel/Documents/freelance/xceedr-api/venv/lib/python3.10/site-packages/gunicorn/util.py", line 371, in import_app
    mod = importlib.import_module(module)
  File "/usr/lib/python3.10/importlib/__init__.py", line 126, in import_module
    return _bootstrap._gcd_import(name[level:], package, level)
  File "<frozen importlib._bootstrap>", line 1050, in _gcd_import
  File "<frozen importlib._bootstrap>", line 1027, in _find_and_load
  File "<frozen importlib._bootstrap>", line 1006, in _find_and_load_unlocked
  File "<frozen importlib._bootstrap>", line 688, in _load_unlocked
  File "<frozen importlib._bootstrap_external>", line 883, in exec_module
  File "<frozen importlib._bootstrap>", line 241, in _call_with_frames_removed
  File "/home/samuel/Documents/freelance/xceedr-api/run.py", line 24, in <module>
    app = create_app(app_config)
  File "/home/samuel/Documents/freelance/xceedr-api/volumx/__init__.py", line 96, in create_app
    db.create_all()
  File "/home/samuel/Documents/freelance/xceedr-api/venv/lib/python3.10/site-packages/flask_sqlalchemy/extension.py", line 900, in create_all
    self._call_for_binds(bind_key, "create_all")
  File "/home/samuel/Documents/freelance/xceedr-api/venv/lib/python3.10/site-packages/flask_sqlalchemy/extension.py", line 881, in _call_for_binds
    getattr(metadata, op_name)(bind=engine)
  File "/home/samuel/Documents/freelance/xceedr-api/venv/lib/python3.10/site-packages/sqlalchemy/sql/schema.py", line 5828, in create_all
    bind._run_ddl_visitor(
  File "/home/samuel/Documents/freelance/xceedr-api/venv/lib/python3.10/site-packages/sqlalchemy/engine/base.py", line 3243, in _run_ddl_visitor
    conn._run_ddl_visitor(visitorcallable, element, **kwargs)
  File "/home/samuel/Documents/freelance/xceedr-api/venv/lib/python3.10/site-packages/sqlalchemy/engine/base.py", line 2447, in _run_ddl_visitor
    visitorcallable(self.dialect, self, **kwargs).traverse_single(element)
  File "/home/samuel/Documents/freelance/xceedr-api/venv/lib/python3.10/site-packages/sqlalchemy/sql/visitors.py", line 671, in traverse_single
    return meth(obj, **kw)
  File "/home/samuel/Documents/freelance/xceedr-api/venv/lib/python3.10/site-packages/sqlalchemy/sql/ddl.py", line 897, in visit_metadata
    collection = sort_tables_and_constraints(
  File "/home/samuel/Documents/freelance/xceedr-api/venv/lib/python3.10/site-packages/sqlalchemy/sql/ddl.py", line 1327, in sort_tables_and_constraints
    dependent_on = fkc.referred_table
  File "/home/samuel/Documents/freelance/xceedr-api/venv/lib/python3.10/site-packages/sqlalchemy/sql/schema.py", line 4751, in referred_table
    return self.elements[0].column.table
  File "/home/samuel/Documents/freelance/xceedr-api/venv/lib/python3.10/site-packages/sqlalchemy/util/langhelpers.py", line 1146, in __get__
    obj.__dict__[self.__name__] = result = self.fget(obj)
  File "/home/samuel/Documents/freelance/xceedr-api/venv/lib/python3.10/site-packages/sqlalchemy/sql/schema.py", line 3159, in column
    return self._resolve_column()
  File "/home/samuel/Documents/freelance/xceedr-api/venv/lib/python3.10/site-packages/sqlalchemy/sql/schema.py", line 3182, in _resolve_column
    raise exc.NoReferencedTableError(
sqlalchemy.exc.NoReferencedTableError: Foreign key associated with column 'business_user_rights.userId' could not find table 'user' with which to generate a foreign key to target column 'id'
[2023-12-04 23:43:45 +0100] [71109] [INFO] Worker exiting (pid: 71109)
[2023-12-04 23:43:45 +0100] [71104] [ERROR] Worker (pid:71109) exited with code 3
[2023-12-05 00:34:02 +0100] [72106] [INFO] Starting gunicorn 21.2.0
[2023-12-05 00:34:02 +0100] [72106] [INFO] Listening at: http://0.0.0.0:5000 (72106)
[2023-12-05 00:34:02 +0100] [72106] [INFO] Using worker: sync
[2023-12-05 00:34:02 +0100] [72108] [INFO] Booting worker with pid: 72108
[2023-12-05 00:34:02 +0100] [72109] [INFO] Booting worker with pid: 72109
[2023-12-05 00:34:02 +0100] [72110] [INFO] Booting worker with pid: 72110
[2023-12-05 00:34:02 +0100] [72111] [INFO] Booting worker with pid: 72111
[2023-12-05 00:34:03 +0100] [72110] [ERROR] Exception in worker process
Traceback (most recent call last):
  File "/home/samuel/Documents/freelance/xceedr-api/venv/lib/python3.10/site-packages/gunicorn/arbiter.py", line 609, in spawn_worker
    worker.init_process()
  File "/home/samuel/Documents/freelance/xceedr-api/venv/lib/python3.10/site-packages/gunicorn/workers/base.py", line 134, in init_process
    self.load_wsgi()
  File "/home/samuel/Documents/freelance/xceedr-api/venv/lib/python3.10/site-packages/gunicorn/workers/base.py", line 146, in load_wsgi
    self.wsgi = self.app.wsgi()
  File "/home/samuel/Documents/freelance/xceedr-api/venv/lib/python3.10/site-packages/gunicorn/app/base.py", line 67, in wsgi
    self.callable = self.load()
  File "/home/samuel/Documents/freelance/xceedr-api/venv/lib/python3.10/site-packages/gunicorn/app/wsgiapp.py", line 58, in load
    return self.load_wsgiapp()
  File "/home/samuel/Documents/freelance/xceedr-api/venv/lib/python3.10/site-packages/gunicorn/app/wsgiapp.py", line 48, in load_wsgiapp
    return util.import_app(self.app_uri)
  File "/home/samuel/Documents/freelance/xceedr-api/venv/lib/python3.10/site-packages/gunicorn/util.py", line 371, in import_app
    mod = importlib.import_module(module)
  File "/usr/lib/python3.10/importlib/__init__.py", line 126, in import_module
    return _bootstrap._gcd_import(name[level:], package, level)
  File "<frozen importlib._bootstrap>", line 1050, in _gcd_import
  File "<frozen importlib._bootstrap>", line 1027, in _find_and_load
  File "<frozen importlib._bootstrap>", line 1006, in _find_and_load_unlocked
  File "<frozen importlib._bootstrap>", line 688, in _load_unlocked
  File "<frozen importlib._bootstrap_external>", line 883, in exec_module
  File "<frozen importlib._bootstrap>", line 241, in _call_with_frames_removed
  File "/home/samuel/Documents/freelance/xceedr-api/run.py", line 24, in <module>
    app = create_app(app_config)
  File "/home/samuel/Documents/freelance/xceedr-api/volumx/__init__.py", line 96, in create_app
    db.create_all()
  File "/home/samuel/Documents/freelance/xceedr-api/venv/lib/python3.10/site-packages/flask_sqlalchemy/extension.py", line 900, in create_all
    self._call_for_binds(bind_key, "create_all")
  File "/home/samuel/Documents/freelance/xceedr-api/venv/lib/python3.10/site-packages/flask_sqlalchemy/extension.py", line 881, in _call_for_binds
    getattr(metadata, op_name)(bind=engine)
  File "/home/samuel/Documents/freelance/xceedr-api/venv/lib/python3.10/site-packages/sqlalchemy/sql/schema.py", line 5828, in create_all
    bind._run_ddl_visitor(
  File "/home/samuel/Documents/freelance/xceedr-api/venv/lib/python3.10/site-packages/sqlalchemy/engine/base.py", line 3243, in _run_ddl_visitor
    conn._run_ddl_visitor(visitorcallable, element, **kwargs)
  File "/home/samuel/Documents/freelance/xceedr-api/venv/lib/python3.10/site-packages/sqlalchemy/engine/base.py", line 2447, in _run_ddl_visitor
    visitorcallable(self.dialect, self, **kwargs).traverse_single(element)
  File "/home/samuel/Documents/freelance/xceedr-api/venv/lib/python3.10/site-packages/sqlalchemy/sql/visitors.py", line 671, in traverse_single
    return meth(obj, **kw)
  File "/home/samuel/Documents/freelance/xceedr-api/venv/lib/python3.10/site-packages/sqlalchemy/sql/ddl.py", line 897, in visit_metadata
    collection = sort_tables_and_constraints(
  File "/home/samuel/Documents/freelance/xceedr-api/venv/lib/python3.10/site-packages/sqlalchemy/sql/ddl.py", line 1327, in sort_tables_and_constraints
    dependent_on = fkc.referred_table
  File "/home/samuel/Documents/freelance/xceedr-api/venv/lib/python3.10/site-packages/sqlalchemy/sql/schema.py", line 4751, in referred_table
    return self.elements[0].column.table
  File "/home/samuel/Documents/freelance/xceedr-api/venv/lib/python3.10/site-packages/sqlalchemy/util/langhelpers.py", line 1146, in __get__
    obj.__dict__[self.__name__] = result = self.fget(obj)
  File "/home/samuel/Documents/freelance/xceedr-api/venv/lib/python3.10/site-packages/sqlalchemy/sql/schema.py", line 3159, in column
    return self._resolve_column()
  File "/home/samuel/Documents/freelance/xceedr-api/venv/lib/python3.10/site-packages/sqlalchemy/sql/schema.py", line 3182, in _resolve_column
    raise exc.NoReferencedTableError(
sqlalchemy.exc.NoReferencedTableError: Foreign key associated with column 'business_user_rights.userId' could not find table 'user' with which to generate a foreign key to target column 'id'
[2023-12-05 00:34:03 +0100] [72109] [ERROR] Exception in worker process
Traceback (most recent call last):
  File "/home/samuel/Documents/freelance/xceedr-api/venv/lib/python3.10/site-packages/gunicorn/arbiter.py", line 609, in spawn_worker
    worker.init_process()
  File "/home/samuel/Documents/freelance/xceedr-api/venv/lib/python3.10/site-packages/gunicorn/workers/base.py", line 134, in init_process
    self.load_wsgi()
  File "/home/samuel/Documents/freelance/xceedr-api/venv/lib/python3.10/site-packages/gunicorn/workers/base.py", line 146, in load_wsgi
    self.wsgi = self.app.wsgi()
  File "/home/samuel/Documents/freelance/xceedr-api/venv/lib/python3.10/site-packages/gunicorn/app/base.py", line 67, in wsgi
    self.callable = self.load()
  File "/home/samuel/Documents/freelance/xceedr-api/venv/lib/python3.10/site-packages/gunicorn/app/wsgiapp.py", line 58, in load
    return self.load_wsgiapp()
  File "/home/samuel/Documents/freelance/xceedr-api/venv/lib/python3.10/site-packages/gunicorn/app/wsgiapp.py", line 48, in load_wsgiapp
    return util.import_app(self.app_uri)
  File "/home/samuel/Documents/freelance/xceedr-api/venv/lib/python3.10/site-packages/gunicorn/util.py", line 371, in import_app
    mod = importlib.import_module(module)
  File "/usr/lib/python3.10/importlib/__init__.py", line 126, in import_module
    return _bootstrap._gcd_import(name[level:], package, level)
  File "<frozen importlib._bootstrap>", line 1050, in _gcd_import
  File "<frozen importlib._bootstrap>", line 1027, in _find_and_load
  File "<frozen importlib._bootstrap>", line 1006, in _find_and_load_unlocked
  File "<frozen importlib._bootstrap>", line 688, in _load_unlocked
  File "<frozen importlib._bootstrap_external>", line 883, in exec_module
  File "<frozen importlib._bootstrap>", line 241, in _call_with_frames_removed
  File "/home/samuel/Documents/freelance/xceedr-api/run.py", line 24, in <module>
    app = create_app(app_config)
  File "/home/samuel/Documents/freelance/xceedr-api/volumx/__init__.py", line 96, in create_app
    db.create_all()
  File "/home/samuel/Documents/freelance/xceedr-api/venv/lib/python3.10/site-packages/flask_sqlalchemy/extension.py", line 900, in create_all
    self._call_for_binds(bind_key, "create_all")
  File "/home/samuel/Documents/freelance/xceedr-api/venv/lib/python3.10/site-packages/flask_sqlalchemy/extension.py", line 881, in _call_for_binds
    getattr(metadata, op_name)(bind=engine)
  File "/home/samuel/Documents/freelance/xceedr-api/venv/lib/python3.10/site-packages/sqlalchemy/sql/schema.py", line 5828, in create_all
    bind._run_ddl_visitor(
  File "/home/samuel/Documents/freelance/xceedr-api/venv/lib/python3.10/site-packages/sqlalchemy/engine/base.py", line 3243, in _run_ddl_visitor
    conn._run_ddl_visitor(visitorcallable, element, **kwargs)
  File "/home/samuel/Documents/freelance/xceedr-api/venv/lib/python3.10/site-packages/sqlalchemy/engine/base.py", line 2447, in _run_ddl_visitor
    visitorcallable(self.dialect, self, **kwargs).traverse_single(element)
  File "/home/samuel/Documents/freelance/xceedr-api/venv/lib/python3.10/site-packages/sqlalchemy/sql/visitors.py", line 671, in traverse_single
    return meth(obj, **kw)
  File "/home/samuel/Documents/freelance/xceedr-api/venv/lib/python3.10/site-packages/sqlalchemy/sql/ddl.py", line 897, in visit_metadata
    collection = sort_tables_and_constraints(
  File "/home/samuel/Documents/freelance/xceedr-api/venv/lib/python3.10/site-packages/sqlalchemy/sql/ddl.py", line 1327, in sort_tables_and_constraints
    dependent_on = fkc.referred_table
  File "/home/samuel/Documents/freelance/xceedr-api/venv/lib/python3.10/site-packages/sqlalchemy/sql/schema.py", line 4751, in referred_table
    return self.elements[0].column.table
  File "/home/samuel/Documents/freelance/xceedr-api/venv/lib/python3.10/site-packages/sqlalchemy/util/langhelpers.py", line 1146, in __get__
    obj.__dict__[self.__name__] = result = self.fget(obj)
  File "/home/samuel/Documents/freelance/xceedr-api/venv/lib/python3.10/site-packages/sqlalchemy/sql/schema.py", line 3159, in column
    return self._resolve_column()
  File "/home/samuel/Documents/freelance/xceedr-api/venv/lib/python3.10/site-packages/sqlalchemy/sql/schema.py", line 3182, in _resolve_column
    raise exc.NoReferencedTableError(
sqlalchemy.exc.NoReferencedTableError: Foreign key associated with column 'business_user_rights.userId' could not find table 'user' with which to generate a foreign key to target column 'id'
[2023-12-05 00:34:03 +0100] [72109] [INFO] Worker exiting (pid: 72109)
[2023-12-05 00:34:03 +0100] [72110] [INFO] Worker exiting (pid: 72110)
[2023-12-05 00:34:03 +0100] [72106] [ERROR] Worker (pid:72109) exited with code 3
[2023-12-05 00:34:03 +0100] [72106] [ERROR] Worker (pid:72110) exited with code 3
[2023-12-05 00:34:03 +0100] [72108] [ERROR] Exception in worker process
Traceback (most recent call last):
  File "/home/samuel/Documents/freelance/xceedr-api/venv/lib/python3.10/site-packages/gunicorn/arbiter.py", line 609, in spawn_worker
    worker.init_process()
  File "/home/samuel/Documents/freelance/xceedr-api/venv/lib/python3.10/site-packages/gunicorn/workers/base.py", line 134, in init_process
    self.load_wsgi()
  File "/home/samuel/Documents/freelance/xceedr-api/venv/lib/python3.10/site-packages/gunicorn/workers/base.py", line 146, in load_wsgi
    self.wsgi = self.app.wsgi()
  File "/home/samuel/Documents/freelance/xceedr-api/venv/lib/python3.10/site-packages/gunicorn/app/base.py", line 67, in wsgi
    self.callable = self.load()
  File "/home/samuel/Documents/freelance/xceedr-api/venv/lib/python3.10/site-packages/gunicorn/app/wsgiapp.py", line 58, in load
    return self.load_wsgiapp()
  File "/home/samuel/Documents/freelance/xceedr-api/venv/lib/python3.10/site-packages/gunicorn/app/wsgiapp.py", line 48, in load_wsgiapp
    return util.import_app(self.app_uri)
  File "/home/samuel/Documents/freelance/xceedr-api/venv/lib/python3.10/site-packages/gunicorn/util.py", line 371, in import_app
    mod = importlib.import_module(module)
  File "/usr/lib/python3.10/importlib/__init__.py", line 126, in import_module
    return _bootstrap._gcd_import(name[level:], package, level)
  File "<frozen importlib._bootstrap>", line 1050, in _gcd_import
  File "<frozen importlib._bootstrap>", line 1027, in _find_and_load
  File "<frozen importlib._bootstrap>", line 1006, in _find_and_load_unlocked
  File "<frozen importlib._bootstrap>", line 688, in _load_unlocked
  File "<frozen importlib._bootstrap_external>", line 883, in exec_module
  File "<frozen importlib._bootstrap>", line 241, in _call_with_frames_removed
  File "/home/samuel/Documents/freelance/xceedr-api/run.py", line 24, in <module>
    app = create_app(app_config)
  File "/home/samuel/Documents/freelance/xceedr-api/volumx/__init__.py", line 96, in create_app
    db.create_all()
  File "/home/samuel/Documents/freelance/xceedr-api/venv/lib/python3.10/site-packages/flask_sqlalchemy/extension.py", line 900, in create_all
    self._call_for_binds(bind_key, "create_all")
  File "/home/samuel/Documents/freelance/xceedr-api/venv/lib/python3.10/site-packages/flask_sqlalchemy/extension.py", line 881, in _call_for_binds
    getattr(metadata, op_name)(bind=engine)
  File "/home/samuel/Documents/freelance/xceedr-api/venv/lib/python3.10/site-packages/sqlalchemy/sql/schema.py", line 5828, in create_all
    bind._run_ddl_visitor(
  File "/home/samuel/Documents/freelance/xceedr-api/venv/lib/python3.10/site-packages/sqlalchemy/engine/base.py", line 3243, in _run_ddl_visitor
    conn._run_ddl_visitor(visitorcallable, element, **kwargs)
  File "/home/samuel/Documents/freelance/xceedr-api/venv/lib/python3.10/site-packages/sqlalchemy/engine/base.py", line 2447, in _run_ddl_visitor
    visitorcallable(self.dialect, self, **kwargs).traverse_single(element)
  File "/home/samuel/Documents/freelance/xceedr-api/venv/lib/python3.10/site-packages/sqlalchemy/sql/visitors.py", line 671, in traverse_single
    return meth(obj, **kw)
  File "/home/samuel/Documents/freelance/xceedr-api/venv/lib/python3.10/site-packages/sqlalchemy/sql/ddl.py", line 897, in visit_metadata
    collection = sort_tables_and_constraints(
  File "/home/samuel/Documents/freelance/xceedr-api/venv/lib/python3.10/site-packages/sqlalchemy/sql/ddl.py", line 1327, in sort_tables_and_constraints
    dependent_on = fkc.referred_table
  File "/home/samuel/Documents/freelance/xceedr-api/venv/lib/python3.10/site-packages/sqlalchemy/sql/schema.py", line 4751, in referred_table
    return self.elements[0].column.table
  File "/home/samuel/Documents/freelance/xceedr-api/venv/lib/python3.10/site-packages/sqlalchemy/util/langhelpers.py", line 1146, in __get__
    obj.__dict__[self.__name__] = result = self.fget(obj)
  File "/home/samuel/Documents/freelance/xceedr-api/venv/lib/python3.10/site-packages/sqlalchemy/sql/schema.py", line 3159, in column
    return self._resolve_column()
  File "/home/samuel/Documents/freelance/xceedr-api/venv/lib/python3.10/site-packages/sqlalchemy/sql/schema.py", line 3182, in _resolve_column
    raise exc.NoReferencedTableError(
sqlalchemy.exc.NoReferencedTableError: Foreign key associated with column 'business_user_rights.userId' could not find table 'user' with which to generate a foreign key to target column 'id'
[2023-12-05 00:34:03 +0100] [72108] [INFO] Worker exiting (pid: 72108)
[2023-12-05 00:34:03 +0100] [72111] [ERROR] Exception in worker process
Traceback (most recent call last):
  File "/home/samuel/Documents/freelance/xceedr-api/venv/lib/python3.10/site-packages/gunicorn/arbiter.py", line 609, in spawn_worker
    worker.init_process()
  File "/home/samuel/Documents/freelance/xceedr-api/venv/lib/python3.10/site-packages/gunicorn/workers/base.py", line 134, in init_process
    self.load_wsgi()
  File "/home/samuel/Documents/freelance/xceedr-api/venv/lib/python3.10/site-packages/gunicorn/workers/base.py", line 146, in load_wsgi
    self.wsgi = self.app.wsgi()
  File "/home/samuel/Documents/freelance/xceedr-api/venv/lib/python3.10/site-packages/gunicorn/app/base.py", line 67, in wsgi
    self.callable = self.load()
  File "/home/samuel/Documents/freelance/xceedr-api/venv/lib/python3.10/site-packages/gunicorn/app/wsgiapp.py", line 58, in load
    return self.load_wsgiapp()
  File "/home/samuel/Documents/freelance/xceedr-api/venv/lib/python3.10/site-packages/gunicorn/app/wsgiapp.py", line 48, in load_wsgiapp
    return util.import_app(self.app_uri)
  File "/home/samuel/Documents/freelance/xceedr-api/venv/lib/python3.10/site-packages/gunicorn/util.py", line 371, in import_app
    mod = importlib.import_module(module)
  File "/usr/lib/python3.10/importlib/__init__.py", line 126, in import_module
    return _bootstrap._gcd_import(name[level:], package, level)
  File "<frozen importlib._bootstrap>", line 1050, in _gcd_import
  File "<frozen importlib._bootstrap>", line 1027, in _find_and_load
  File "<frozen importlib._bootstrap>", line 1006, in _find_and_load_unlocked
  File "<frozen importlib._bootstrap>", line 688, in _load_unlocked
  File "<frozen importlib._bootstrap_external>", line 883, in exec_module
  File "<frozen importlib._bootstrap>", line 241, in _call_with_frames_removed
  File "/home/samuel/Documents/freelance/xceedr-api/run.py", line 24, in <module>
    app = create_app(app_config)
  File "/home/samuel/Documents/freelance/xceedr-api/volumx/__init__.py", line 96, in create_app
    db.create_all()
  File "/home/samuel/Documents/freelance/xceedr-api/venv/lib/python3.10/site-packages/flask_sqlalchemy/extension.py", line 900, in create_all
    self._call_for_binds(bind_key, "create_all")
  File "/home/samuel/Documents/freelance/xceedr-api/venv/lib/python3.10/site-packages/flask_sqlalchemy/extension.py", line 881, in _call_for_binds
    getattr(metadata, op_name)(bind=engine)
  File "/home/samuel/Documents/freelance/xceedr-api/venv/lib/python3.10/site-packages/sqlalchemy/sql/schema.py", line 5828, in create_all
    bind._run_ddl_visitor(
  File "/home/samuel/Documents/freelance/xceedr-api/venv/lib/python3.10/site-packages/sqlalchemy/engine/base.py", line 3243, in _run_ddl_visitor
    conn._run_ddl_visitor(visitorcallable, element, **kwargs)
  File "/home/samuel/Documents/freelance/xceedr-api/venv/lib/python3.10/site-packages/sqlalchemy/engine/base.py", line 2447, in _run_ddl_visitor
    visitorcallable(self.dialect, self, **kwargs).traverse_single(element)
  File "/home/samuel/Documents/freelance/xceedr-api/venv/lib/python3.10/site-packages/sqlalchemy/sql/visitors.py", line 671, in traverse_single
    return meth(obj, **kw)
  File "/home/samuel/Documents/freelance/xceedr-api/venv/lib/python3.10/site-packages/sqlalchemy/sql/ddl.py", line 897, in visit_metadata
    collection = sort_tables_and_constraints(
  File "/home/samuel/Documents/freelance/xceedr-api/venv/lib/python3.10/site-packages/sqlalchemy/sql/ddl.py", line 1327, in sort_tables_and_constraints
    dependent_on = fkc.referred_table
  File "/home/samuel/Documents/freelance/xceedr-api/venv/lib/python3.10/site-packages/sqlalchemy/sql/schema.py", line 4751, in referred_table
    return self.elements[0].column.table
  File "/home/samuel/Documents/freelance/xceedr-api/venv/lib/python3.10/site-packages/sqlalchemy/util/langhelpers.py", line 1146, in __get__
    obj.__dict__[self.__name__] = result = self.fget(obj)
  File "/home/samuel/Documents/freelance/xceedr-api/venv/lib/python3.10/site-packages/sqlalchemy/sql/schema.py", line 3159, in column
    return self._resolve_column()
  File "/home/samuel/Documents/freelance/xceedr-api/venv/lib/python3.10/site-packages/sqlalchemy/sql/schema.py", line 3182, in _resolve_column
    raise exc.NoReferencedTableError(
sqlalchemy.exc.NoReferencedTableError: Foreign key associated with column 'business_user_rights.userId' could not find table 'user' with which to generate a foreign key to target column 'id'
[2023-12-05 00:34:03 +0100] [72111] [INFO] Worker exiting (pid: 72111)
[2023-12-05 00:35:52 +0100] [72369] [INFO] Starting gunicorn 21.2.0
[2023-12-05 00:35:52 +0100] [72369] [INFO] Listening at: http://0.0.0.0:5000 (72369)
[2023-12-05 00:35:52 +0100] [72369] [INFO] Using worker: sync
[2023-12-05 00:35:52 +0100] [72374] [INFO] Booting worker with pid: 72374
[2023-12-05 00:35:52 +0100] [72375] [INFO] Booting worker with pid: 72375
[2023-12-05 00:35:52 +0100] [72377] [INFO] Booting worker with pid: 72377
[2023-12-05 00:35:52 +0100] [72378] [INFO] Booting worker with pid: 72378
[2023-12-05 00:39:02 +0100] [72369] [INFO] Handling signal: int
[2023-12-05 00:39:02 +0100] [72378] [INFO] Worker exiting (pid: 72378)
[2023-12-05 00:39:02 +0100] [72374] [INFO] Worker exiting (pid: 72374)
[2023-12-05 00:39:02 +0100] [72377] [INFO] Worker exiting (pid: 72377)
[2023-12-05 00:39:02 +0100] [72375] [INFO] Worker exiting (pid: 72375)
[2023-12-05 00:39:02 +0100] [72369] [INFO] Shutting down: Master
[2023-12-05 00:39:03 +0100] [73262] [INFO] Starting gunicorn 21.2.0
[2023-12-05 00:39:03 +0100] [73262] [INFO] Listening at: http://0.0.0.0:5000 (73262)
[2023-12-05 00:39:03 +0100] [73262] [INFO] Using worker: sync
[2023-12-05 00:39:03 +0100] [73263] [INFO] Booting worker with pid: 73263
[2023-12-05 00:39:03 +0100] [73264] [INFO] Booting worker with pid: 73264
[2023-12-05 00:39:03 +0100] [73265] [INFO] Booting worker with pid: 73265
[2023-12-05 00:39:03 +0100] [73266] [INFO] Booting worker with pid: 73266
[2023-12-05 00:40:57,950] ERROR in app: Exception on /api/v1/business/ [GET]
Traceback (most recent call last):
  File "/home/samuel/Documents/freelance/xceedr-api/venv/lib/python3.10/site-packages/flask/app.py", line 1455, in wsgi_app
    response = self.full_dispatch_request()
  File "/home/samuel/Documents/freelance/xceedr-api/venv/lib/python3.10/site-packages/flask/app.py", line 869, in full_dispatch_request
    rv = self.handle_user_exception(e)
  File "/home/samuel/Documents/freelance/xceedr-api/venv/lib/python3.10/site-packages/flask_cors/extension.py", line 176, in wrapped_function
    return cors_after_request(app.make_response(f(*args, **kwargs)))
  File "/home/samuel/Documents/freelance/xceedr-api/venv/lib/python3.10/site-packages/flask/app.py", line 867, in full_dispatch_request
    rv = self.dispatch_request()
  File "/home/samuel/Documents/freelance/xceedr-api/venv/lib/python3.10/site-packages/flask/app.py", line 852, in dispatch_request
    return self.ensure_sync(self.view_functions[rule.endpoint])(**view_args)
TypeError: get_business_data() missing 1 required positional argument: 'business_id'
[2023-12-05 00:43:45 +0100] [73262] [INFO] Handling signal: int
[2023-12-05 00:43:45 +0100] [73265] [INFO] Worker exiting (pid: 73265)
[2023-12-05 00:43:45 +0100] [73263] [INFO] Worker exiting (pid: 73263)
[2023-12-05 00:43:45 +0100] [73264] [INFO] Worker exiting (pid: 73264)
[2023-12-05 00:43:45 +0100] [73266] [INFO] Worker exiting (pid: 73266)
[2023-12-05 00:43:45 +0100] [73262] [INFO] Shutting down: Master
[2023-12-05 00:43:46 +0100] [73620] [INFO] Starting gunicorn 21.2.0
[2023-12-05 00:43:46 +0100] [73620] [INFO] Listening at: http://0.0.0.0:5000 (73620)
[2023-12-05 00:43:46 +0100] [73620] [INFO] Using worker: sync
[2023-12-05 00:43:46 +0100] [73621] [INFO] Booting worker with pid: 73621
[2023-12-05 00:43:46 +0100] [73622] [INFO] Booting worker with pid: 73622
[2023-12-05 00:43:46 +0100] [73625] [INFO] Booting worker with pid: 73625
[2023-12-05 00:43:46 +0100] [73627] [INFO] Booting worker with pid: 73627
[2023-12-05 00:44:56 +0100] [73620] [INFO] Handling signal: int
[2023-12-05 00:44:56 +0100] [73621] [INFO] Worker exiting (pid: 73621)
[2023-12-05 00:44:56 +0100] [73622] [INFO] Worker exiting (pid: 73622)
[2023-12-05 00:44:56 +0100] [73625] [INFO] Worker exiting (pid: 73625)
[2023-12-05 00:44:56 +0100] [73627] [INFO] Worker exiting (pid: 73627)
[2023-12-05 00:44:56 +0100] [73620] [INFO] Shutting down: Master
[2023-12-05 00:44:57 +0100] [73754] [INFO] Starting gunicorn 21.2.0
[2023-12-05 00:44:57 +0100] [73754] [INFO] Listening at: http://0.0.0.0:5000 (73754)
[2023-12-05 00:44:57 +0100] [73754] [INFO] Using worker: sync
[2023-12-05 00:44:57 +0100] [73756] [INFO] Booting worker with pid: 73756
[2023-12-05 00:44:57 +0100] [73757] [INFO] Booting worker with pid: 73757
[2023-12-05 00:44:57 +0100] [73758] [INFO] Booting worker with pid: 73758
[2023-12-05 00:44:57 +0100] [73759] [INFO] Booting worker with pid: 73759
[2023-12-05 00:51:15 +0100] [73754] [INFO] Handling signal: winch
[2023-12-05 00:54:04 +0100] [73754] [INFO] Handling signal: winch
[2023-12-05 00:57:23 +0100] [73754] [INFO] Handling signal: int
[2023-12-05 00:57:23 +0100] [73756] [INFO] Worker exiting (pid: 73756)
[2023-12-05 00:57:23 +0100] [73757] [INFO] Worker exiting (pid: 73757)
[2023-12-05 00:57:23 +0100] [73759] [INFO] Worker exiting (pid: 73759)
[2023-12-05 00:57:23 +0100] [73758] [INFO] Worker exiting (pid: 73758)
[2023-12-05 00:57:23 +0100] [73754] [INFO] Shutting down: Master
[2023-12-05 00:57:24 +0100] [74527] [INFO] Starting gunicorn 21.2.0
[2023-12-05 00:57:24 +0100] [74527] [INFO] Listening at: http://0.0.0.0:5000 (74527)
[2023-12-05 00:57:24 +0100] [74527] [INFO] Using worker: sync
[2023-12-05 00:57:24 +0100] [74528] [INFO] Booting worker with pid: 74528
[2023-12-05 00:57:24 +0100] [74530] [INFO] Booting worker with pid: 74530
[2023-12-05 00:57:24 +0100] [74531] [INFO] Booting worker with pid: 74531
[2023-12-05 00:57:24 +0100] [74532] [INFO] Booting worker with pid: 74532
[2023-12-05 00:57:53,315] ERROR in app: Exception on /api/v1/auth/users [GET]
Traceback (most recent call last):
  File "/home/samuel/Documents/freelance/xceedr-api/venv/lib/python3.10/site-packages/flask/app.py", line 1455, in wsgi_app
    response = self.full_dispatch_request()
  File "/home/samuel/Documents/freelance/xceedr-api/venv/lib/python3.10/site-packages/flask/app.py", line 869, in full_dispatch_request
    rv = self.handle_user_exception(e)
  File "/home/samuel/Documents/freelance/xceedr-api/venv/lib/python3.10/site-packages/flask_cors/extension.py", line 176, in wrapped_function
    return cors_after_request(app.make_response(f(*args, **kwargs)))
  File "/home/samuel/Documents/freelance/xceedr-api/venv/lib/python3.10/site-packages/flask/app.py", line 867, in full_dispatch_request
    rv = self.dispatch_request()
  File "/home/samuel/Documents/freelance/xceedr-api/venv/lib/python3.10/site-packages/flask/app.py", line 852, in dispatch_request
    return self.ensure_sync(self.view_functions[rule.endpoint])(**view_args)
TypeError: get_users() missing 1 required positional argument: 'user'
[2023-12-05 00:58:12 +0100] [74527] [INFO] Handling signal: int
[2023-12-05 00:58:12 +0100] [74528] [INFO] Worker exiting (pid: 74528)
[2023-12-05 00:58:12 +0100] [74531] [INFO] Worker exiting (pid: 74531)
[2023-12-05 00:58:12 +0100] [74532] [INFO] Worker exiting (pid: 74532)
[2023-12-05 00:58:12 +0100] [74530] [INFO] Worker exiting (pid: 74530)
[2023-12-05 00:58:13 +0100] [74527] [INFO] Shutting down: Master
[2023-12-05 00:58:13 +0100] [74669] [INFO] Starting gunicorn 21.2.0
[2023-12-05 00:58:13 +0100] [74669] [INFO] Listening at: http://0.0.0.0:5000 (74669)
[2023-12-05 00:58:13 +0100] [74669] [INFO] Using worker: sync
[2023-12-05 00:58:13 +0100] [74671] [INFO] Booting worker with pid: 74671
[2023-12-05 00:58:13 +0100] [74672] [INFO] Booting worker with pid: 74672
[2023-12-05 00:58:13 +0100] [74674] [INFO] Booting worker with pid: 74674
[2023-12-05 00:58:13 +0100] [74675] [INFO] Booting worker with pid: 74675
[2023-12-05 01:01:03 +0100] [74669] [INFO] Handling signal: int
[2023-12-05 01:01:03 +0100] [74671] [INFO] Worker exiting (pid: 74671)
[2023-12-05 01:01:03 +0100] [74674] [INFO] Worker exiting (pid: 74674)
[2023-12-05 01:01:03 +0100] [74672] [INFO] Worker exiting (pid: 74672)
[2023-12-05 01:01:03 +0100] [74675] [INFO] Worker exiting (pid: 74675)
[2023-12-05 01:01:03 +0100] [74669] [INFO] Shutting down: Master
[2023-12-05 01:01:04 +0100] [74874] [INFO] Starting gunicorn 21.2.0
[2023-12-05 01:01:04 +0100] [74874] [INFO] Listening at: http://0.0.0.0:5000 (74874)
[2023-12-05 01:01:04 +0100] [74874] [INFO] Using worker: sync
[2023-12-05 01:01:04 +0100] [74876] [INFO] Booting worker with pid: 74876
[2023-12-05 01:01:04 +0100] [74878] [INFO] Booting worker with pid: 74878
[2023-12-05 01:01:04 +0100] [74879] [INFO] Booting worker with pid: 74879
[2023-12-05 01:01:04 +0100] [74880] [INFO] Booting worker with pid: 74880
[2023-12-05 01:12:38 +0100] [74874] [INFO] Handling signal: int
[2023-12-05 01:12:38 +0100] [74876] [INFO] Worker exiting (pid: 74876)
[2023-12-05 01:12:38 +0100] [74878] [INFO] Worker exiting (pid: 74878)
[2023-12-05 01:12:38 +0100] [74879] [INFO] Worker exiting (pid: 74879)
[2023-12-05 01:12:38 +0100] [74880] [INFO] Worker exiting (pid: 74880)
[2023-12-05 01:12:38 +0100] [74874] [INFO] Shutting down: Master
[2023-12-05 01:12:39 +0100] [75519] [INFO] Starting gunicorn 21.2.0
[2023-12-05 01:12:39 +0100] [75519] [INFO] Listening at: http://0.0.0.0:5000 (75519)
[2023-12-05 01:12:39 +0100] [75519] [INFO] Using worker: sync
[2023-12-05 01:12:39 +0100] [75521] [INFO] Booting worker with pid: 75521
[2023-12-05 01:12:39 +0100] [75522] [INFO] Booting worker with pid: 75522
[2023-12-05 01:12:39 +0100] [75523] [INFO] Booting worker with pid: 75523
[2023-12-05 01:12:39 +0100] [75524] [INFO] Booting worker with pid: 75524
[2023-12-05 01:13:06 +0100] [75519] [INFO] Handling signal: int
[2023-12-05 01:13:06 +0100] [75523] [INFO] Worker exiting (pid: 75523)
[2023-12-05 01:13:06 +0100] [75524] [INFO] Worker exiting (pid: 75524)
[2023-12-05 01:13:06 +0100] [75522] [INFO] Worker exiting (pid: 75522)
[2023-12-05 01:13:06 +0100] [75521] [INFO] Worker exiting (pid: 75521)
[2023-12-05 01:13:06 +0100] [75519] [INFO] Shutting down: Master
[2023-12-05 01:16:46 +0100] [76037] [INFO] Starting gunicorn 21.2.0
[2023-12-05 01:16:46 +0100] [76037] [INFO] Listening at: http://0.0.0.0:5000 (76037)
[2023-12-05 01:16:46 +0100] [76037] [INFO] Using worker: sync
[2023-12-05 01:16:46 +0100] [76042] [INFO] Booting worker with pid: 76042
[2023-12-05 01:16:46 +0100] [76043] [INFO] Booting worker with pid: 76043
[2023-12-05 01:16:46 +0100] [76044] [INFO] Booting worker with pid: 76044
[2023-12-05 01:16:46 +0100] [76045] [INFO] Booting worker with pid: 76045
[2023-12-05 01:19:16 +0100] [76037] [INFO] Handling signal: winch
[2023-12-05 01:19:20 +0100] [76037] [INFO] Handling signal: winch
[2023-12-05 01:25:12 +0100] [76037] [INFO] Handling signal: int
[2023-12-05 01:25:12 +0100] [76042] [INFO] Worker exiting (pid: 76042)
[2023-12-05 01:25:12 +0100] [76043] [INFO] Worker exiting (pid: 76043)
[2023-12-05 01:25:12 +0100] [76045] [INFO] Worker exiting (pid: 76045)
[2023-12-05 01:25:12 +0100] [76044] [INFO] Worker exiting (pid: 76044)
[2023-12-05 01:25:13 +0100] [76037] [INFO] Shutting down: Master
[2023-12-05 01:25:13 +0100] [76699] [INFO] Starting gunicorn 21.2.0
[2023-12-05 01:25:13 +0100] [76699] [INFO] Listening at: http://0.0.0.0:5000 (76699)
[2023-12-05 01:25:13 +0100] [76699] [INFO] Using worker: sync
[2023-12-05 01:25:13 +0100] [76700] [INFO] Booting worker with pid: 76700
[2023-12-05 01:25:13 +0100] [76701] [INFO] Booting worker with pid: 76701
[2023-12-05 01:25:13 +0100] [76702] [INFO] Booting worker with pid: 76702
[2023-12-05 01:25:13 +0100] [76704] [INFO] Booting worker with pid: 76704
[2023-12-05 01:28:21 +0100] [76699] [INFO] Handling signal: int
[2023-12-05 01:28:21 +0100] [76701] [INFO] Worker exiting (pid: 76701)
[2023-12-05 01:28:21 +0100] [76704] [INFO] Worker exiting (pid: 76704)
[2023-12-05 01:28:21 +0100] [76702] [INFO] Worker exiting (pid: 76702)
[2023-12-05 01:28:21 +0100] [76700] [INFO] Worker exiting (pid: 76700)
[2023-12-05 01:28:21 +0100] [76699] [INFO] Shutting down: Master
[2023-12-05 01:28:22 +0100] [76977] [INFO] Starting gunicorn 21.2.0
[2023-12-05 01:28:22 +0100] [76977] [INFO] Listening at: http://0.0.0.0:5000 (76977)
[2023-12-05 01:28:22 +0100] [76977] [INFO] Using worker: sync
[2023-12-05 01:28:22 +0100] [76978] [INFO] Booting worker with pid: 76978
[2023-12-05 01:28:22 +0100] [76979] [INFO] Booting worker with pid: 76979
[2023-12-05 01:28:22 +0100] [76980] [INFO] Booting worker with pid: 76980
[2023-12-05 01:28:22 +0100] [76981] [INFO] Booting worker with pid: 76981
[2023-12-05 01:33:28 +0100] [76977] [INFO] Handling signal: int
[2023-12-05 01:33:28 +0100] [76978] [INFO] Worker exiting (pid: 76978)
[2023-12-05 01:33:28 +0100] [76979] [INFO] Worker exiting (pid: 76979)
[2023-12-05 01:33:28 +0100] [76981] [INFO] Worker exiting (pid: 76981)
[2023-12-05 01:33:28 +0100] [76980] [INFO] Worker exiting (pid: 76980)
[2023-12-05 01:33:28 +0100] [76977] [INFO] Shutting down: Master
[2023-12-05 01:33:29 +0100] [77275] [INFO] Starting gunicorn 21.2.0
[2023-12-05 01:33:29 +0100] [77275] [INFO] Listening at: http://0.0.0.0:5000 (77275)
[2023-12-05 01:33:29 +0100] [77275] [INFO] Using worker: sync
[2023-12-05 01:33:29 +0100] [77276] [INFO] Booting worker with pid: 77276
[2023-12-05 01:33:29 +0100] [77277] [INFO] Booting worker with pid: 77277
[2023-12-05 01:33:29 +0100] [77278] [INFO] Booting worker with pid: 77278
[2023-12-05 01:33:29 +0100] [77279] [INFO] Booting worker with pid: 77279
[2023-12-05 01:34:13 +0100] [77275] [INFO] Handling signal: int
[2023-12-05 01:34:14 +0100] [77277] [INFO] Worker exiting (pid: 77277)
[2023-12-05 01:34:14 +0100] [77278] [INFO] Worker exiting (pid: 77278)
[2023-12-05 01:34:14 +0100] [77276] [INFO] Worker exiting (pid: 77276)
[2023-12-05 01:34:14 +0100] [77279] [INFO] Worker exiting (pid: 77279)
[2023-12-05 01:34:14 +0100] [77275] [INFO] Shutting down: Master
[2023-12-05 01:34:14 +0100] [77391] [INFO] Starting gunicorn 21.2.0
[2023-12-05 01:34:14 +0100] [77391] [INFO] Listening at: http://0.0.0.0:5000 (77391)
[2023-12-05 01:34:14 +0100] [77391] [INFO] Using worker: sync
[2023-12-05 01:34:14 +0100] [77392] [INFO] Booting worker with pid: 77392
[2023-12-05 01:34:14 +0100] [77393] [INFO] Booting worker with pid: 77393
[2023-12-05 01:34:14 +0100] [77394] [INFO] Booting worker with pid: 77394
[2023-12-05 01:34:15 +0100] [77395] [INFO] Booting worker with pid: 77395
[2023-12-05 01:39:20 +0100] [77391] [INFO] Handling signal: int
[2023-12-05 01:39:20 +0100] [77395] [INFO] Worker exiting (pid: 77395)
[2023-12-05 01:39:20 +0100] [77393] [INFO] Worker exiting (pid: 77393)
[2023-12-05 01:39:20 +0100] [77394] [INFO] Worker exiting (pid: 77394)
[2023-12-05 01:39:20 +0100] [77392] [INFO] Worker exiting (pid: 77392)
[2023-12-05 01:39:20 +0100] [77391] [INFO] Shutting down: Master
[2023-12-05 01:39:21 +0100] [77604] [INFO] Starting gunicorn 21.2.0
[2023-12-05 01:39:21 +0100] [77604] [INFO] Listening at: http://0.0.0.0:5000 (77604)
[2023-12-05 01:39:21 +0100] [77604] [INFO] Using worker: sync
[2023-12-05 01:39:21 +0100] [77605] [INFO] Booting worker with pid: 77605
[2023-12-05 01:39:21 +0100] [77606] [INFO] Booting worker with pid: 77606
[2023-12-05 01:39:22 +0100] [77607] [INFO] Booting worker with pid: 77607
[2023-12-05 01:39:22 +0100] [77608] [INFO] Booting worker with pid: 77608
[2023-12-05 01:41:42 +0100] [77604] [INFO] Handling signal: int
[2023-12-05 01:41:42 +0100] [77607] [INFO] Worker exiting (pid: 77607)
[2023-12-05 01:41:42 +0100] [77606] [INFO] Worker exiting (pid: 77606)
[2023-12-05 01:41:42 +0100] [77605] [INFO] Worker exiting (pid: 77605)
[2023-12-05 01:41:42 +0100] [77608] [INFO] Worker exiting (pid: 77608)
[2023-12-05 01:41:42 +0100] [77604] [INFO] Shutting down: Master
[2023-12-05 01:41:43 +0100] [77757] [INFO] Starting gunicorn 21.2.0
[2023-12-05 01:41:43 +0100] [77757] [INFO] Listening at: http://0.0.0.0:5000 (77757)
[2023-12-05 01:41:43 +0100] [77757] [INFO] Using worker: sync
[2023-12-05 01:41:43 +0100] [77758] [INFO] Booting worker with pid: 77758
[2023-12-05 01:41:43 +0100] [77759] [INFO] Booting worker with pid: 77759
[2023-12-05 01:41:43 +0100] [77760] [INFO] Booting worker with pid: 77760
[2023-12-05 01:41:43 +0100] [77761] [INFO] Booting worker with pid: 77761
[2023-12-05 01:42:35 +0100] [77757] [INFO] Handling signal: int
[2023-12-05 01:42:35 +0100] [77761] [INFO] Worker exiting (pid: 77761)
[2023-12-05 01:42:35 +0100] [77758] [INFO] Worker exiting (pid: 77758)
[2023-12-05 01:42:35 +0100] [77759] [INFO] Worker exiting (pid: 77759)
[2023-12-05 01:42:35 +0100] [77760] [INFO] Worker exiting (pid: 77760)
[2023-12-05 01:42:35 +0100] [77757] [INFO] Shutting down: Master
[2023-12-05 01:42:36 +0100] [77905] [INFO] Starting gunicorn 21.2.0
[2023-12-05 01:42:36 +0100] [77905] [INFO] Listening at: http://0.0.0.0:5000 (77905)
[2023-12-05 01:42:36 +0100] [77905] [INFO] Using worker: sync
[2023-12-05 01:42:36 +0100] [77907] [INFO] Booting worker with pid: 77907
[2023-12-05 01:42:36 +0100] [77908] [INFO] Booting worker with pid: 77908
[2023-12-05 01:42:36 +0100] [77909] [INFO] Booting worker with pid: 77909
[2023-12-05 01:42:36 +0100] [77910] [INFO] Booting worker with pid: 77910
[2023-12-05 01:43:24 +0100] [77905] [INFO] Handling signal: int
[2023-12-05 01:43:25 +0100] [77910] [INFO] Worker exiting (pid: 77910)
[2023-12-05 01:43:25 +0100] [77908] [INFO] Worker exiting (pid: 77908)
[2023-12-05 01:43:25 +0100] [77909] [INFO] Worker exiting (pid: 77909)
[2023-12-05 01:43:25 +0100] [77907] [INFO] Worker exiting (pid: 77907)
[2023-12-05 01:43:25 +0100] [77905] [INFO] Shutting down: Master
[2023-12-05 01:43:25 +0100] [78022] [INFO] Starting gunicorn 21.2.0
[2023-12-05 01:43:25 +0100] [78022] [INFO] Listening at: http://0.0.0.0:5000 (78022)
[2023-12-05 01:43:25 +0100] [78022] [INFO] Using worker: sync
[2023-12-05 01:43:25 +0100] [78023] [INFO] Booting worker with pid: 78023
[2023-12-05 01:43:25 +0100] [78024] [INFO] Booting worker with pid: 78024
[2023-12-05 01:43:25 +0100] [78025] [INFO] Booting worker with pid: 78025
[2023-12-05 01:43:25 +0100] [78026] [INFO] Booting worker with pid: 78026
[2023-12-05 01:46:26 +0100] [78022] [INFO] Handling signal: int
[2023-12-05 01:46:27 +0100] [78026] [INFO] Worker exiting (pid: 78026)
[2023-12-05 01:46:27 +0100] [78024] [INFO] Worker exiting (pid: 78024)
[2023-12-05 01:46:27 +0100] [78023] [INFO] Worker exiting (pid: 78023)
[2023-12-05 01:46:27 +0100] [78025] [INFO] Worker exiting (pid: 78025)
[2023-12-05 01:46:27 +0100] [78022] [INFO] Shutting down: Master
